Workbook

Sheet Summary
A1: Modello di ingresso nel mercato Liguria: SaaS agentico + IoT/hardware per ospiti (EUR)
A2: Celle blu = ipotesi di pianificazione (NON dati di mercato verificati). Sostituire con preventivi fornitori e risultati pilota.
A3: Indicatore | B3: Valore
A4: Scenario attivo | B4: =CHOOSE(Assumptions!B3,"Lean","Base","Regionale")
A5: Ricavi Anno 1 (EUR) | B5: =PnL!Z6
A6: Ricavi Anno 2 (EUR) | B6: =PnL!AA6
A7: EBITDA Anno 1 (EUR) | B7: =PnL!Z12
A8: EBITDA Anno 2 (EUR) | B8: =PnL!AA12
A9: Utile netto 24 mesi (EUR) | B9: =PnL!AB16
A10: Capex 24 mesi (EUR) | B10: =Capex!AB15
A11: Fabbisogno finanziario massimo (EUR) | B11: =MAX(0,-MIN(CashFlow!B10:Y10))
A12: Primo mese EBITDA positivo | B12: =IF(MIN(PnL!B18:Y18)=999,"n/a",MIN(PnL!B18:Y18))
A13: Cassa finale a M24 (EUR) | B13: =CashFlow!Y9
A14: Installazioni modulo a M24 | B14: =SUM(Customers!Y4:Y14)
A17: Ancore di mercato verificate (Liguria 2025, Regione Liguria)
A18: Arrivi, strutture ricettive | B18: 5306612
A19: Presenze, strutture ricettive | B19: 15963328
A20: Presenze incl. AAUT | B20: 20702403
A21: Presenze, alberghiere | B21: 9304836
A22: Presenze, extralberghiere | B22: 6658492
A24: Indice dei fogli
A25: Assumptions
A26: Customers
A27: Revenue
A28: DirectCosts
A29: Capex
A30: PnL
A31: CashFlow
A32: UnitEcon
A33: Scope
A34: Trends
A35: Software
... A40: Sources

Sheet Assumptions
A1: Modello di ingresso nel mercato Liguria: SaaS agentico + IoT/hardware per ospiti (EUR)
A2: Celle blu = ipotesi di pianificazione (NON dati di mercato verificati). Sostituire con preventivi fornitori e risultati pilota.
A3: Scenario (1=Lean, 2=Base, 3=Regionale) | B3: 2
A4: Moltiplicatore adozione (attivo) | B4: =CHOOSE(B3,B5,B6,B7)
A5: Lean | B5: 0.5
A6: Base | B6: 1
A7: Regionale | B7: 1.8
A9: Periodo ammortamento (mesi) | B9: 36
A10: Contingenza capex % | B10: 0.1
A11: Aliquota imposte (IRES+IRAP semplificata) | B11: 0.279
A12: Cassa iniziale (EUR) | B12: 0
A15: Categoria | B15: Mese di avvio | C15: Strutture a M12 (base) | D15: Strutture a M24 (base) | E15: Unità per struttura | F15: Costo sbarcato per unità (EUR) | G15: Installazione per unità (EUR) | H15: Canone setup per struttura (EUR) | I15: Canone mensile per struttura (EUR) | J15: Costo variabile % ricavi ricorrenti
A16: Hotel Agent OS (agenti AI operativi) | B16: 3 | C16: 12 | D16: 40 | E16: 1 | F16: 0 | G16: 600 | H16: 1500 | I16: 350 | J16: 0.25
A17: GuestNode Lobby (terminale in reception) | B17: 4 | C17: 8 | D17: 25 | E17: 1 | F17: 450 | G17: 150 | H17: 300 | I17: 120 | J17: 0.2
A18: GuestNode in camera | B18: 8 | C18: 3 | D18: 12 | E18: 15 | F18: 120 | G18: 25 | H18: 500 | I18: 90 | J18: 0.2
A19: Smart Travel Wall (vending/micro-market) | B19: 5 | C19: 6 | D19: 20 | E19: 1 | F19: 3500 | G19: 400 | H19: 500 | I19: 250 | J19: 0.3
A20: Armadietti a noleggio | B20: 6 | C20: 6 | D20: 18 | E20: 1 | F20: 1800 | G20: 250 | H20: 200 | I20: 120 | J20: 0.2
A21: Armadietti bagagli | B21: 7 | C21: 4 | D21: 12 | E21: 1 | F21: 2800 | G21: 400 | H21: 300 | I21: 200 | J21: 0.15
A22: Noleggio power bank | B22: 7 | C22: 5 | D22: 15 | E22: 1 | F22: 1200 | G22: 100 | H22: 0 | I22: 110 | J22: 0.25
A23: Kit IoT Energia | B23: 5 | C23: 5 | D23: 20 | E23: 20 | F23: 70 | G23: 30 | H23: 800 | I23: 160 | J23: 0.15
A24: Healthy Room IoT (qualità aria) | B24: 12 | C24: 2 | D24: 8 | E24: 10 | F24: 55 | G24: 15 | H24: 300 | I24: 60 | J24: 0.15
A25: Marketplace locale (tour, transfer, eSIM) | B25: 6 | C25: 10 | D25: 35 | E25: 0 | F25: 0 | G25: 0 | H25: 0 | I25: 90 | J25: 0.2
A26: Vending regolamentato tramite partner autorizzato (opzione, OFF nel base) | B26: 18 | C26: 0 | D26: 0 | E26: 1 | F26: 3000 | G26: 400 | H26: 0 | I26: 200 | J26: 0.3
A30: Costo fisso (EUR/mese) | B30: Importo (EUR) | C30: Mese di avvio
A31: Ingegnere FDE / integrazioni | B31: 3500 | C31: 1
A32: Vendite e partnership | B32: 2500 | C32: 3
A33: Supporto e coordinamento installatori | B33: 1800 | C33: 6
A34: Cloud, LLM base, strumenti | B34: 600 | C34: 1
A35: Marketing ed eventi (TTG, Hospitality Day) | B35: 1200 | C35: 1
A36: Legale, privacy, contabilità | B36: 900 | C36: 1
A37: Assicurazione e piccolo magazzino | B37: 500 | C37: 4
A41: Costo una tantum (EUR) | B41: Importo (EUR) | C41: Mese
A42: Audit conformità + campioni hardware | B42: 15000 | C42: 1
A43: Setup legale / privacy / contratti | B43: 5000 | C43: 1
A44: Kit demo e hardware pilota | B44: 8000 | C44: 2

Sheet Customers
A1: Strutture per modulo (scenario attivo)
A3: Categoria | B3: 1 | C3: 2 | D3: 3 | E3: 4 | F3: 5 | G3: 6 | H3: 7 | I3: 8 | J3: 9 | K3: 10 | L3: 11 | M3: 12 | N3: 13 | O3: 14 | P3: 15 | Q3: 16 | R3: 17 | S3: 18 | T3: 19 | U3: 20 | V3: 21 | W3: 22 | X3: 23 | Y3: 24
A4: Hotel Agent OS (agenti AI operativi) | B4: =ROUND(IF(B$3<Assumptions!$B16,0,IF(B$3<=12,Assumptions!$C16*Assumptions!$B$4*(B$3-Assumptions!$B16+1)/MAX(1,12-Assumptions!$B16+1),Assumptions!$C16*Assumptions!$B$4+(Assumptions!$D16-Assumptions!$C16)*Assumptions!$B$4*(B$3-12)/12)),0) | C4: =ROUND(IF(C$3<Assumptions!$B16,0,IF(C$3<=12,Assumptions!$C16*Assumptions!$B$4*(C$3-Assumptions!$B16+1)/MAX(1,12-Assumptions!$B16+1),Assumptions!$C16*Assumptions!$B$4+(Assumptions!$D16-Assumptions!$C16)*Assumptions!$B$4*(C$3-12)/12)),0) | D4: =ROUND(IF(D$3<Assumptions!$B16,0,IF(D$3<=12,Assumptions!$C16*Assumptions!$B$4*(D$3-Assumptions!$B16+1)/MAX(1,12-Assumptions!$B16+1),Assumptions!$C16*Assumptions!$B$4+(Assumptions!$D16-Assumptions!$C16)*Assumptions!$B$4*(D$3-12)/12)),0) | E4: =ROUND(IF(E$3<Assumptions!$B16,0,IF(E$3<=12,Assumptions!$C16*Assumptions!$B$4*(E$3-Assumptions!$B16+1)/MAX(1,12-Assumptions!$B16+1),Assumptions!$C16*Assumptions!$B$4+(Assumptions!$D16-Assumptions!$C16)*Assumptions!$B$4*(E$3-12)/12)),0) | F4: =ROUND(IF(F$3<Assumptions!$B16,0,IF(F$3<=12,Assumptions!$C16*Assumptions!$B$4*(F$3-Assumptions!$B16+1)/MAX(1,12-Assumptions!$B16+1),Assumptions!$C16*Assumptions!$B$4+(Assumptions!$D16-Assumptions!$C16)*Assumptions!$B$4*(F$3-12)/12)),0) | G4: =ROUND(IF(G$3<Assumptions!$B16,0,IF(G$3<=12,Assumptions!$C16*Assumptions!$B$4*(G$3-Assumptions!$B16+1)/MAX(1,12-Assumptions!$B16+1),Assumptions!$C16*Assumptions!$B$4+(Assumptions!$D16-Assumptions!$C16)*Assumptions!$B$4*(G$3-12)/12)),0) | H4: =ROUND(IF(H$3<Assumptions!$B16,0,IF(H$3<=12,Assumptions!$C16*Assumptions!$B$4*(H$3-Assumptions!$B16+1)/MAX(1,12-Assumptions!$B16+1),Assumptions!$C16*Assumptions!$B$4+(Assumptions!$D16-Assumptions!$C16)*Assumptions!$B$4*(H$3-12)/12)),0) | I4: =ROUND(IF(I$3<Assumptions!$B16,0,IF(I$3<=12,Assumptions!$C16*Assumptions!$B$4*(I$3-Assumptions!$B16+1)/MAX(1,12-Assumptions!$B16+1),Assumptions!$C16*Assumptions!$B$4+(Assumptions!$D16-Assumptions!$C16)*Assumptions!$B$4*(I$3-12)/12)),0) | ... Y4: =ROUND(IF(Y$3<Assumptions!$B16,0,IF(Y$3<=12,Assumptions!$C16*Assumptions!$B$4*(Y$3-Assumptions!$B16+1)/MAX(1,12-Assumptions!$B16+1),Assumptions!$C16*Assumptions!$B$4+(Assumptions!$D16-Assumptions!$C16)*Assumptions!$B$4*(Y$3-12)/12)),0)
A5: GuestNode Lobby (terminale in reception) | B5: =ROUND(IF(B$3<Assumptions!$B17,0,IF(B$3<=12,Assumptions!$C17*Assumptions!$B$4*(B$3-Assumptions!$B17+1)/MAX(1,12-Assumptions!$B17+1),Assumptions!$C17*Assumptions!$B$4+(Assumptions!$D17-Assumptions!$C17)*Assumptions!$B$4*(B$3-12)/12)),0) | C5: =ROUND(IF(C$3<Assumptions!$B17,0,IF(C$3<=12,Assumptions!$C17*Assumptions!$B$4*(C$3-Assumptions!$B17+1)/MAX(1,12-Assumptions!$B17+1),Assumptions!$C17*Assumptions!$B$4+(Assumptions!$D17-Assumptions!$C17)*Assumptions!$B$4*(C$3-12)/12)),0) | D5: =ROUND(IF(D$3<Assumptions!$B17,0,IF(D$3<=12,Assumptions!$C17*Assumptions!$B$4*(D$3-Assumptions!$B17+1)/MAX(1,12-Assumptions!$B17+1),Assumptions!$C17*Assumptions!$B$4+(Assumptions!$D17-Assumptions!$C17)*Assumptions!$B$4*(D$3-12)/12)),0) | E5: =ROUND(IF(E$3<Assumptions!$B17,0,IF(E$3<=12,Assumptions!$C17*Assumptions!$B$4*(E$3-Assumptions!$B17+1)/MAX(1,12-Assumptions!$B17+1),Assumptions!$C17*Assumptions!$B$4+(Assumptions!$D17-Assumptions!$C17)*Assumptions!$B$4*(E$3-12)/12)),0) | F5: =ROUND(IF(F$3<Assumptions!$B17,0,IF(F$3<=12,Assumptions!$C17*Assumptions!$B$4*(F$3-Assumptions!$B17+1)/MAX(1,12-Assumptions!$B17+1),Assumptions!$C17*Assumptions!$B$4+(Assumptions!$D17-Assumptions!$C17)*Assumptions!$B$4*(F$3-12)/12)),0) | G5: =ROUND(IF(G$3<Assumptions!$B17,0,IF(G$3<=12,Assumptions!$C17*Assumptions!$B$4*(G$3-Assumptions!$B17+1)/MAX(1,12-Assumptions!$B17+1),Assumptions!$C17*Assumptions!$B$4+(Assumptions!$D17-Assumptions!$C17)*Assumptions!$B$4*(G$3-12)/12)),0) | H5: =ROUND(IF(H$3<Assumptions!$B17,0,IF(H$3<=12,Assumptions!$C17*Assumptions!$B$4*(H$3-Assumptions!$B17+1)/MAX(1,12-Assumptions!$B17+1),Assumptions!$C17*Assumptions!$B$4+(Assumptions!$D17-Assumptions!$C17)*Assumptions!$B$4*(H$3-12)/12)),0) | I5: =ROUND(IF(I$3<Assumptions!$B17,0,IF(I$3<=12,Assumptions!$C17*Assumptions!$B$4*(I$3-Assumptions!$B17+1)/MAX(1,12-Assumptions!$B17+1),Assumptions!$C17*Assumptions!$B$4+(Assumptions!$D17-Assumptions!$C17)*Assumptions!$B$4*(I$3-12)/12)),0) | ... Y5: =ROUND(IF(Y$3<Assumptions!$B17,0,IF(Y$3<=12,Assumptions!$C17*Assumptions!$B$4*(Y$3-Assumptions!$B17+1)/MAX(1,12-Assumptions!$B17+1),Assumptions!$C17*Assumptions!$B$4+(Assumptions!$D17-Assumptions!$C17)*Assumptions!$B$4*(Y$3-12)/12)),0)
A6: GuestNode in camera | B6: =ROUND(IF(B$3<Assumptions!$B18,0,IF(B$3<=12,Assumptions!$C18*Assumptions!$B$4*(B$3-Assumptions!$B18+1)/MAX(1,12-Assumptions!$B18+1),Assumptions!$C18*Assumptions!$B$4+(Assumptions!$D18-Assumptions!$C18)*Assumptions!$B$4*(B$3-12)/12)),0) | C6: =ROUND(IF(C$3<Assumptions!$B18,0,IF(C$3<=12,Assumptions!$C18*Assumptions!$B$4*(C$3-Assumptions!$B18+1)/MAX(1,12-Assumptions!$B18+1),Assumptions!$C18*Assumptions!$B$4+(Assumptions!$D18-Assumptions!$C18)*Assumptions!$B$4*(C$3-12)/12)),0) | D6: =ROUND(IF(D$3<Assumptions!$B18,0,IF(D$3<=12,Assumptions!$C18*Assumptions!$B$4*(D$3-Assumptions!$B18+1)/MAX(1,12-Assumptions!$B18+1),Assumptions!$C18*Assumptions!$B$4+(Assumptions!$D18-Assumptions!$C18)*Assumptions!$B$4*(D$3-12)/12)),0) | E6: =ROUND(IF(E$3<Assumptions!$B18,0,IF(E$3<=12,Assumptions!$C18*Assumptions!$B$4*(E$3-Assumptions!$B18+1)/MAX(1,12-Assumptions!$B18+1),Assumptions!$C18*Assumptions!$B$4+(Assumptions!$D18-Assumptions!$C18)*Assumptions!$B$4*(E$3-12)/12)),0) | F6: =ROUND(IF(F$3<Assumptions!$B18,0,IF(F$3<=12,Assumptions!$C18*Assumptions!$B$4*(F$3-Assumptions!$B18+1)/MAX(1,12-Assumptions!$B18+1),Assumptions!$C18*Assumptions!$B$4+(Assumptions!$D18-Assumptions!$C18)*Assumptions!$B$4*(F$3-12)/12)),0) | G6: =ROUND(IF(G$3<Assumptions!$B18,0,IF(G$3<=12,Assumptions!$C18*Assumptions!$B$4*(G$3-Assumptions!$B18+1)/MAX(1,12-Assumptions!$B18+1),Assumptions!$C18*Assumptions!$B$4+(Assumptions!$D18-Assumptions!$C18)*Assumptions!$B$4*(G$3-12)/12)),0) | H6: =ROUND(IF(H$3<Assumptions!$B18,0,IF(H$3<=12,Assumptions!$C18*Assumptions!$B$4*(H$3-Assumptions!$B18+1)/MAX(1,12-Assumptions!$B18+1),Assumptions!$C18*Assumptions!$B$4+(Assumptions!$D18-Assumptions!$C18)*Assumptions!$B$4*(H$3-12)/12)),0) | I6: =ROUND(IF(I$3<Assumptions!$B18,0,IF(I$3<=12,Assumptions!$C18*Assumptions!$B$4*(I$3-Assumptions!$B18+1)/MAX(1,12-Assumptions!$B18+1),Assumptions!$C18*Assumptions!$B$4+(Assumptions!$D18-Assumptions!$C18)*Assumptions!$B$4*(I$3-12)/12)),0) | ... Y6: =ROUND(IF(Y$3<Assumptions!$B18,0,IF(Y$3<=12,Assumptions!$C18*Assumptions!$B$4*(Y$3-Assumptions!$B18+1)/MAX(1,12-Assumptions!$B18+1),Assumptions!$C18*Assumptions!$B$4+(Assumptions!$D18-Assumptions!$C18)*Assumptions!$B$4*(Y$3-12)/12)),0)
A7: Smart Travel Wall (vending/micro-market) | B7: =ROUND(IF(B$3<Assumptions!$B19,0,IF(B$3<=12,Assumptions!$C19*Assumptions!$B$4*(B$3-Assumptions!$B19+1)/MAX(1,12-Assumptions!$B19+1),Assumptions!$C19*Assumptions!$B$4+(Assumptions!$D19-Assumptions!$C19)*Assumptions!$B$4*(B$3-12)/12)),0) | C7: =ROUND(IF(C$3<Assumptions!$B19,0,IF(C$3<=12,Assumptions!$C19*Assumptions!$B$4*(C$3-Assumptions!$B19+1)/MAX(1,12-Assumptions!$B19+1),Assumptions!$C19*Assumptions!$B$4+(Assumptions!$D19-Assumptions!$C19)*Assumptions!$B$4*(C$3-12)/12)),0) | D7: =ROUND(IF(D$3<Assumptions!$B19,0,IF(D$3<=12,Assumptions!$C19*Assumptions!$B$4*(D$3-Assumptions!$B19+1)/MAX(1,12-Assumptions!$B19+1),Assumptions!$C19*Assumptions!$B$4+(Assumptions!$D19-Assumptions!$C19)*Assumptions!$B$4*(D$3-12)/12)),0) | E7: =ROUND(IF(E$3<Assumptions!$B19,0,IF(E$3<=12,Assumptions!$C19*Assumptions!$B$4*(E$3-Assumptions!$B19+1)/MAX(1,12-Assumptions!$B19+1),Assumptions!$C19*Assumptions!$B$4+(Assumptions!$D19-Assumptions!$C19)*Assumptions!$B$4*(E$3-12)/12)),0) | F7: =ROUND(IF(F$3<Assumptions!$B19,0,IF(F$3<=12,Assumptions!$C19*Assumptions!$B$4*(F$3-Assumptions!$B19+1)/MAX(1,12-Assumptions!$B19+1),Assumptions!$C19*Assumptions!$B$4+(Assumptions!$D19-Assumptions!$C19)*Assumptions!$B$4*(F$3-12)/12)),0) | G7: =ROUND(IF(G$3<Assumptions!$B19,0,IF(G$3<=12,Assumptions!$C19*Assumptions!$B$4*(G$3-Assumptions!$B19+1)/MAX(1,12-Assumptions!$B19+1),Assumptions!$C19*Assumptions!$B$4+(Assumptions!$D19-Assumptions!$C19)*Assumptions!$B$4*(G$3-12)/12)),0) | H7: =ROUND(IF(H$3<Assumptions!$B19,0,IF(H$3<=12,Assumptions!$C19*Assumptions!$B$4*(H$3-Assumptions!$B19+1)/MAX(1,12-Assumptions!$B19+1),Assumptions!$C19*Assumptions!$B$4+(Assumptions!$D19-Assumptions!$C19)*Assumptions!$B$4*(H$3-12)/12)),0) | I7: =ROUND(IF(I$3<Assumptions!$B19,0,IF(I$3<=12,Assumptions!$C19*Assumptions!$B$4*(I$3-Assumptions!$B19+1)/MAX(1,12-Assumptions!$B19+1),Assumptions!$C19*Assumptions!$B$4+(Assumptions!$D19-Assumptions!$C19)*Assumptions!$B$4*(I$3-12)/12)),0) | ... Y7: =ROUND(IF(Y$3<Assumptions!$B19,0,IF(Y$3<=12,Assumptions!$C19*Assumptions!$B$4*(Y$3-Assumptions!$B19+1)/MAX(1,12-Assumptions!$B19+1),Assumptions!$C19*Assumptions!$B$4+(Assumptions!$D19-Assumptions!$C19)*Assumptions!$B$4*(Y$3-12)/12)),0)
A8: Armadietti a noleggio | B8: =ROUND(IF(B$3<Assumptions!$B20,0,IF(B$3<=12,Assumptions!$C20*Assumptions!$B$4*(B$3-Assumptions!$B20+1)/MAX(1,12-Assumptions!$B20+1),Assumptions!$C20*Assumptions!$B$4+(Assumptions!$D20-Assumptions!$C20)*Assumptions!$B$4*(B$3-12)/12)),0) | C8: =ROUND(IF(C$3<Assumptions!$B20,0,IF(C$3<=12,Assumptions!$C20*Assumptions!$B$4*(C$3-Assumptions!$B20+1)/MAX(1,12-Assumptions!$B20+1),Assumptions!$C20*Assumptions!$B$4+(Assumptions!$D20-Assumptions!$C20)*Assumptions!$B$4*(C$3-12)/12)),0) | D8: =ROUND(IF(D$3<Assumptions!$B20,0,IF(D$3<=12,Assumptions!$C20*Assumptions!$B$4*(D$3-Assumptions!$B20+1)/MAX(1,12-Assumptions!$B20+1),Assumptions!$C20*Assumptions!$B$4+(Assumptions!$D20-Assumptions!$C20)*Assumptions!$B$4*(D$3-12)/12)),0) | E8: =ROUND(IF(E$3<Assumptions!$B20,0,IF(E$3<=12,Assumptions!$C20*Assumptions!$B$4*(E$3-Assumptions!$B20+1)/MAX(1,12-Assumptions!$B20+1),Assumptions!$C20*Assumptions!$B$4+(Assumptions!$D20-Assumptions!$C20)*Assumptions!$B$4*(E$3-12)/12)),0) | F8: =ROUND(IF(F$3<Assumptions!$B20,0,IF(F$3<=12,Assumptions!$C20*Assumptions!$B$4*(F$3-Assumptions!$B20+1)/MAX(1,12-Assumptions!$B20+1),Assumptions!$C20*Assumptions!$B$4+(Assumptions!$D20-Assumptions!$C20)*Assumptions!$B$4*(F$3-12)/12)),0) | G8: =ROUND(IF(G$3<Assumptions!$B20,0,IF(G$3<=12,Assumptions!$C20*Assumptions!$B$4*(G$3-Assumptions!$B20+1)/MAX(1,12-Assumptions!$B20+1),Assumptions!$C20*Assumptions!$B$4+(Assumptions!$D20-Assumptions!$C20)*Assumptions!$B$4*(G$3-12)/12)),0) | H8: =ROUND(IF(H$3<Assumptions!$B20,0,IF(H$3<=12,Assumptions!$C20*Assumptions!$B$4*(H$3-Assumptions!$B20+1)/MAX(1,12-Assumptions!$B20+1),Assumptions!$C20*Assumptions!$B$4+(Assumptions!$D20-Assumptions!$C20)*Assumptions!$B$4*(H$3-12)/12)),0) | I8: =ROUND(IF(I$3<Assumptions!$B20,0,IF(I$3<=12,Assumptions!$C20*Assumptions!$B$4*(I$3-Assumptions!$B20+1)/MAX(1,12-Assumptions!$B20+1),Assumptions!$C20*Assumptions!$B$4+(Assumptions!$D20-Assumptions!$C20)*Assumptions!$B$4*(I$3-12)/12)),0) | ... Y8: =ROUND(IF(Y$3<Assumptions!$B20,0,IF(Y$3<=12,Assumptions!$C20*Assumptions!$B$4*(Y$3-Assumptions!$B20+1)/MAX(1,12-Assumptions!$B20+1),Assumptions!$C20*Assumptions!$B$4+(Assumptions!$D20-Assumptions!$C20)*Assumptions!$B$4*(Y$3-12)/12)),0)
A9: Armadietti bagagli | B9: =ROUND(IF(B$3<Assumptions!$B21,0,IF(B$3<=12,Assumptions!$C21*Assumptions!$B$4*(B$3-Assumptions!$B21+1)/MAX(1,12-Assumptions!$B21+1),Assumptions!$C21*Assumptions!$B$4+(Assumptions!$D21-Assumptions!$C21)*Assumptions!$B$4*(B$3-12)/12)),0) | C9: =ROUND(IF(C$3<Assumptions!$B21,0,IF(C$3<=12,Assumptions!$C21*Assumptions!$B$4*(C$3-Assumptions!$B21+1)/MAX(1,12-Assumptions!$B21+1),Assumptions!$C21*Assumptions!$B$4+(Assumptions!$D21-Assumptions!$C21)*Assumptions!$B$4*(C$3-12)/12)),0) | D9: =ROUND(IF(D$3<Assumptions!$B21,0,IF(D$3<=12,Assumptions!$C21*Assumptions!$B$4*(D$3-Assumptions!$B21+1)/MAX(1,12-Assumptions!$B21+1),Assumptions!$C21*Assumptions!$B$4+(Assumptions!$D21-Assumptions!$C21)*Assumptions!$B$4*(D$3-12)/12)),0) | E9: =ROUND(IF(E$3<Assumptions!$B21,0,IF(E$3<=12,Assumptions!$C21*Assumptions!$B$4*(E$3-Assumptions!$B21+1)/MAX(1,12-Assumptions!$B21+1),Assumptions!$C21*Assumptions!$B$4+(Assumptions!$D21-Assumptions!$C21)*Assumptions!$B$4*(E$3-12)/12)),0) | F9: =ROUND(IF(F$3<Assumptions!$B21,0,IF(F$3<=12,Assumptions!$C21*Assumptions!$B$4*(F$3-Assumptions!$B21+1)/MAX(1,12-Assumptions!$B21+1),Assumptions!$C21*Assumptions!$B$4+(Assumptions!$D21-Assumptions!$C21)*Assumptions!$B$4*(F$3-12)/12)),0) | G9: =ROUND(IF(G$3<Assumptions!$B21,0,IF(G$3<=12,Assumptions!$C21*Assumptions!$B$4*(G$3-Assumptions!$B21+1)/MAX(1,12-Assumptions!$B21+1),Assumptions!$C21*Assumptions!$B$4+(Assumptions!$D21-Assumptions!$C21)*Assumptions!$B$4*(G$3-12)/12)),0) | H9: =ROUND(IF(H$3<Assumptions!$B21,0,IF(H$3<=12,Assumptions!$C21*Assumptions!$B$4*(H$3-Assumptions!$B21+1)/MAX(1,12-Assumptions!$B21+1),Assumptions!$C21*Assumptions!$B$4+(Assumptions!$D21-Assumptions!$C21)*Assumptions!$B$4*(H$3-12)/12)),0) | I9: =ROUND(IF(I$3<Assumptions!$B21,0,IF(I$3<=12,Assumptions!$C21*Assumptions!$B$4*(I$3-Assumptions!$B21+1)/MAX(1,12-Assumptions!$B21+1),Assumptions!$C21*Assumptions!$B$4+(Assumptions!$D21-Assumptions!$C21)*Assumptions!$B$4*(I$3-12)/12)),0) | ... Y9: =ROUND(IF(Y$3<Assumptions!$B21,0,IF(Y$3<=12,Assumptions!$C21*Assumptions!$B$4*(Y$3-Assumptions!$B21+1)/MAX(1,12-Assumptions!$B21+1),Assumptions!$C21*Assumptions!$B$4+(Assumptions!$D21-Assumptions!$C21)*Assumptions!$B$4*(Y$3-12)/12)),0)
A10: Noleggio power bank | B10: =ROUND(IF(B$3<Assumptions!$B22,0,IF(B$3<=12,Assumptions!$C22*Assumptions!$B$4*(B$3-Assumptions!$B22+1)/MAX(1,12-Assumptions!$B22+1),Assumptions!$C22*Assumptions!$B$4+(Assumptions!$D22-Assumptions!$C22)*Assumptions!$B$4*(B$3-12)/12)),0) | C10: =ROUND(IF(C$3<Assumptions!$B22,0,IF(C$3<=12,Assumptions!$C22*Assumptions!$B$4*(C$3-Assumptions!$B22+1)/MAX(1,12-Assumptions!$B22+1),Assumptions!$C22*Assumptions!$B$4+(Assumptions!$D22-Assumptions!$C22)*Assumptions!$B$4*(C$3-12)/12)),0) | D10: =ROUND(IF(D$3<Assumptions!$B22,0,IF(D$3<=12,Assumptions!$C22*Assumptions!$B$4*(D$3-Assumptions!$B22+1)/MAX(1,12-Assumptions!$B22+1),Assumptions!$C22*Assumptions!$B$4+(Assumptions!$D22-Assumptions!$C22)*Assumptions!$B$4*(D$3-12)/12)),0) | E10: =ROUND(IF(E$3<Assumptions!$B22,0,IF(E$3<=12,Assumptions!$C22*Assumptions!$B$4*(E$3-Assumptions!$B22+1)/MAX(1,12-Assumptions!$B22+1),Assumptions!$C22*Assumptions!$B$4+(Assumptions!$D22-Assumptions!$C22)*Assumptions!$B$4*(E$3-12)/12)),0) | F10: =ROUND(IF(F$3<Assumptions!$B22,0,IF(F$3<=12,Assumptions!$C22*Assumptions!$B$4*(F$3-Assumptions!$B22+1)/MAX(1,12-Assumptions!$B22+1),Assumptions!$C22*Assumptions!$B$4+(Assumptions!$D22-Assumptions!$C22)*Assumptions!$B$4*(F$3-12)/12)),0) | G10: =ROUND(IF(G$3<Assumptions!$B22,0,IF(G$3<=12,Assumptions!$C22*Assumptions!$B$4*(G$3-Assumptions!$B22+1)/MAX(1,12-Assumptions!$B22+1),Assumptions!$C22*Assumptions!$B$4+(Assumptions!$D22-Assumptions!$C22)*Assumptions!$B$4*(G$3-12)/12)),0) | H10: =ROUND(IF(H$3<Assumptions!$B22,0,IF(H$3<=12,Assumptions!$C22*Assumptions!$B$4*(H$3-Assumptions!$B22+1)/MAX(1,12-Assumptions!$B22+1),Assumptions!$C22*Assumptions!$B$4+(Assumptions!$D22-Assumptions!$C22)*Assumptions!$B$4*(H$3-12)/12)),0) | I10: =ROUND(IF(I$3<Assumptions!$B22,0,IF(I$3<=12,Assumptions!$C22*Assumptions!$B$4*(I$3-Assumptions!$B22+1)/MAX(1,12-Assumptions!$B22+1),Assumptions!$C22*Assumptions!$B$4+(Assumptions!$D22-Assumptions!$C22)*Assumptions!$B$4*(I$3-12)/12)),0) | ... Y10: =ROUND(IF(Y$3<Assumptions!$B22,0,IF(Y$3<=12,Assumptions!$C22*Assumptions!$B$4*(Y$3-Assumptions!$B22+1)/MAX(1,12-Assumptions!$B22+1),Assumptions!$C22*Assumptions!$B$4+(Assumptions!$D22-Assumptions!$C22)*Assumptions!$B$4*(Y$3-12)/12)),0)
A11: Kit IoT Energia | B11: =ROUND(IF(B$3<Assumptions!$B23,0,IF(B$3<=12,Assumptions!$C23*Assumptions!$B$4*(B$3-Assumptions!$B23+1)/MAX(1,12-Assumptions!$B23+1),Assumptions!$C23*Assumptions!$B$4+(Assumptions!$D23-Assumptions!$C23)*Assumptions!$B$4*(B$3-12)/12)),0) | C11: =ROUND(IF(C$3<Assumptions!$B23,0,IF(C$3<=12,Assumptions!$C23*Assumptions!$B$4*(C$3-Assumptions!$B23+1)/MAX(1,12-Assumptions!$B23+1),Assumptions!$C23*Assumptions!$B$4+(Assumptions!$D23-Assumptions!$C23)*Assumptions!$B$4*(C$3-12)/12)),0) | D11: =ROUND(IF(D$3<Assumptions!$B23,0,IF(D$3<=12,Assumptions!$C23*Assumptions!$B$4*(D$3-Assumptions!$B23+1)/MAX(1,12-Assumptions!$B23+1),Assumptions!$C23*Assumptions!$B$4+(Assumptions!$D23-Assumptions!$C23)*Assumptions!$B$4*(D$3-12)/12)),0) | E11: =ROUND(IF(E$3<Assumptions!$B23,0,IF(E$3<=12,Assumptions!$C23*Assumptions!$B$4*(E$3-Assumptions!$B23+1)/MAX(1,12-Assumptions!$B23+1),Assumptions!$C23*Assumptions!$B$4+(Assumptions!$D23-Assumptions!$C23)*Assumptions!$B$4*(E$3-12)/12)),0) | F11: =ROUND(IF(F$3<Assumptions!$B23,0,IF(F$3<=12,Assumptions!$C23*Assumptions!$B$4*(F$3-Assumptions!$B23+1)/MAX(1,12-Assumptions!$B23+1),Assumptions!$C23*Assumptions!$B$4+(Assumptions!$D23-Assumptions!$C23)*Assumptions!$B$4*(F$3-12)/12)),0) | G11: =ROUND(IF(G$3<Assumptions!$B23,0,IF(G$3<=12,Assumptions!$C23*Assumptions!$B$4*(G$3-Assumptions!$B23+1)/MAX(1,12-Assumptions!$B23+1),Assumptions!$C23*Assumptions!$B$4+(Assumptions!$D23-Assumptions!$C23)*Assumptions!$B$4*(G$3-12)/12)),0) | H11: =ROUND(IF(H$3<Assumptions!$B23,0,IF(H$3<=12,Assumptions!$C23*Assumptions!$B$4*(H$3-Assumptions!$B23+1)/MAX(1,12-Assumptions!$B23+1),Assumptions!$C23*Assumptions!$B$4+(Assumptions!$D23-Assumptions!$C23)*Assumptions!$B$4*(H$3-12)/12)),0) | I11: =ROUND(IF(I$3<Assumptions!$B23,0,IF(I$3<=12,Assumptions!$C23*Assumptions!$B$4*(I$3-Assumptions!$B23+1)/MAX(1,12-Assumptions!$B23+1),Assumptions!$C23*Assumptions!$B$4+(Assumptions!$D23-Assumptions!$C23)*Assumptions!$B$4*(I$3-12)/12)),0) | ... Y11: =ROUND(IF(Y$3<Assumptions!$B23,0,IF(Y$3<=12,Assumptions!$C23*Assumptions!$B$4*(Y$3-Assumptions!$B23+1)/MAX(1,12-Assumptions!$B23+1),Assumptions!$C23*Assumptions!$B$4+(Assumptions!$D23-Assumptions!$C23)*Assumptions!$B$4*(Y$3-12)/12)),0)
A12: Healthy Room IoT (qualità aria) | B12: =ROUND(IF(B$3<Assumptions!$B24,0,IF(B$3<=12,Assumptions!$C24*Assumptions!$B$4*(B$3-Assumptions!$B24+1)/MAX(1,12-Assumptions!$B24+1),Assumptions!$C24*Assumptions!$B$4+(Assumptions!$D24-Assumptions!$C24)*Assumptions!$B$4*(B$3-12)/12)),0) | C12: =ROUND(IF(C$3<Assumptions!$B24,0,IF(C$3<=12,Assumptions!$C24*Assumptions!$B$4*(C$3-Assumptions!$B24+1)/MAX(1,12-Assumptions!$B24+1),Assumptions!$C24*Assumptions!$B$4+(Assumptions!$D24-Assumptions!$C24)*Assumptions!$B$4*(C$3-12)/12)),0) | D12: =ROUND(IF(D$3<Assumptions!$B24,0,IF(D$3<=12,Assumptions!$C24*Assumptions!$B$4*(D$3-Assumptions!$B24+1)/MAX(1,12-Assumptions!$B24+1),Assumptions!$C24*Assumptions!$B$4+(Assumptions!$D24-Assumptions!$C24)*Assumptions!$B$4*(D$3-12)/12)),0) | E12: =ROUND(IF(E$3<Assumptions!$B24,0,IF(E$3<=12,Assumptions!$C24*Assumptions!$B$4*(E$3-Assumptions!$B24+1)/MAX(1,12-Assumptions!$B24+1),Assumptions!$C24*Assumptions!$B$4+(Assumptions!$D24-Assumptions!$C24)*Assumptions!$B$4*(E$3-12)/12)),0) | F12: =ROUND(IF(F$3<Assumptions!$B24,0,IF(F$3<=12,Assumptions!$C24*Assumptions!$B$4*(F$3-Assumptions!$B24+1)/MAX(1,12-Assumptions!$B24+1),Assumptions!$C24*Assumptions!$B$4+(Assumptions!$D24-Assumptions!$C24)*Assumptions!$B$4*(F$3-12)/12)),0) | G12: =ROUND(IF(G$3<Assumptions!$B24,0,IF(G$3<=12,Assumptions!$C24*Assumptions!$B$4*(G$3-Assumptions!$B24+1)/MAX(1,12-Assumptions!$B24+1),Assumptions!$C24*Assumptions!$B$4+(Assumptions!$D24-Assumptions!$C24)*Assumptions!$B$4*(G$3-12)/12)),0) | H12: =ROUND(IF(H$3<Assumptions!$B24,0,IF(H$3<=12,Assumptions!$C24*Assumptions!$B$4*(H$3-Assumptions!$B24+1)/MAX(1,12-Assumptions!$B24+1),Assumptions!$C24*Assumptions!$B$4+(Assumptions!$D24-Assumptions!$C24)*Assumptions!$B$4*(H$3-12)/12)),0) | I12: =ROUND(IF(I$3<Assumptions!$B24,0,IF(I$3<=12,Assumptions!$C24*Assumptions!$B$4*(I$3-Assumptions!$B24+1)/MAX(1,12-Assumptions!$B24+1),Assumptions!$C24*Assumptions!$B$4+(Assumptions!$D24-Assumptions!$C24)*Assumptions!$B$4*(I$3-12)/12)),0) | ... Y12: =ROUND(IF(Y$3<Assumptions!$B24,0,IF(Y$3<=12,Assumptions!$C24*Assumptions!$B$4*(Y$3-Assumptions!$B24+1)/MAX(1,12-Assumptions!$B24+1),Assumptions!$C24*Assumptions!$B$4+(Assumptions!$D24-Assumptions!$C24)*Assumptions!$B$4*(Y$3-12)/12)),0)
A13: Marketplace locale (tour, transfer, eSIM) | B13: =ROUND(IF(B$3<Assumptions!$B25,0,IF(B$3<=12,Assumptions!$C25*Assumptions!$B$4*(B$3-Assumptions!$B25+1)/MAX(1,12-Assumptions!$B25+1),Assumptions!$C25*Assumptions!$B$4+(Assumptions!$D25-Assumptions!$C25)*Assumptions!$B$4*(B$3-12)/12)),0) | C13: =ROUND(IF(C$3<Assumptions!$B25,0,IF(C$3<=12,Assumptions!$C25*Assumptions!$B$4*(C$3-Assumptions!$B25+1)/MAX(1,12-Assumptions!$B25+1),Assumptions!$C25*Assumptions!$B$4+(Assumptions!$D25-Assumptions!$C25)*Assumptions!$B$4*(C$3-12)/12)),0) | D13: =ROUND(IF(D$3<Assumptions!$B25,0,IF(D$3<=12,Assumptions!$C25*Assumptions!$B$4*(D$3-Assumptions!$B25+1)/MAX(1,12-Assumptions!$B25+1),Assumptions!$C25*Assumptions!$B$4+(Assumptions!$D25-Assumptions!$C25)*Assumptions!$B$4*(D$3-12)/12)),0) | E13: =ROUND(IF(E$3<Assumptions!$B25,0,IF(E$3<=12,Assumptions!$C25*Assumptions!$B$4*(E$3-Assumptions!$B25+1)/MAX(1,12-Assumptions!$B25+1),Assumptions!$C25*Assumptions!$B$4+(Assumptions!$D25-Assumptions!$C25)*Assumptions!$B$4*(E$3-12)/12)),0) | F13: =ROUND(IF(F$3<Assumptions!$B25,0,IF(F$3<=12,Assumptions!$C25*Assumptions!$B$4*(F$3-Assumptions!$B25+1)/MAX(1,12-Assumptions!$B25+1),Assumptions!$C25*Assumptions!$B$4+(Assumptions!$D25-Assumptions!$C25)*Assumptions!$B$4*(F$3-12)/12)),0) | G13: =ROUND(IF(G$3<Assumptions!$B25,0,IF(G$3<=12,Assumptions!$C25*Assumptions!$B$4*(G$3-Assumptions!$B25+1)/MAX(1,12-Assumptions!$B25+1),Assumptions!$C25*Assumptions!$B$4+(Assumptions!$D25-Assumptions!$C25)*Assumptions!$B$4*(G$3-12)/12)),0) | H13: =ROUND(IF(H$3<Assumptions!$B25,0,IF(H$3<=12,Assumptions!$C25*Assumptions!$B$4*(H$3-Assumptions!$B25+1)/MAX(1,12-Assumptions!$B25+1),Assumptions!$C25*Assumptions!$B$4+(Assumptions!$D25-Assumptions!$C25)*Assumptions!$B$4*(H$3-12)/12)),0) | I13: =ROUND(IF(I$3<Assumptions!$B25,0,IF(I$3<=12,Assumptions!$C25*Assumptions!$B$4*(I$3-Assumptions!$B25+1)/MAX(1,12-Assumptions!$B25+1),Assumptions!$C25*Assumptions!$B$4+(Assumptions!$D25-Assumptions!$C25)*Assumptions!$B$4*(I$3-12)/12)),0) | ... Y13: =ROUND(IF(Y$3<Assumptions!$B25,0,IF(Y$3<=12,Assumptions!$C25*Assumptions!$B$4*(Y$3-Assumptions!$B25+1)/MAX(1,12-Assumptions!$B25+1),Assumptions!$C25*Assumptions!$B$4+(Assumptions!$D25-Assumptions!$C25)*Assumptions!$B$4*(Y$3-12)/12)),0)
A14: Vending regolamentato tramite partner autorizzato (opzione, OFF nel base) | B14: =ROUND(IF(B$3<Assumptions!$B26,0,IF(B$3<=12,Assumptions!$C26*Assumptions!$B$4*(B$3-Assumptions!$B26+1)/MAX(1,12-Assumptions!$B26+1),Assumptions!$C26*Assumptions!$B$4+(Assumptions!$D26-Assumptions!$C26)*Assumptions!$B$4*(B$3-12)/12)),0) | C14: =ROUND(IF(C$3<Assumptions!$B26,0,IF(C$3<=12,Assumptions!$C26*Assumptions!$B$4*(C$3-Assumptions!$B26+1)/MAX(1,12-Assumptions!$B26+1),Assumptions!$C26*Assumptions!$B$4+(Assumptions!$D26-Assumptions!$C26)*Assumptions!$B$4*(C$3-12)/12)),0) | D14: =ROUND(IF(D$3<Assumptions!$B26,0,IF(D$3<=12,Assumptions!$C26*Assumptions!$B$4*(D$3-Assumptions!$B26+1)/MAX(1,12-Assumptions!$B26+1),Assumptions!$C26*Assumptions!$B$4+(Assumptions!$D26-Assumptions!$C26)*Assumptions!$B$4*(D$3-12)/12)),0) | E14: =ROUND(IF(E$3<Assumptions!$B26,0,IF(E$3<=12,Assumptions!$C26*Assumptions!$B$4*(E$3-Assumptions!$B26+1)/MAX(1,12-Assumptions!$B26+1),Assumptions!$C26*Assumptions!$B$4+(Assumptions!$D26-Assumptions!$C26)*Assumptions!$B$4*(E$3-12)/12)),0) | F14: =ROUND(IF(F$3<Assumptions!$B26,0,IF(F$3<=12,Assumptions!$C26*Assumptions!$B$4*(F$3-Assumptions!$B26+1)/MAX(1,12-Assumptions!$B26+1),Assumptions!$C26*Assumptions!$B$4+(Assumptions!$D26-Assumptions!$C26)*Assumptions!$B$4*(F$3-12)/12)),0) | G14: =ROUND(IF(G$3<Assumptions!$B26,0,IF(G$3<=12,Assumptions!$C26*Assumptions!$B$4*(G$3-Assumptions!$B26+1)/MAX(1,12-Assumptions!$B26+1),Assumptions!$C26*Assumptions!$B$4+(Assumptions!$D26-Assumptions!$C26)*Assumptions!$B$4*(G$3-12)/12)),0) | H14: =ROUND(IF(H$3<Assumptions!$B26,0,IF(H$3<=12,Assumptions!$C26*Assumptions!$B$4*(H$3-Assumptions!$B26+1)/MAX(1,12-Assumptions!$B26+1),Assumptions!$C26*Assumptions!$B$4+(Assumptions!$D26-Assumptions!$C26)*Assumptions!$B$4*(H$3-12)/12)),0) | I14: =ROUND(IF(I$3<Assumptions!$B26,0,IF(I$3<=12,Assumptions!$C26*Assumptions!$B$4*(I$3-Assumptions!$B26+1)/MAX(1,12-Assumptions!$B26+1),Assumptions!$C26*Assumptions!$B$4+(Assumptions!$D26-Assumptions!$C26)*Assumptions!$B$4*(I$3-12)/12)),0) | ... Y14: =ROUND(IF(Y$3<Assumptions!$B26,0,IF(Y$3<=12,Assumptions!$C26*Assumptions!$B$4*(Y$3-Assumptions!$B26+1)/MAX(1,12-Assumptions!$B26+1),Assumptions!$C26*Assumptions!$B$4+(Assumptions!$D26-Assumptions!$C26)*Assumptions!$B$4*(Y$3-12)/12)),0)

Sheet Revenue
A1: Ricavi ricorrenti / Ricavi setup
A3: Ricavi ricorrenti | B3: 1 | C3: 2 | D3: 3 | E3: 4 | F3: 5 | G3: 6 | H3: 7 | I3: 8 | J3: 9 | K3: 10 | L3: 11 | M3: 12 | N3: 13 | O3: 14 | P3: 15 | Q3: 16 | R3: 17 | S3: 18 | T3: 19 | U3: 20 | V3: 21 | W3: 22 | X3: 23 | Y3: 24 | Z3: Anno 1 | AA3: Anno 2 | AB3: 24 mesi
A4: Hotel Agent OS (agenti AI operativi) | B4: =Customers!B4*Assumptions!$I$16 | C4: =Customers!C4*Assumptions!$I$16 | D4: =Customers!D4*Assumptions!$I$16 | E4: =Customers!E4*Assumptions!$I$16 | F4: =Customers!F4*Assumptions!$I$16 | G4: =Customers!G4*Assumptions!$I$16 | H4: =Customers!H4*Assumptions!$I$16 | I4: =Customers!I4*Assumptions!$I$16 | ... Y4: =Customers!Y4*Assumptions!$I$16 | Z4: =SUM(B4:M4) | AA4: =SUM(N4:Y4) | AB4: =Z4+AA4
A5: GuestNode Lobby (terminale in reception) | B5: =Customers!B5*Assumptions!$I$17 | C5: =Customers!C5*Assumptions!$I$17 | D5: =Customers!D5*Assumptions!$I$17 | E5: =Customers!E5*Assumptions!$I$17 | F5: =Customers!F5*Assumptions!$I$17 | G5: =Customers!G5*Assumptions!$I$17 | H5: =Customers!H5*Assumptions!$I$17 | I5: =Customers!I5*Assumptions!$I$17 | ... Y5: =Customers!Y5*Assumptions!$I$17 | Z5: =SUM(B5:M5) | AA5: =SUM(N5:Y5) | AB5: =Z5+AA5
A6: GuestNode in camera | B6: =Customers!B6*Assumptions!$I$18 | C6: =Customers!C6*Assumptions!$I$18 | D6: =Customers!D6*Assumptions!$I$18 | E6: =Customers!E6*Assumptions!$I$18 | F6: =Customers!F6*Assumptions!$I$18 | G6: =Customers!G6*Assumptions!$I$18 | H6: =Customers!H6*Assumptions!$I$18 | I6: =Customers!I6*Assumptions!$I$18 | ... Y6: =Customers!Y6*Assumptions!$I$18 | Z6: =SUM(B6:M6) | AA6: =SUM(N6:Y6) | AB6: =Z6+AA6
A7: Smart Travel Wall (vending/micro-market) | B7: =Customers!B7*Assumptions!$I$19 | C7: =Customers!C7*Assumptions!$I$19 | D7: =Customers!D7*Assumptions!$I$19 | E7: =Customers!E7*Assumptions!$I$19 | F7: =Customers!F7*Assumptions!$I$19 | G7: =Customers!G7*Assumptions!$I$19 | H7: =Customers!H7*Assumptions!$I$19 | I7: =Customers!I7*Assumptions!$I$19 | ... Y7: =Customers!Y7*Assumptions!$I$19 | Z7: =SUM(B7:M7) | AA7: =SUM(N7:Y7) | AB7: =Z7+AA7
A8: Armadietti a noleggio | B8: =Customers!B8*Assumptions!$I$20 | C8: =Customers!C8*Assumptions!$I$20 | D8: =Customers!D8*Assumptions!$I$20 | E8: =Customers!E8*Assumptions!$I$20 | F8: =Customers!F8*Assumptions!$I$20 | G8: =Customers!G8*Assumptions!$I$20 | H8: =Customers!H8*Assumptions!$I$20 | I8: =Customers!I8*Assumptions!$I$20 | ... Y8: =Customers!Y8*Assumptions!$I$20 | Z8: =SUM(B8:M8) | AA8: =SUM(N8:Y8) | AB8: =Z8+AA8
A9: Armadietti bagagli | B9: =Customers!B9*Assumptions!$I$21 | C9: =Customers!C9*Assumptions!$I$21 | D9: =Customers!D9*Assumptions!$I$21 | E9: =Customers!E9*Assumptions!$I$21 | F9: =Customers!F9*Assumptions!$I$21 | G9: =Customers!G9*Assumptions!$I$21 | H9: =Customers!H9*Assumptions!$I$21 | I9: =Customers!I9*Assumptions!$I$21 | ... Y9: =Customers!Y9*Assumptions!$I$21 | Z9: =SUM(B9:M9) | AA9: =SUM(N9:Y9) | AB9: =Z9+AA9
A10: Noleggio power bank | B10: =Customers!B10*Assumptions!$I$22 | C10: =Customers!C10*Assumptions!$I$22 | D10: =Customers!D10*Assumptions!$I$22 | E10: =Customers!E10*Assumptions!$I$22 | F10: =Customers!F10*Assumptions!$I$22 | G10: =Customers!G10*Assumptions!$I$22 | H10: =Customers!H10*Assumptions!$I$22 | I10: =Customers!I10*Assumptions!$I$22 | ... Y10: =Customers!Y10*Assumptions!$I$22 | Z10: =SUM(B10:M10) | AA10: =SUM(N10:Y10) | AB10: =Z10+AA10
A11: Kit IoT Energia | B11: =Customers!B11*Assumptions!$I$23 | C11: =Customers!C11*Assumptions!$I$23 | D11: =Customers!D11*Assumptions!$I$23 | E11: =Customers!E11*Assumptions!$I$23 | F11: =Customers!F11*Assumptions!$I$23 | G11: =Customers!G11*Assumptions!$I$23 | H11: =Customers!H11*Assumptions!$I$23 | I11: =Customers!I11*Assumptions!$I$23 | ... Y11: =Customers!Y11*Assumptions!$I$23 | Z11: =SUM(B11:M11) | AA11: =SUM(N11:Y11) | AB11: =Z11+AA11
A12: Healthy Room IoT (qualità aria) | B12: =Customers!B12*Assumptions!$I$24 | C12: =Customers!C12*Assumptions!$I$24 | D12: =Customers!D12*Assumptions!$I$24 | E12: =Customers!E12*Assumptions!$I$24 | F12: =Customers!F12*Assumptions!$I$24 | G12: =Customers!G12*Assumptions!$I$24 | H12: =Customers!H12*Assumptions!$I$24 | I12: =Customers!I12*Assumptions!$I$24 | ... Y12: =Customers!Y12*Assumptions!$I$24 | Z12: =SUM(B12:M12) | AA12: =SUM(N12:Y12) | AB12: =Z12+AA12
A13: Marketplace locale (tour, transfer, eSIM) | B13: =Customers!B13*Assumptions!$I$25 | C13: =Customers!C13*Assumptions!$I$25 | D13: =Customers!D13*Assumptions!$I$25 | E13: =Customers!E13*Assumptions!$I$25 | F13: =Customers!F13*Assumptions!$I$25 | G13: =Customers!G13*Assumptions!$I$25 | H13: =Customers!H13*Assumptions!$I$25 | I13: =Customers!I13*Assumptions!$I$25 | ... Y13: =Customers!Y13*Assumptions!$I$25 | Z13: =SUM(B13:M13) | AA13: =SUM(N13:Y13) | AB13: =Z13+AA13
A14: Vending regolamentato tramite partner autorizzato (opzione, OFF nel base) | B14: =Customers!B14*Assumptions!$I$26 | C14: =Customers!C14*Assumptions!$I$26 | D14: =Customers!D14*Assumptions!$I$26 | E14: =Customers!E14*Assumptions!$I$26 | F14: =Customers!F14*Assumptions!$I$26 | G14: =Customers!G14*Assumptions!$I$26 | H14: =Customers!H14*Assumptions!$I$26 | I14: =Customers!I14*Assumptions!$I$26 | ... Y14: =Customers!Y14*Assumptions!$I$26 | Z14: =SUM(B14:M14) | AA14: =SUM(N14:Y14) | AB14: =Z14+AA14
A15: Ricavi ricorrenti | B15: =SUM(B4:B14) | C15: =SUM(C4:C14) | D15: =SUM(D4:D14) | E15: =SUM(E4:E14) | F15: =SUM(F4:F14) | G15: =SUM(G4:G14) | H15: =SUM(H4:H14) | I15: =SUM(I4:I14) | ... Y15: =SUM(Y4:Y14) | Z15: =SUM(B15:M15) | AA15: =SUM(N15:Y15) | AB15: =Z15+AA15
A18: Ricavi setup
A19: Hotel Agent OS (agenti AI operativi) | B19: =Customers!B4*Assumptions!$H$16 | C19: =MAX(0,Customers!C4-Customers!B4)*Assumptions!$H$16 | D19: =MAX(0,Customers!D4-Customers!C4)*Assumptions!$H$16 | E19: =MAX(0,Customers!E4-Customers!D4)*Assumptions!$H$16 | F19: =MAX(0,Customers!F4-Customers!E4)*Assumptions!$H$16 | G19: =MAX(0,Customers!G4-Customers!F4)*Assumptions!$H$16 | H19: =MAX(0,Customers!H4-Customers!G4)*Assumptions!$H$16 | I19: =MAX(0,Customers!I4-Customers!H4)*Assumptions!$H$16 | J19: =MAX(0,Customers!J4-Customers!I4)*Assumptions!$H$16 | ... Y19: =MAX(0,Customers!Y4-Customers!X4)*Assumptions!$H$16 | Z19: =SUM(B19:M19) | AA19: =SUM(N19:Y19) | AB19: =Z19+AA19
A20: GuestNode Lobby (terminale in reception) | B20: =Customers!B5*Assumptions!$H$17 | C20: =MAX(0,Customers!C5-Customers!B5)*Assumptions!$H$17 | D20: =MAX(0,Customers!D5-Customers!C5)*Assumptions!$H$17 | E20: =MAX(0,Customers!E5-Customers!D5)*Assumptions!$H$17 | F20: =MAX(0,Customers!F5-Customers!E5)*Assumptions!$H$17 | G20: =MAX(0,Customers!G5-Customers!F5)*Assumptions!$H$17 | H20: =MAX(0,Customers!H5-Customers!G5)*Assumptions!$H$17 | I20: =MAX(0,Customers!I5-Customers!H5)*Assumptions!$H$17 | J20: =MAX(0,Customers!J5-Customers!I5)*Assumptions!$H$17 | ... Y20: =MAX(0,Customers!Y5-Customers!X5)*Assumptions!$H$17 | Z20: =SUM(B20:M20) | AA20: =SUM(N20:Y20) | AB20: =Z20+AA20
A21: GuestNode in camera | B21: =Customers!B6*Assumptions!$H$18 | C21: =MAX(0,Customers!C6-Customers!B6)*Assumptions!$H$18 | D21: =MAX(0,Customers!D6-Customers!C6)*Assumptions!$H$18 | E21: =MAX(0,Customers!E6-Customers!D6)*Assumptions!$H$18 | F21: =MAX(0,Customers!F6-Customers!E6)*Assumptions!$H$18 | G21: =MAX(0,Customers!G6-Customers!F6)*Assumptions!$H$18 | H21: =MAX(0,Customers!H6-Customers!G6)*Assumptions!$H$18 | I21: =MAX(0,Customers!I6-Customers!H6)*Assumptions!$H$18 | J21: =MAX(0,Customers!J6-Customers!I6)*Assumptions!$H$18 | ... Y21: =MAX(0,Customers!Y6-Customers!X6)*Assumptions!$H$18 | Z21: =SUM(B21:M21) | AA21: =SUM(N21:Y21) | AB21: =Z21+AA21
A22: Smart Travel Wall (vending/micro-market) | B22: =Customers!B7*Assumptions!$H$19 | C22: =MAX(0,Customers!C7-Customers!B7)*Assumptions!$H$19 | D22: =MAX(0,Customers!D7-Customers!C7)*Assumptions!$H$19 | E22: =MAX(0,Customers!E7-Customers!D7)*Assumptions!$H$19 | F22: =MAX(0,Customers!F7-Customers!E7)*Assumptions!$H$19 | G22: =MAX(0,Customers!G7-Customers!F7)*Assumptions!$H$19 | H22: =MAX(0,Customers!H7-Customers!G7)*Assumptions!$H$19 | I22: =MAX(0,Customers!I7-Customers!H7)*Assumptions!$H$19 | J22: =MAX(0,Customers!J7-Customers!I7)*Assumptions!$H$19 | ... Y22: =MAX(0,Customers!Y7-Customers!X7)*Assumptions!$H$19 | Z22: =SUM(B22:M22) | AA22: =SUM(N22:Y22) | AB22: =Z22+AA22
A23: Armadietti a noleggio | B23: =Customers!B8*Assumptions!$H$20 | C23: =MAX(0,Customers!C8-Customers!B8)*Assumptions!$H$20 | D23: =MAX(0,Customers!D8-Customers!C8)*Assumptions!$H$20 | E23: =MAX(0,Customers!E8-Customers!D8)*Assumptions!$H$20 | F23: =MAX(0,Customers!F8-Customers!E8)*Assumptions!$H$20 | G23: =MAX(0,Customers!G8-Customers!F8)*Assumptions!$H$20 | H23: =MAX(0,Customers!H8-Customers!G8)*Assumptions!$H$20 | I23: =MAX(0,Customers!I8-Customers!H8)*Assumptions!$H$20 | J23: =MAX(0,Customers!J8-Customers!I8)*Assumptions!$H$20 | ... Y23: =MAX(0,Customers!Y8-Customers!X8)*Assumptions!$H$20 | Z23: =SUM(B23:M23) | AA23: =SUM(N23:Y23) | AB23: =Z23+AA23
A24: Armadietti bagagli | B24: =Customers!B9*Assumptions!$H$21 | C24: =MAX(0,Customers!C9-Customers!B9)*Assumptions!$H$21 | D24: =MAX(0,Customers!D9-Customers!C9)*Assumptions!$H$21 | E24: =MAX(0,Customers!E9-Customers!D9)*Assumptions!$H$21 | F24: =MAX(0,Customers!F9-Customers!E9)*Assumptions!$H$21 | G24: =MAX(0,Customers!G9-Customers!F9)*Assumptions!$H$21 | H24: =MAX(0,Customers!H9-Customers!G9)*Assumptions!$H$21 | I24: =MAX(0,Customers!I9-Customers!H9)*Assumptions!$H$21 | J24: =MAX(0,Customers!J9-Customers!I9)*Assumptions!$H$21 | ... Y24: =MAX(0,Customers!Y9-Customers!X9)*Assumptions!$H$21 | Z24: =SUM(B24:M24) | AA24: =SUM(N24:Y24) | AB24: =Z24+AA24
A25: Noleggio power bank | B25: =Customers!B10*Assumptions!$H$22 | C25: =MAX(0,Customers!C10-Customers!B10)*Assumptions!$H$22 | D25: =MAX(0,Customers!D10-Customers!C10)*Assumptions!$H$22 | E25: =MAX(0,Customers!E10-Customers!D10)*Assumptions!$H$22 | F25: =MAX(0,Customers!F10-Customers!E10)*Assumptions!$H$22 | G25: =MAX(0,Customers!G10-Customers!F10)*Assumptions!$H$22 | H25: =MAX(0,Customers!H10-Customers!G10)*Assumptions!$H$22 | I25: =MAX(0,Customers!I10-Customers!H10)*Assumptions!$H$22 | J25: =MAX(0,Customers!J10-Customers!I10)*Assumptions!$H$22 | ... Y25: =MAX(0,Customers!Y10-Customers!X10)*Assumptions!$H$22 | Z25: =SUM(B25:M25) | AA25: =SUM(N25:Y25) | AB25: =Z25+AA25
A26: Kit IoT Energia | B26: =Customers!B11*Assumptions!$H$23 | C26: =MAX(0,Customers!C11-Customers!B11)*Assumptions!$H$23 | D26: =MAX(0,Customers!D11-Customers!C11)*Assumptions!$H$23 | E26: =MAX(0,Customers!E11-Customers!D11)*Assumptions!$H$23 | F26: =MAX(0,Customers!F11-Customers!E11)*Assumptions!$H$23 | G26: =MAX(0,Customers!G11-Customers!F11)*Assumptions!$H$23 | H26: =MAX(0,Customers!H11-Customers!G11)*Assumptions!$H$23 | I26: =MAX(0,Customers!I11-Customers!H11)*Assumptions!$H$23 | J26: =MAX(0,Customers!J11-Customers!I11)*Assumptions!$H$23 | ... Y26: =MAX(0,Customers!Y11-Customers!X11)*Assumptions!$H$23 | Z26: =SUM(B26:M26) | AA26: =SUM(N26:Y26) | AB26: =Z26+AA26
A27: Healthy Room IoT (qualità aria) | B27: =Customers!B12*Assumptions!$H$24 | C27: =MAX(0,Customers!C12-Customers!B12)*Assumptions!$H$24 | D27: =MAX(0,Customers!D12-Customers!C12)*Assumptions!$H$24 | E27: =MAX(0,Customers!E12-Customers!D12)*Assumptions!$H$24 | F27: =MAX(0,Customers!F12-Customers!E12)*Assumptions!$H$24 | G27: =MAX(0,Customers!G12-Customers!F12)*Assumptions!$H$24 | H27: =MAX(0,Customers!H12-Customers!G12)*Assumptions!$H$24 | I27: =MAX(0,Customers!I12-Customers!H12)*Assumptions!$H$24 | J27: =MAX(0,Customers!J12-Customers!I12)*Assumptions!$H$24 | ... Y27: =MAX(0,Customers!Y12-Customers!X12)*Assumptions!$H$24 | Z27: =SUM(B27:M27) | AA27: =SUM(N27:Y27) | AB27: =Z27+AA27
A28: Marketplace locale (tour, transfer, eSIM) | B28: =Customers!B13*Assumptions!$H$25 | C28: =MAX(0,Customers!C13-Customers!B13)*Assumptions!$H$25 | D28: =MAX(0,Customers!D13-Customers!C13)*Assumptions!$H$25 | E28: =MAX(0,Customers!E13-Customers!D13)*Assumptions!$H$25 | F28: =MAX(0,Customers!F13-Customers!E13)*Assumptions!$H$25 | G28: =MAX(0,Customers!G13-Customers!F13)*Assumptions!$H$25 | H28: =MAX(0,Customers!H13-Customers!G13)*Assumptions!$H$25 | I28: =MAX(0,Customers!I13-Customers!H13)*Assumptions!$H$25 | J28: =MAX(0,Customers!J13-Customers!I13)*Assumptions!$H$25 | ... Y28: =MAX(0,Customers!Y13-Customers!X13)*Assumptions!$H$25 | Z28: =SUM(B28:M28) | AA28: =SUM(N28:Y28) | AB28: =Z28+AA28
A29: Vending regolamentato tramite partner autorizzato (opzione, OFF nel base) | B29: =Customers!B14*Assumptions!$H$26 | C29: =MAX(0,Customers!C14-Customers!B14)*Assumptions!$H$26 | D29: =MAX(0,Customers!D14-Customers!C14)*Assumptions!$H$26 | E29: =MAX(0,Customers!E14-Customers!D14)*Assumptions!$H$26 | F29: =MAX(0,Customers!F14-Customers!E14)*Assumptions!$H$26 | G29: =MAX(0,Customers!G14-Customers!F14)*Assumptions!$H$26 | H29: =MAX(0,Customers!H14-Customers!G14)*Assumptions!$H$26 | I29: =MAX(0,Customers!I14-Customers!H14)*Assumptions!$H$26 | J29: =MAX(0,Customers!J14-Customers!I14)*Assumptions!$H$26 | ... Y29: =MAX(0,Customers!Y14-Customers!X14)*Assumptions!$H$26 | Z29: =SUM(B29:M29) | AA29: =SUM(N29:Y29) | AB29: =Z29+AA29
A30: Ricavi setup | B30: =SUM(B19:B29) | C30: =SUM(C19:C29) | D30: =SUM(D19:D29) | E30: =SUM(E19:E29) | F30: =SUM(F19:F29) | G30: =SUM(G19:G29) | H30: =SUM(H19:H29) | I30: =SUM(I19:I29) | ... Y30: =SUM(Y19:Y29) | Z30: =SUM(B30:M30) | AA30: =SUM(N30:Y30) | AB30: =Z30+AA30
A32: Ricavi totali | B32: =B15+B30 | C32: =C15+C30 | D32: =D15+D30 | E32: =E15+E30 | F32: =F15+F30 | G32: =G15+G30 | H32: =H15+H30 | I32: =I15+I30 | ... Y32: =Y15+Y30 | Z32: =SUM(B32:M32) | AA32: =SUM(N32:Y32) | AB32: =Z32+AA32

Sheet DirectCosts
A1: Costi diretti
A3: Categoria | B3: 1 | C3: 2 | D3: 3 | E3: 4 | F3: 5 | G3: 6 | H3: 7 | I3: 8 | J3: 9 | K3: 10 | L3: 11 | M3: 12 | N3: 13 | O3: 14 | P3: 15 | Q3: 16 | R3: 17 | S3: 18 | T3: 19 | U3: 20 | V3: 21 | W3: 22 | X3: 23 | Y3: 24 | Z3: Anno 1 | AA3: Anno 2 | AB3: 24 mesi
A4: Hotel Agent OS (agenti AI operativi) | B4: =Revenue!B4*Assumptions!$J$16 | C4: =Revenue!C4*Assumptions!$J$16 | D4: =Revenue!D4*Assumptions!$J$16 | E4: =Revenue!E4*Assumptions!$J$16 | F4: =Revenue!F4*Assumptions!$J$16 | G4: =Revenue!G4*Assumptions!$J$16 | H4: =Revenue!H4*Assumptions!$J$16 | I4: =Revenue!I4*Assumptions!$J$16 | ... Y4: =Revenue!Y4*Assumptions!$J$16 | Z4: =SUM(B4:M4) | AA4: =SUM(N4:Y4) | AB4: =Z4+AA4
A5: GuestNode Lobby (terminale in reception) | B5: =Revenue!B5*Assumptions!$J$17 | C5: =Revenue!C5*Assumptions!$J$17 | D5: =Revenue!D5*Assumptions!$J$17 | E5: =Revenue!E5*Assumptions!$J$17 | F5: =Revenue!F5*Assumptions!$J$17 | G5: =Revenue!G5*Assumptions!$J$17 | H5: =Revenue!H5*Assumptions!$J$17 | I5: =Revenue!I5*Assumptions!$J$17 | ... Y5: =Revenue!Y5*Assumptions!$J$17 | Z5: =SUM(B5:M5) | AA5: =SUM(N5:Y5) | AB5: =Z5+AA5
A6: GuestNode in camera | B6: =Revenue!B6*Assumptions!$J$18 | C6: =Revenue!C6*Assumptions!$J$18 | D6: =Revenue!D6*Assumptions!$J$18 | E6: =Revenue!E6*Assumptions!$J$18 | F6: =Revenue!F6*Assumptions!$J$18 | G6: =Revenue!G6*Assumptions!$J$18 | H6: =Revenue!H6*Assumptions!$J$18 | I6: =Revenue!I6*Assumptions!$J$18 | ... Y6: =Revenue!Y6*Assumptions!$J$18 | Z6: =SUM(B6:M6) | AA6: =SUM(N6:Y6) | AB6: =Z6+AA6
A7: Smart Travel Wall (vending/micro-market) | B7: =Revenue!B7*Assumptions!$J$19 | C7: =Revenue!C7*Assumptions!$J$19 | D7: =Revenue!D7*Assumptions!$J$19 | E7: =Revenue!E7*Assumptions!$J$19 | F7: =Revenue!F7*Assumptions!$J$19 | G7: =Revenue!G7*Assumptions!$J$19 | H7: =Revenue!H7*Assumptions!$J$19 | I7: =Revenue!I7*Assumptions!$J$19 | ... Y7: =Revenue!Y7*Assumptions!$J$19 | Z7: =SUM(B7:M7) | AA7: =SUM(N7:Y7) | AB7: =Z7+AA7
A8: Armadietti a noleggio | B8: =Revenue!B8*Assumptions!$J$20 | C8: =Revenue!C8*Assumptions!$J$20 | D8: =Revenue!D8*Assumptions!$J$20 | E8: =Revenue!E8*Assumptions!$J$20 | F8: =Revenue!F8*Assumptions!$J$20 | G8: =Revenue!G8*Assumptions!$J$20 | H8: =Revenue!H8*Assumptions!$J$20 | I8: =Revenue!I8*Assumptions!$J$20 | ... Y8: =Revenue!Y8*Assumptions!$J$20 | Z8: =SUM(B8:M8) | AA8: =SUM(N8:Y8) | AB8: =Z8+AA8
A9: Armadietti bagagli | B9: =Revenue!B9*Assumptions!$J$21 | C9: =Revenue!C9*Assumptions!$J$21 | D9: =Revenue!D9*Assumptions!$J$21 | E9: =Revenue!E9*Assumptions!$J$21 | F9: =Revenue!F9*Assumptions!$J$21 | G9: =Revenue!G9*Assumptions!$J$21 | H9: =Revenue!H9*Assumptions!$J$21 | I9: =Revenue!I9*Assumptions!$J$21 | ... Y9: =Revenue!Y9*Assumptions!$J$21 | Z9: =SUM(B9:M9) | AA9: =SUM(N9:Y9) | AB9: =Z9+AA9
A10: Noleggio power bank | B10: =Revenue!B10*Assumptions!$J$22 | C10: =Revenue!C10*Assumptions!$J$22 | D10: =Revenue!D10*Assumptions!$J$22 | E10: =Revenue!E10*Assumptions!$J$22 | F10: =Revenue!F10*Assumptions!$J$22 | G10: =Revenue!G10*Assumptions!$J$22 | H10: =Revenue!H10*Assumptions!$J$22 | I10: =Revenue!I10*Assumptions!$J$22 | ... Y10: =Revenue!Y10*Assumptions!$J$22 | Z10: =SUM(B10:M10) | AA10: =SUM(N10:Y10) | AB10: =Z10+AA10
A11: Kit IoT Energia | B11: =Revenue!B11*Assumptions!$J$23 | C11: =Revenue!C11*Assumptions!$J$23 | D11: =Revenue!D11*Assumptions!$J$23 | E11: =Revenue!E11*Assumptions!$J$23 | F11: =Revenue!F11*Assumptions!$J$23 | G11: =Revenue!G11*Assumptions!$J$23 | H11: =Revenue!H11*Assumptions!$J$23 | I11: =Revenue!I11*Assumptions!$J$23 | ... Y11: =Revenue!Y11*Assumptions!$J$23 | Z11: =SUM(B11:M11) | AA11: =SUM(N11:Y11) | AB11: =Z11+AA11
A12: Healthy Room IoT (qualità aria) | B12: =Revenue!B12*Assumptions!$J$24 | C12: =Revenue!C12*Assumptions!$J$24 | D12: =Revenue!D12*Assumptions!$J$24 | E12: =Revenue!E12*Assumptions!$J$24 | F12: =Revenue!F12*Assumptions!$J$24 | G12: =Revenue!G12*Assumptions!$J$24 | H12: =Revenue!H12*Assumptions!$J$24 | I12: =Revenue!I12*Assumptions!$J$24 | ... Y12: =Revenue!Y12*Assumptions!$J$24 | Z12: =SUM(B12:M12) | AA12: =SUM(N12:Y12) | AB12: =Z12+AA12
A13: Marketplace locale (tour, transfer, eSIM) | B13: =Revenue!B13*Assumptions!$J$25 | C13: =Revenue!C13*Assumptions!$J$25 | D13: =Revenue!D13*Assumptions!$J$25 | E13: =Revenue!E13*Assumptions!$J$25 | F13: =Revenue!F13*Assumptions!$J$25 | G13: =Revenue!G13*Assumptions!$J$25 | H13: =Revenue!H13*Assumptions!$J$25 | I13: =Revenue!I13*Assumptions!$J$25 | ... Y13: =Revenue!Y13*Assumptions!$J$25 | Z13: =SUM(B13:M13) | AA13: =SUM(N13:Y13) | AB13: =Z13+AA13
A14: Vending regolamentato tramite partner autorizzato (opzione, OFF nel base) | B14: =Revenue!B14*Assumptions!$J$26 | C14: =Revenue!C14*Assumptions!$J$26 | D14: =Revenue!D14*Assumptions!$J$26 | E14: =Revenue!E14*Assumptions!$J$26 | F14: =Revenue!F14*Assumptions!$J$26 | G14: =Revenue!G14*Assumptions!$J$26 | H14: =Revenue!H14*Assumptions!$J$26 | I14: =Revenue!I14*Assumptions!$J$26 | ... Y14: =Revenue!Y14*Assumptions!$J$26 | Z14: =SUM(B14:M14) | AA14: =SUM(N14:Y14) | AB14: =Z14+AA14
A15: 24 mesi | B15: =SUM(B4:B14) | C15: =SUM(C4:C14) | D15: =SUM(D4:D14) | E15: =SUM(E4:E14) | F15: =SUM(F4:F14) | G15: =SUM(G4:G14) | H15: =SUM(H4:H14) | I15: =SUM(I4:I14) | ... Y15: =SUM(Y4:Y14) | Z15: =SUM(B15:M15) | AA15: =SUM(N15:Y15) | AB15: =Z15+AA15

Sheet Capex
A1: Capex (hardware + installazione)
A3: Categoria | B3: 1 | C3: 2 | D3: 3 | E3: 4 | F3: 5 | G3: 6 | H3: 7 | I3: 8 | J3: 9 | K3: 10 | L3: 11 | M3: 12 | N3: 13 | O3: 14 | P3: 15 | Q3: 16 | R3: 17 | S3: 18 | T3: 19 | U3: 20 | V3: 21 | W3: 22 | X3: 23 | Y3: 24 | Z3: Anno 1 | AA3: Anno 2 | AB3: 24 mesi
A4: Hotel Agent OS (agenti AI operativi) | B4: =Customers!B4*Assumptions!$E$16*(Assumptions!$F$16+Assumptions!$G$16)*(1+Assumptions!$B$10) | C4: =MAX(0,Customers!C4-Customers!B4)*Assumptions!$E$16*(Assumptions!$F$16+Assumptions!$G$16)*(1+Assumptions!$B$10) | D4: =MAX(0,Customers!D4-Customers!C4)*Assumptions!$E$16*(Assumptions!$F$16+Assumptions!$G$16)*(1+Assumptions!$B$10) | E4: =MAX(0,Customers!E4-Customers!D4)*Assumptions!$E$16*(Assumptions!$F$16+Assumptions!$G$16)*(1+Assumptions!$B$10) | F4: =MAX(0,Customers!F4-Customers!E4)*Assumptions!$E$16*(Assumptions!$F$16+Assumptions!$G$16)*(1+Assumptions!$B$10) | G4: =MAX(0,Customers!G4-Customers!F4)*Assumptions!$E$16*(Assumptions!$F$16+Assumptions!$G$16)*(1+Assumptions!$B$10) | H4: =MAX(0,Customers!H4-Customers!G4)*Assumptions!$E$16*(Assumptions!$F$16+Assumptions!$G$16)*(1+Assumptions!$B$10) | I4: =MAX(0,Customers!I4-Customers!H4)*Assumptions!$E$16*(Assumptions!$F$16+Assumptions!$G$16)*(1+Assumptions!$B$10) | J4: =MAX(0,Customers!J4-Customers!I4)*Assumptions!$E$16*(Assumptions!$F$16+Assumptions!$G$16)*(1+Assumptions!$B$10) | ... Y4: =MAX(0,Customers!Y4-Customers!X4)*Assumptions!$E$16*(Assumptions!$F$16+Assumptions!$G$16)*(1+Assumptions!$B$10) | Z4: =SUM(B4:M4) | AA4: =SUM(N4:Y4) | AB4: =Z4+AA4
A5: GuestNode Lobby (terminale in reception) | B5: =Customers!B5*Assumptions!$E$17*(Assumptions!$F$17+Assumptions!$G$17)*(1+Assumptions!$B$10) | C5: =MAX(0,Customers!C5-Customers!B5)*Assumptions!$E$17*(Assumptions!$F$17+Assumptions!$G$17)*(1+Assumptions!$B$10) | D5: =MAX(0,Customers!D5-Customers!C5)*Assumptions!$E$17*(Assumptions!$F$17+Assumptions!$G$17)*(1+Assumptions!$B$10) | E5: =MAX(0,Customers!E5-Customers!D5)*Assumptions!$E$17*(Assumptions!$F$17+Assumptions!$G$17)*(1+Assumptions!$B$10) | F5: =MAX(0,Customers!F5-Customers!E5)*Assumptions!$E$17*(Assumptions!$F$17+Assumptions!$G$17)*(1+Assumptions!$B$10) | G5: =MAX(0,Customers!G5-Customers!F5)*Assumptions!$E$17*(Assumptions!$F$17+Assumptions!$G$17)*(1+Assumptions!$B$10) | H5: =MAX(0,Customers!H5-Customers!G5)*Assumptions!$E$17*(Assumptions!$F$17+Assumptions!$G$17)*(1+Assumptions!$B$10) | I5: =MAX(0,Customers!I5-Customers!H5)*Assumptions!$E$17*(Assumptions!$F$17+Assumptions!$G$17)*(1+Assumptions!$B$10) | J5: =MAX(0,Customers!J5-Customers!I5)*Assumptions!$E$17*(Assumptions!$F$17+Assumptions!$G$17)*(1+Assumptions!$B$10) | ... Y5: =MAX(0,Customers!Y5-Customers!X5)*Assumptions!$E$17*(Assumptions!$F$17+Assumptions!$G$17)*(1+Assumptions!$B$10) | Z5: =SUM(B5:M5) | AA5: =SUM(N5:Y5) | AB5: =Z5+AA5
A6: GuestNode in camera | B6: =Customers!B6*Assumptions!$E$18*(Assumptions!$F$18+Assumptions!$G$18)*(1+Assumptions!$B$10) | C6: =MAX(0,Customers!C6-Customers!B6)*Assumptions!$E$18*(Assumptions!$F$18+Assumptions!$G$18)*(1+Assumptions!$B$10) | D6: =MAX(0,Customers!D6-Customers!C6)*Assumptions!$E$18*(Assumptions!$F$18+Assumptions!$G$18)*(1+Assumptions!$B$10) | E6: =MAX(0,Customers!E6-Customers!D6)*Assumptions!$E$18*(Assumptions!$F$18+Assumptions!$G$18)*(1+Assumptions!$B$10) | F6: =MAX(0,Customers!F6-Customers!E6)*Assumptions!$E$18*(Assumptions!$F$18+Assumptions!$G$18)*(1+Assumptions!$B$10) | G6: =MAX(0,Customers!G6-Customers!F6)*Assumptions!$E$18*(Assumptions!$F$18+Assumptions!$G$18)*(1+Assumptions!$B$10) | H6: =MAX(0,Customers!H6-Customers!G6)*Assumptions!$E$18*(Assumptions!$F$18+Assumptions!$G$18)*(1+Assumptions!$B$10) | I6: =MAX(0,Customers!I6-Customers!H6)*Assumptions!$E$18*(Assumptions!$F$18+Assumptions!$G$18)*(1+Assumptions!$B$10) | J6: =MAX(0,Customers!J6-Customers!I6)*Assumptions!$E$18*(Assumptions!$F$18+Assumptions!$G$18)*(1+Assumptions!$B$10) | ... Y6: =MAX(0,Customers!Y6-Customers!X6)*Assumptions!$E$18*(Assumptions!$F$18+Assumptions!$G$18)*(1+Assumptions!$B$10) | Z6: =SUM(B6:M6) | AA6: =SUM(N6:Y6) | AB6: =Z6+AA6
A7: Smart Travel Wall (vending/micro-market) | B7: =Customers!B7*Assumptions!$E$19*(Assumptions!$F$19+Assumptions!$G$19)*(1+Assumptions!$B$10) | C7: =MAX(0,Customers!C7-Customers!B7)*Assumptions!$E$19*(Assumptions!$F$19+Assumptions!$G$19)*(1+Assumptions!$B$10) | D7: =MAX(0,Customers!D7-Customers!C7)*Assumptions!$E$19*(Assumptions!$F$19+Assumptions!$G$19)*(1+Assumptions!$B$10) | E7: =MAX(0,Customers!E7-Customers!D7)*Assumptions!$E$19*(Assumptions!$F$19+Assumptions!$G$19)*(1+Assumptions!$B$10) | F7: =MAX(0,Customers!F7-Customers!E7)*Assumptions!$E$19*(Assumptions!$F$19+Assumptions!$G$19)*(1+Assumptions!$B$10) | G7: =MAX(0,Customers!G7-Customers!F7)*Assumptions!$E$19*(Assumptions!$F$19+Assumptions!$G$19)*(1+Assumptions!$B$10) | H7: =MAX(0,Customers!H7-Customers!G7)*Assumptions!$E$19*(Assumptions!$F$19+Assumptions!$G$19)*(1+Assumptions!$B$10) | I7: =MAX(0,Customers!I7-Customers!H7)*Assumptions!$E$19*(Assumptions!$F$19+Assumptions!$G$19)*(1+Assumptions!$B$10) | J7: =MAX(0,Customers!J7-Customers!I7)*Assumptions!$E$19*(Assumptions!$F$19+Assumptions!$G$19)*(1+Assumptions!$B$10) | ... Y7: =MAX(0,Customers!Y7-Customers!X7)*Assumptions!$E$19*(Assumptions!$F$19+Assumptions!$G$19)*(1+Assumptions!$B$10) | Z7: =SUM(B7:M7) | AA7: =SUM(N7:Y7) | AB7: =Z7+AA7
A8: Armadietti a noleggio | B8: =Customers!B8*Assumptions!$E$20*(Assumptions!$F$20+Assumptions!$G$20)*(1+Assumptions!$B$10) | C8: =MAX(0,Customers!C8-Customers!B8)*Assumptions!$E$20*(Assumptions!$F$20+Assumptions!$G$20)*(1+Assumptions!$B$10) | D8: =MAX(0,Customers!D8-Customers!C8)*Assumptions!$E$20*(Assumptions!$F$20+Assumptions!$G$20)*(1+Assumptions!$B$10) | E8: =MAX(0,Customers!E8-Customers!D8)*Assumptions!$E$20*(Assumptions!$F$20+Assumptions!$G$20)*(1+Assumptions!$B$10) | F8: =MAX(0,Customers!F8-Customers!E8)*Assumptions!$E$20*(Assumptions!$F$20+Assumptions!$G$20)*(1+Assumptions!$B$10) | G8: =MAX(0,Customers!G8-Customers!F8)*Assumptions!$E$20*(Assumptions!$F$20+Assumptions!$G$20)*(1+Assumptions!$B$10) | H8: =MAX(0,Customers!H8-Customers!G8)*Assumptions!$E$20*(Assumptions!$F$20+Assumptions!$G$20)*(1+Assumptions!$B$10) | I8: =MAX(0,Customers!I8-Customers!H8)*Assumptions!$E$20*(Assumptions!$F$20+Assumptions!$G$20)*(1+Assumptions!$B$10) | J8: =MAX(0,Customers!J8-Customers!I8)*Assumptions!$E$20*(Assumptions!$F$20+Assumptions!$G$20)*(1+Assumptions!$B$10) | ... Y8: =MAX(0,Customers!Y8-Customers!X8)*Assumptions!$E$20*(Assumptions!$F$20+Assumptions!$G$20)*(1+Assumptions!$B$10) | Z8: =SUM(B8:M8) | AA8: =SUM(N8:Y8) | AB8: =Z8+AA8
A9: Armadietti bagagli | B9: =Customers!B9*Assumptions!$E$21*(Assumptions!$F$21+Assumptions!$G$21)*(1+Assumptions!$B$10) | C9: =MAX(0,Customers!C9-Customers!B9)*Assumptions!$E$21*(Assumptions!$F$21+Assumptions!$G$21)*(1+Assumptions!$B$10) | D9: =MAX(0,Customers!D9-Customers!C9)*Assumptions!$E$21*(Assumptions!$F$21+Assumptions!$G$21)*(1+Assumptions!$B$10) | E9: =MAX(0,Customers!E9-Customers!D9)*Assumptions!$E$21*(Assumptions!$F$21+Assumptions!$G$21)*(1+Assumptions!$B$10) | F9: =MAX(0,Customers!F9-Customers!E9)*Assumptions!$E$21*(Assumptions!$F$21+Assumptions!$G$21)*(1+Assumptions!$B$10) | G9: =MAX(0,Customers!G9-Customers!F9)*Assumptions!$E$21*(Assumptions!$F$21+Assumptions!$G$21)*(1+Assumptions!$B$10) | H9: =MAX(0,Customers!H9-Customers!G9)*Assumptions!$E$21*(Assumptions!$F$21+Assumptions!$G$21)*(1+Assumptions!$B$10) | I9: =MAX(0,Customers!I9-Customers!H9)*Assumptions!$E$21*(Assumptions!$F$21+Assumptions!$G$21)*(1+Assumptions!$B$10) | J9: =MAX(0,Customers!J9-Customers!I9)*Assumptions!$E$21*(Assumptions!$F$21+Assumptions!$G$21)*(1+Assumptions!$B$10) | ... Y9: =MAX(0,Customers!Y9-Customers!X9)*Assumptions!$E$21*(Assumptions!$F$21+Assumptions!$G$21)*(1+Assumptions!$B$10) | Z9: =SUM(B9:M9) | AA9: =SUM(N9:Y9) | AB9: =Z9+AA9
A10: Noleggio power bank | B10: =Customers!B10*Assumptions!$E$22*(Assumptions!$F$22+Assumptions!$G$22)*(1+Assumptions!$B$10) | C10: =MAX(0,Customers!C10-Customers!B10)*Assumptions!$E$22*(Assumptions!$F$22+Assumptions!$G$22)*(1+Assumptions!$B$10) | D10: =MAX(0,Customers!D10-Customers!C10)*Assumptions!$E$22*(Assumptions!$F$22+Assumptions!$G$22)*(1+Assumptions!$B$10) | E10: =MAX(0,Customers!E10-Customers!D10)*Assumptions!$E$22*(Assumptions!$F$22+Assumptions!$G$22)*(1+Assumptions!$B$10) | F10: =MAX(0,Customers!F10-Customers!E10)*Assumptions!$E$22*(Assumptions!$F$22+Assumptions!$G$22)*(1+Assumptions!$B$10) | G10: =MAX(0,Customers!G10-Customers!F10)*Assumptions!$E$22*(Assumptions!$F$22+Assumptions!$G$22)*(1+Assumptions!$B$10) | H10: =MAX(0,Customers!H10-Customers!G10)*Assumptions!$E$22*(Assumptions!$F$22+Assumptions!$G$22)*(1+Assumptions!$B$10) | I10: =MAX(0,Customers!I10-Customers!H10)*Assumptions!$E$22*(Assumptions!$F$22+Assumptions!$G$22)*(1+Assumptions!$B$10) | J10: =MAX(0,Customers!J10-Customers!I10)*Assumptions!$E$22*(Assumptions!$F$22+Assumptions!$G$22)*(1+Assumptions!$B$10) | ... Y10: =MAX(0,Customers!Y10-Customers!X10)*Assumptions!$E$22*(Assumptions!$F$22+Assumptions!$G$22)*(1+Assumptions!$B$10) | Z10: =SUM(B10:M10) | AA10: =SUM(N10:Y10) | AB10: =Z10+AA10
A11: Kit IoT Energia | B11: =Customers!B11*Assumptions!$E$23*(Assumptions!$F$23+Assumptions!$G$23)*(1+Assumptions!$B$10) | C11: =MAX(0,Customers!C11-Customers!B11)*Assumptions!$E$23*(Assumptions!$F$23+Assumptions!$G$23)*(1+Assumptions!$B$10) | D11: =MAX(0,Customers!D11-Customers!C11)*Assumptions!$E$23*(Assumptions!$F$23+Assumptions!$G$23)*(1+Assumptions!$B$10) | E11: =MAX(0,Customers!E11-Customers!D11)*Assumptions!$E$23*(Assumptions!$F$23+Assumptions!$G$23)*(1+Assumptions!$B$10) | F11: =MAX(0,Customers!F11-Customers!E11)*Assumptions!$E$23*(Assumptions!$F$23+Assumptions!$G$23)*(1+Assumptions!$B$10) | G11: =MAX(0,Customers!G11-Customers!F11)*Assumptions!$E$23*(Assumptions!$F$23+Assumptions!$G$23)*(1+Assumptions!$B$10) | H11: =MAX(0,Customers!H11-Customers!G11)*Assumptions!$E$23*(Assumptions!$F$23+Assumptions!$G$23)*(1+Assumptions!$B$10) | I11: =MAX(0,Customers!I11-Customers!H11)*Assumptions!$E$23*(Assumptions!$F$23+Assumptions!$G$23)*(1+Assumptions!$B$10) | J11: =MAX(0,Customers!J11-Customers!I11)*Assumptions!$E$23*(Assumptions!$F$23+Assumptions!$G$23)*(1+Assumptions!$B$10) | ... Y11: =MAX(0,Customers!Y11-Customers!X11)*Assumptions!$E$23*(Assumptions!$F$23+Assumptions!$G$23)*(1+Assumptions!$B$10) | Z11: =SUM(B11:M11) | AA11: =SUM(N11:Y11) | AB11: =Z11+AA11
A12: Healthy Room IoT (qualità aria) | B12: =Customers!B12*Assumptions!$E$24*(Assumptions!$F$24+Assumptions!$G$24)*(1+Assumptions!$B$10) | C12: =MAX(0,Customers!C12-Customers!B12)*Assumptions!$E$24*(Assumptions!$F$24+Assumptions!$G$24)*(1+Assumptions!$B$10) | D12: =MAX(0,Customers!D12-Customers!C12)*Assumptions!$E$24*(Assumptions!$F$24+Assumptions!$G$24)*(1+Assumptions!$B$10) | E12: =MAX(0,Customers!E12-Customers!D12)*Assumptions!$E$24*(Assumptions!$F$24+Assumptions!$G$24)*(1+Assumptions!$B$10) | F12: =MAX(0,Customers!F12-Customers!E12)*Assumptions!$E$24*(Assumptions!$F$24+Assumptions!$G$24)*(1+Assumptions!$B$10) | G12: =MAX(0,Customers!G12-Customers!F12)*Assumptions!$E$24*(Assumptions!$F$24+Assumptions!$G$24)*(1+Assumptions!$B$10) | H12: =MAX(0,Customers!H12-Customers!G12)*Assumptions!$E$24*(Assumptions!$F$24+Assumptions!$G$24)*(1+Assumptions!$B$10) | I12: =MAX(0,Customers!I12-Customers!H12)*Assumptions!$E$24*(Assumptions!$F$24+Assumptions!$G$24)*(1+Assumptions!$B$10) | J12: =MAX(0,Customers!J12-Customers!I12)*Assumptions!$E$24*(Assumptions!$F$24+Assumptions!$G$24)*(1+Assumptions!$B$10) | ... Y12: =MAX(0,Customers!Y12-Customers!X12)*Assumptions!$E$24*(Assumptions!$F$24+Assumptions!$G$24)*(1+Assumptions!$B$10) | Z12: =SUM(B12:M12) | AA12: =SUM(N12:Y12) | AB12: =Z12+AA12
