Workbook

Sheet Сводка
B2: Модель запуска в Лигурии: hardware + agent-сервисы для отелей (EUR, без НДС)
B3: ВСЕ финансовые входные данные на листе «Допущения» — плановые заглушки (синие), НЕ котировки поставщиков и НЕ проверенные рыночные данные. Заменить реальными предложениями до любого инвестиционного решения.
B5: Показатель | C5: Значение
B6: Активный сценарий | C6: =CHOOSE('Допущения'!C5,"Lean","Base","Regional")
B7: Выручка, год 1 | C7: ='PnL'!AB8
B8: Выручка, год 2 | C8: ='PnL'!AC8
B9: EBITDA, год 1 | C9: ='PnL'!AB15
B10: EBITDA, год 2 | C10: ='PnL'!AC15
B11: Чистый результат за 24 мес. | C11: ='PnL'!AD17
B12: Первый месяц с EBITDA > 0 | C12: =IF(MIN('PnL'!D19:AA19)=99,"н/д",MIN('PnL'!D19:AA19))
B13: Пиковая потребность в финансировании | C13: =MAX(0,-MIN('Cashflow'!D14:AA14))
B14: Минимальный остаток денег | C14: =MIN('Cashflow'!D13:AA13)
B15: Активные объекты, месяц 12 | C15: ='Модель'!O5
B16: Активные объекты, месяц 24 | C16: ='Модель'!AA5
B17: Run-rate recurring+txn x12, месяц 24 | C17: =('PnL'!AA6+'PnL'!AA7)*12
B18: Валовая маржа, год 2 | C18: ='PnL'!AC12
B21: Index
B22: Допущения
B23: Сценарии
B24: Модель
B25: PnL
B26: Cashflow
B27: Экон_категорий
B28: Лицензии
B29: Риски
B30: Долговечность
B31: Примечания

Sheet Допущения
B2: Модель запуска в Лигурии: hardware + agent-сервисы для отелей (EUR, без НДС)
B3: ВСЕ финансовые входные данные на листе «Допущения» — плановые заглушки (синие), НЕ котировки поставщиков и НЕ проверенные рыночные данные. Заменить реальными предложениями до любого инвестиционного решения.
B4: Общие параметры
B5: Сценарий (1=Lean, 2=Base, 3=Regional) | C5: 2
B6: Месячный churn объектов | C6: 0.008
B7: Стартовый капитал, EUR | C7: 60000
B8: Налог на положительный месячный результат (упрощённо IRES+IRAP) | C8: 0.279
B9: Доля выручки, собираемая в том же месяце | C9: 0.5
B14: Категория | C14: Landed-стоимость HW / ед. | D14: Установка / настройка / ед. | E14: Разовая цена / ед. | F14: Ежемесячно (SaaS/lease) / ед. | G14: Маржа транзакций / мес / ед. | H14: Перем. затраты / мес / ед. | I14: Ед. на объект | J14: Attach rate (доля новых объектов) | K14: Месяц запуска | L14: ID
B15: Hotel Agent OS (платформа агентов) | C15: 0 | D15: 600 | E15: 1500 | F15: 250 | G15: 0 | H15: 60 | I15: 1 | J15: 1 | K15: 1 | L15: C01
B16: GuestNode Lobby (ресепшен) | C16: 280 | D16: 60 | E16: 590 | F16: 40 | G16: 15 | H16: 8 | I16: 1 | J16: 0.5 | K16: 3 | L16: C02
B17: GuestNode в номере | C17: 95 | D17: 15 | E17: 180 | F17: 6 | G17: 0 | H17: 2.5 | I17: 12 | J17: 0.2 | K17: 6 | L17: C03
B18: Smart Travel Wall (микро-магазин) | C18: 2800 | D18: 250 | E18: 4200 | F18: 60 | G18: 150 | H18: 40 | I18: 1 | J18: 0.25 | K18: 4 | L18: C04
B19: Rental-локеры | C19: 900 | D19: 120 | E19: 1500 | F19: 20 | G19: 60 | H19: 10 | I19: 1 | J19: 0.25 | K19: 4 | L19: C05
B20: Локеры для багажа | C20: 1800 | D20: 200 | E20: 2800 | F20: 25 | G20: 90 | H20: 10 | I20: 1 | J20: 0.15 | K20: 6 | L20: C06
B21: Аренда power bank | C21: 700 | D21: 60 | E21: 1100 | F21: 15 | G21: 45 | H21: 12 | I21: 1 | J21: 0.15 | K21: 6 | L21: C07
B22: IoT-комплект энергосбережения (на номер) | C22: 70 | D22: 25 | E22: 140 | F22: 3 | G22: 0 | H22: 0.8 | I22: 25 | J22: 0.3 | K22: 3 | L22: C08
B23: Smart access (на дверь) | C23: 130 | D23: 40 | E23: 260 | F23: 2 | G23: 0 | H23: 0.5 | I23: 15 | J23: 0.15 | K23: 8 | L23: C09
B24: Датчики Healthy Room (на номер) | C24: 45 | D24: 10 | E24: 90 | F24: 1.5 | G24: 0 | H24: 0.4 | I24: 15 | J24: 0.1 | K24: 9 | L24: C10
B25: Киоск check-in / ID | C25: 1500 | D25: 150 | E25: 2600 | F25: 50 | G25: 10 | H25: 15 | I25: 1 | J25: 0.1 | K25: 8 | L25: C11
B26: Локальный marketplace | C26: 0 | D26: 0 | E26: 0 | F26: 0 | G26: 120 | H26: 5 | I26: 1 | J26: 0.4 | K26: 5 | L26: C12
... B29: Регулируемый vending (только fee лицензированного партнёра) | C29: 0 | D29: 0 | E29: 0 | F29: 0 | G29: 80 | H29: 10 | I29: 1 | J29: 0 | K29: 12 | L29: C15
B32: Постоянные ежемесячные расходы
B33: Категория | C33: EUR / мес | D33: Месяц старта
B34: Founder/FDE-инженер | C34: 3500 | D34: 1
B35: Продажи и партнёрства (part-time) | C35: 2000 | D35: 3
B36: Монтажник/поддержка (подряд) | C36: 1500 | D36: 4
B37: Cloud + LLM (база) | C37: 400 | D37: 1
B38: Юристы, compliance, бухгалтерия | C38: 900 | D38: 1
B39: Маркетинг и выставки | C39: 800 | D39: 1
B40: Страхование | C40: 250 | D40: 2
B41: Склад/офис | C41: 400 | D41: 2
B42: Поездки | C42: 500 | D42: 1
B45: Разовые расходы запуска (месяц 1)
B46: Предсертификационный аудит CE/RED/EMC | C46: 6000
B47: Пробные партии у OEM | C47: 5000
B48: Юр. подготовка (контракты, GDPR/DPA) | C48: 4000
B49: Демо-комплект | C49: 3500
B50: Бренд и сайт | C50: 2000

Sheet Сценарии
B2: Новые объекты / мес
B4: Месяц | C4: 1 | D4: 2 | E4: 3 | F4: 4 | G4: 5 | H4: 6 | I4: 7 | J4: 8 | K4: 9 | L4: 10 | M4: 11 | N4: 12 | O4: 13 | P4: 14 | Q4: 15 | R4: 16 | S4: 17 | T4: 18 | U4: 19 | V4: 20 | W4: 21 | X4: 22 | Y4: 23 | Z4: 24
B5: Lean | C5: 0 | D5: 0 | E5: 1 | F5: 1 | G5: 1 | H5: 1 | I5: 1 | J5: 1 | K5: 1 | L5: 1 | M5: 1 | N5: 1 | O5: 2 | P5: 2 | Q5: 2 | R5: 2 | S5: 2 | T5: 2 | U5: 2 | V5: 2 | W5: 2 | X5: 2 | Y5: 2 | Z5: 2
B6: Base | C6: 0 | D6: 0 | E6: 2 | F6: 2 | G6: 2 | H6: 2 | I6: 4 | J6: 4 | K6: 4 | L6: 4 | M6: 4 | N6: 4 | O6: 4 | P6: 4 | Q6: 4 | R6: 4 | S6: 4 | T6: 4 | U6: 4 | V6: 4 | W6: 4 | X6: 4 | Y6: 4 | Z6: 4
B7: Regional | C7: 0 | D7: 0 | E7: 4 | F7: 4 | G7: 4 | H7: 4 | I7: 8 | J7: 8 | K7: 8 | L7: 8 | M7: 8 | N7: 8 | O7: 8 | P7: 8 | Q7: 8 | R7: 8 | S7: 8 | T7: 8 | U7: 8 | V7: 8 | W7: 8 | X7: 8 | Y7: 8 | Z7: 8
B8: Выбранный сценарий | C8: =CHOOSE('Допущения'!$C$5,C5,C6,C7) | D8: =CHOOSE('Допущения'!$C$5,D5,D6,D7) | E8: =CHOOSE('Допущения'!$C$5,E5,E6,E7) | F8: =CHOOSE('Допущения'!$C$5,F5,F6,F7) | G8: =CHOOSE('Допущения'!$C$5,G5,G6,G7) | H8: =CHOOSE('Допущения'!$C$5,H5,H6,H7) | I8: =CHOOSE('Допущения'!$C$5,I5,I6,I7) | J8: =CHOOSE('Допущения'!$C$5,J5,J6,J7) | ... Z8: =CHOOSE('Допущения'!$C$5,Z5,Z6,Z7)

Sheet Модель
B1: Модель запуска в Лигурии: hardware + agent-сервисы для отелей (EUR, без НДС)
A3: ID | B3: Категория | C3: metric | D3: 1 | E3: 2 | F3: 3 | G3: 4 | H3: 5 | I3: 6 | J3: 7 | K3: 8 | L3: 9 | M3: 10 | N3: 11 | O3: 12 | P3: 13 | Q3: 14 | R3: 15 | S3: 16 | T3: 17 | U3: 18 | V3: 19 | W3: 20 | X3: 21 | Y3: 22 | Z3: 23 | AA3: 24 | AB3: 24 мес.
B4: Новые объекты / мес | D4: ='Сценарии'!C8 | E4: ='Сценарии'!D8 | F4: ='Сценарии'!E8 | G4: ='Сценарии'!F8 | H4: ='Сценарии'!G8 | I4: ='Сценарии'!H8 | J4: ='Сценарии'!I8 | K4: ='Сценарии'!J8 | ... AA4: ='Сценарии'!Z8
B5: Активные объекты | D5: =D4 | E5: =D5*(1-'Допущения'!$C$6)+E4 | F5: =E5*(1-'Допущения'!$C$6)+F4 | G5: =F5*(1-'Допущения'!$C$6)+G4 | H5: =G5*(1-'Допущения'!$C$6)+H4 | I5: =H5*(1-'Допущения'!$C$6)+I4 | J5: =I5*(1-'Допущения'!$C$6)+J4 | K5: =J5*(1-'Допущения'!$C$6)+K4 | L5: =K5*(1-'Допущения'!$C$6)+L4 | ... AA5: =Z5*(1-'Допущения'!$C$6)+AA4
A7: C01 | B7: Hotel Agent OS (платформа агентов) | C7: NEWU | D7: =IF(D$3>='Допущения'!$K$15,D$4*'Допущения'!$J$15*'Допущения'!$I$15,0) | E7: =IF(E$3>='Допущения'!$K$15,E$4*'Допущения'!$J$15*'Допущения'!$I$15,0) | F7: =IF(F$3>='Допущения'!$K$15,F$4*'Допущения'!$J$15*'Допущения'!$I$15,0) | G7: =IF(G$3>='Допущения'!$K$15,G$4*'Допущения'!$J$15*'Допущения'!$I$15,0) | H7: =IF(H$3>='Допущения'!$K$15,H$4*'Допущения'!$J$15*'Допущения'!$I$15,0) | I7: =IF(I$3>='Допущения'!$K$15,I$4*'Допущения'!$J$15*'Допущения'!$I$15,0) | J7: =IF(J$3>='Допущения'!$K$15,J$4*'Допущения'!$J$15*'Допущения'!$I$15,0) | K7: =IF(K$3>='Допущения'!$K$15,K$4*'Допущения'!$J$15*'Допущения'!$I$15,0) | ... AA7: =IF(AA$3>='Допущения'!$K$15,AA$4*'Допущения'!$J$15*'Допущения'!$I$15,0) | AB7: =SUM(D7:AA7)
A8: C01 | B8: Hotel Agent OS (платформа агентов) | C8: ACTU | D8: =D7 | E8: =D8*(1-'Допущения'!$C$6)+E7 | F8: =E8*(1-'Допущения'!$C$6)+F7 | G8: =F8*(1-'Допущения'!$C$6)+G7 | H8: =G8*(1-'Допущения'!$C$6)+H7 | I8: =H8*(1-'Допущения'!$C$6)+I7 | J8: =I8*(1-'Допущения'!$C$6)+J7 | K8: =J8*(1-'Допущения'!$C$6)+K7 | L8: =K8*(1-'Допущения'!$C$6)+L7 | ... AA8: =Z8*(1-'Допущения'!$C$6)+AA7 | AB8: =SUM(D8:AA8)
A9: C01 | B9: Hotel Agent OS (платформа агентов) | C9: HWREV | D9: =D7*'Допущения'!$E$15 | E9: =E7*'Допущения'!$E$15 | F9: =F7*'Допущения'!$E$15 | G9: =G7*'Допущения'!$E$15 | H9: =H7*'Допущения'!$E$15 | I9: =I7*'Допущения'!$E$15 | J9: =J7*'Допущения'!$E$15 | K9: =K7*'Допущения'!$E$15 | ... AA9: =AA7*'Допущения'!$E$15 | AB9: =SUM(D9:AA9)
A10: C01 | B10: Hotel Agent OS (платформа агентов) | C10: RECREV | D10: =D8*'Допущения'!$F$15 | E10: =E8*'Допущения'!$F$15 | F10: =F8*'Допущения'!$F$15 | G10: =G8*'Допущения'!$F$15 | H10: =H8*'Допущения'!$F$15 | I10: =I8*'Допущения'!$F$15 | J10: =J8*'Допущения'!$F$15 | K10: =K8*'Допущения'!$F$15 | ... AA10: =AA8*'Допущения'!$F$15 | AB10: =SUM(D10:AA10)
A11: C01 | B11: Hotel Agent OS (платформа агентов) | C11: TXNREV | D11: =D8*'Допущения'!$G$15 | E11: =E8*'Допущения'!$G$15 | F11: =F8*'Допущения'!$G$15 | G11: =G8*'Допущения'!$G$15 | H11: =H8*'Допущения'!$G$15 | I11: =I8*'Допущения'!$G$15 | J11: =J8*'Допущения'!$G$15 | K11: =K8*'Допущения'!$G$15 | ... AA11: =AA8*'Допущения'!$G$15 | AB11: =SUM(D11:AA11)
A12: C01 | B12: Hotel Agent OS (платформа агентов) | C12: COGS | D12: =D7*('Допущения'!$C$15+'Допущения'!$D$15) | E12: =E7*('Допущения'!$C$15+'Допущения'!$D$15) | F12: =F7*('Допущения'!$C$15+'Допущения'!$D$15) | G12: =G7*('Допущения'!$C$15+'Допущения'!$D$15) | H12: =H7*('Допущения'!$C$15+'Допущения'!$D$15) | I12: =I7*('Допущения'!$C$15+'Допущения'!$D$15) | J12: =J7*('Допущения'!$C$15+'Допущения'!$D$15) | K12: =K7*('Допущения'!$C$15+'Допущения'!$D$15) | ... AA12: =AA7*('Допущения'!$C$15+'Допущения'!$D$15) | AB12: =SUM(D12:AA12)
A13: C01 | B13: Hotel Agent OS (платформа агентов) | C13: VARC | D13: =D8*'Допущения'!$H$15 | E13: =E8*'Допущения'!$H$15 | F13: =F8*'Допущения'!$H$15 | G13: =G8*'Допущения'!$H$15 | H13: =H8*'Допущения'!$H$15 | I13: =I8*'Допущения'!$H$15 | J13: =J8*'Допущения'!$H$15 | K13: =K8*'Допущения'!$H$15 | ... AA13: =AA8*'Допущения'!$H$15 | AB13: =SUM(D13:AA13)
A14: C02 | B14: GuestNode Lobby (ресепшен) | C14: NEWU | D14: =IF(D$3>='Допущения'!$K$16,D$4*'Допущения'!$J$16*'Допущения'!$I$16,0) | E14: =IF(E$3>='Допущения'!$K$16,E$4*'Допущения'!$J$16*'Допущения'!$I$16,0) | F14: =IF(F$3>='Допущения'!$K$16,F$4*'Допущения'!$J$16*'Допущения'!$I$16,0) | G14: =IF(G$3>='Допущения'!$K$16,G$4*'Допущения'!$J$16*'Допущения'!$I$16,0) | H14: =IF(H$3>='Допущения'!$K$16,H$4*'Допущения'!$J$16*'Допущения'!$I$16,0) | I14: =IF(I$3>='Допущения'!$K$16,I$4*'Допущения'!$J$16*'Допущения'!$I$16,0) | J14: =IF(J$3>='Допущения'!$K$16,J$4*'Допущения'!$J$16*'Допущения'!$I$16,0) | K14: =IF(K$3>='Допущения'!$K$16,K$4*'Допущения'!$J$16*'Допущения'!$I$16,0) | ... AA14: =IF(AA$3>='Допущения'!$K$16,AA$4*'Допущения'!$J$16*'Допущения'!$I$16,0) | AB14: =SUM(D14:AA14)
A15: C02 | B15: GuestNode Lobby (ресепшен) | C15: ACTU | D15: =D14 | E15: =D15*(1-'Допущения'!$C$6)+E14 | F15: =E15*(1-'Допущения'!$C$6)+F14 | G15: =F15*(1-'Допущения'!$C$6)+G14 | H15: =G15*(1-'Допущения'!$C$6)+H14 | I15: =H15*(1-'Допущения'!$C$6)+I14 | J15: =I15*(1-'Допущения'!$C$6)+J14 | K15: =J15*(1-'Допущения'!$C$6)+K14 | L15: =K15*(1-'Допущения'!$C$6)+L14 | ... AA15: =Z15*(1-'Допущения'!$C$6)+AA14 | AB15: =SUM(D15:AA15)
A16: C02 | B16: GuestNode Lobby (ресепшен) | C16: HWREV | D16: =D14*'Допущения'!$E$16 | E16: =E14*'Допущения'!$E$16 | F16: =F14*'Допущения'!$E$16 | G16: =G14*'Допущения'!$E$16 | H16: =H14*'Допущения'!$E$16 | I16: =I14*'Допущения'!$E$16 | J16: =J14*'Допущения'!$E$16 | K16: =K14*'Допущения'!$E$16 | ... AA16: =AA14*'Допущения'!$E$16 | AB16: =SUM(D16:AA16)
A17: C02 | B17: GuestNode Lobby (ресепшен) | C17: RECREV | D17: =D15*'Допущения'!$F$16 | E17: =E15*'Допущения'!$F$16 | F17: =F15*'Допущения'!$F$16 | G17: =G15*'Допущения'!$F$16 | H17: =H15*'Допущения'!$F$16 | I17: =I15*'Допущения'!$F$16 | J17: =J15*'Допущения'!$F$16 | K17: =K15*'Допущения'!$F$16 | ... AA17: =AA15*'Допущения'!$F$16 | AB17: =SUM(D17:AA17)
A18: C02 | B18: GuestNode Lobby (ресепшен) | C18: TXNREV | D18: =D15*'Допущения'!$G$16 | E18: =E15*'Допущения'!$G$16 | F18: =F15*'Допущения'!$G$16 | G18: =G15*'Допущения'!$G$16 | H18: =H15*'Допущения'!$G$16 | I18: =I15*'Допущения'!$G$16 | J18: =J15*'Допущения'!$G$16 | K18: =K15*'Допущения'!$G$16 | ... AA18: =AA15*'Допущения'!$G$16 | AB18: =SUM(D18:AA18)
A19: C02 | B19: GuestNode Lobby (ресепшен) | C19: COGS | D19: =D14*('Допущения'!$C$16+'Допущения'!$D$16) | E19: =E14*('Допущения'!$C$16+'Допущения'!$D$16) | F19: =F14*('Допущения'!$C$16+'Допущения'!$D$16) | G19: =G14*('Допущения'!$C$16+'Допущения'!$D$16) | H19: =H14*('Допущения'!$C$16+'Допущения'!$D$16) | I19: =I14*('Допущения'!$C$16+'Допущения'!$D$16) | J19: =J14*('Допущения'!$C$16+'Допущения'!$D$16) | K19: =K14*('Допущения'!$C$16+'Допущения'!$D$16) | ... AA19: =AA14*('Допущения'!$C$16+'Допущения'!$D$16) | AB19: =SUM(D19:AA19)
A20: C02 | B20: GuestNode Lobby (ресепшен) | C20: VARC | D20: =D15*'Допущения'!$H$16 | E20: =E15*'Допущения'!$H$16 | F20: =F15*'Допущения'!$H$16 | G20: =G15*'Допущения'!$H$16 | H20: =H15*'Допущения'!$H$16 | I20: =I15*'Допущения'!$H$16 | J20: =J15*'Допущения'!$H$16 | K20: =K15*'Допущения'!$H$16 | ... AA20: =AA15*'Допущения'!$H$16 | AB20: =SUM(D20:AA20)
A21: C03 | B21: GuestNode в номере | C21: NEWU | D21: =IF(D$3>='Допущения'!$K$17,D$4*'Допущения'!$J$17*'Допущения'!$I$17,0) | E21: =IF(E$3>='Допущения'!$K$17,E$4*'Допущения'!$J$17*'Допущения'!$I$17,0) | F21: =IF(F$3>='Допущения'!$K$17,F$4*'Допущения'!$J$17*'Допущения'!$I$17,0) | G21: =IF(G$3>='Допущения'!$K$17,G$4*'Допущения'!$J$17*'Допущения'!$I$17,0) | H21: =IF(H$3>='Допущения'!$K$17,H$4*'Допущения'!$J$17*'Допущения'!$I$17,0) | I21: =IF(I$3>='Допущения'!$K$17,I$4*'Допущения'!$J$17*'Допущения'!$I$17,0) | J21: =IF(J$3>='Допущения'!$K$17,J$4*'Допущения'!$J$17*'Допущения'!$I$17,0) | K21: =IF(K$3>='Допущения'!$K$17,K$4*'Допущения'!$J$17*'Допущения'!$I$17,0) | ... AA21: =IF(AA$3>='Допущения'!$K$17,AA$4*'Допущения'!$J$17*'Допущения'!$I$17,0) | AB21: =SUM(D21:AA21)
A22: C03 | B22: GuestNode в номере | C22: ACTU | D22: =D21 | E22: =D22*(1-'Допущения'!$C$6)+E21 | F22: =E22*(1-'Допущения'!$C$6)+F21 | G22: =F22*(1-'Допущения'!$C$6)+G21 | H22: =G22*(1-'Допущения'!$C$6)+H21 | I22: =H22*(1-'Допущения'!$C$6)+I21 | J22: =I22*(1-'Допущения'!$C$6)+J21 | K22: =J22*(1-'Допущения'!$C$6)+K21 | L22: =K22*(1-'Допущения'!$C$6)+L21 | ... AA22: =Z22*(1-'Допущения'!$C$6)+AA21 | AB22: =SUM(D22:AA22)
A23: C03 | B23: GuestNode в номере | C23: HWREV | D23: =D21*'Допущения'!$E$17 | E23: =E21*'Допущения'!$E$17 | F23: =F21*'Допущения'!$E$17 | G23: =G21*'Допущения'!$E$17 | H23: =H21*'Допущения'!$E$17 | I23: =I21*'Допущения'!$E$17 | J23: =J21*'Допущения'!$E$17 | K23: =K21*'Допущения'!$E$17 | ... AA23: =AA21*'Допущения'!$E$17 | AB23: =SUM(D23:AA23)
A24: C03 | B24: GuestNode в номере | C24: RECREV | D24: =D22*'Допущения'!$F$17 | E24: =E22*'Допущения'!$F$17 | F24: =F22*'Допущения'!$F$17 | G24: =G22*'Допущения'!$F$17 | H24: =H22*'Допущения'!$F$17 | I24: =I22*'Допущения'!$F$17 | J24: =J22*'Допущения'!$F$17 | K24: =K22*'Допущения'!$F$17 | ... AA24: =AA22*'Допущения'!$F$17 | AB24: =SUM(D24:AA24)
A25: C03 | B25: GuestNode в номере | C25: TXNREV | D25: =D22*'Допущения'!$G$17 | E25: =E22*'Допущения'!$G$17 | F25: =F22*'Допущения'!$G$17 | G25: =G22*'Допущения'!$G$17 | H25: =H22*'Допущения'!$G$17 | I25: =I22*'Допущения'!$G$17 | J25: =J22*'Допущения'!$G$17 | K25: =K22*'Допущения'!$G$17 | ... AA25: =AA22*'Допущения'!$G$17 | AB25: =SUM(D25:AA25)
A26: C03 | B26: GuestNode в номере | C26: COGS | D26: =D21*('Допущения'!$C$17+'Допущения'!$D$17) | E26: =E21*('Допущения'!$C$17+'Допущения'!$D$17) | F26: =F21*('Допущения'!$C$17+'Допущения'!$D$17) | G26: =G21*('Допущения'!$C$17+'Допущения'!$D$17) | H26: =H21*('Допущения'!$C$17+'Допущения'!$D$17) | I26: =I21*('Допущения'!$C$17+'Допущения'!$D$17) | J26: =J21*('Допущения'!$C$17+'Допущения'!$D$17) | K26: =K21*('Допущения'!$C$17+'Допущения'!$D$17) | ... AA26: =AA21*('Допущения'!$C$17+'Допущения'!$D$17) | AB26: =SUM(D26:AA26)
A27: C03 | B27: GuestNode в номере | C27: VARC | D27: =D22*'Допущения'!$H$17 | E27: =E22*'Допущения'!$H$17 | F27: =F22*'Допущения'!$H$17 | G27: =G22*'Допущения'!$H$17 | H27: =H22*'Допущения'!$H$17 | I27: =I22*'Допущения'!$H$17 | J27: =J22*'Допущения'!$H$17 | K27: =K22*'Допущения'!$H$17 | ... AA27: =AA22*'Допущения'!$H$17 | AB27: =SUM(D27:AA27)
A28: C04 | B28: Smart Travel Wall (микро-магазин) | C28: NEWU | D28: =IF(D$3>='Допущения'!$K$18,D$4*'Допущения'!$J$18*'Допущения'!$I$18,0) | E28: =IF(E$3>='Допущения'!$K$18,E$4*'Допущения'!$J$18*'Допущения'!$I$18,0) | F28: =IF(F$3>='Допущения'!$K$18,F$4*'Допущения'!$J$18*'Допущения'!$I$18,0) | G28: =IF(G$3>='Допущения'!$K$18,G$4*'Допущения'!$J$18*'Допущения'!$I$18,0) | H28: =IF(H$3>='Допущения'!$K$18,H$4*'Допущения'!$J$18*'Допущения'!$I$18,0) | I28: =IF(I$3>='Допущения'!$K$18,I$4*'Допущения'!$J$18*'Допущения'!$I$18,0) | J28: =IF(J$3>='Допущения'!$K$18,J$4*'Допущения'!$J$18*'Допущения'!$I$18,0) | K28: =IF(K$3>='Допущения'!$K$18,K$4*'Допущения'!$J$18*'Допущения'!$I$18,0) | ... AA28: =IF(AA$3>='Допущения'!$K$18,AA$4*'Допущения'!$J$18*'Допущения'!$I$18,0) | AB28: =SUM(D28:AA28)
A29: C04 | B29: Smart Travel Wall (микро-магазин) | C29: ACTU | D29: =D28 | E29: =D29*(1-'Допущения'!$C$6)+E28 | F29: =E29*(1-'Допущения'!$C$6)+F28 | G29: =F29*(1-'Допущения'!$C$6)+G28 | H29: =G29*(1-'Допущения'!$C$6)+H28 | I29: =H29*(1-'Допущения'!$C$6)+I28 | J29: =I29*(1-'Допущения'!$C$6)+J28 | K29: =J29*(1-'Допущения'!$C$6)+K28 | L29: =K29*(1-'Допущения'!$C$6)+L28 | ... AA29: =Z29*(1-'Допущения'!$C$6)+AA28 | AB29: =SUM(D29:AA29)
A30: C04 | B30: Smart Travel Wall (микро-магазин) | C30: HWREV | D30: =D28*'Допущения'!$E$18 | E30: =E28*'Допущения'!$E$18 | F30: =F28*'Допущения'!$E$18 | G30: =G28*'Допущения'!$E$18 | H30: =H28*'Допущения'!$E$18 | I30: =I28*'Допущения'!$E$18 | J30: =J28*'Допущения'!$E$18 | K30: =K28*'Допущения'!$E$18 | ... AA30: =AA28*'Допущения'!$E$18 | AB30: =SUM(D30:AA30)
A31: C04 | B31: Smart Travel Wall (микро-магазин) | C31: RECREV | D31: =D29*'Допущения'!$F$18 | E31: =E29*'Допущения'!$F$18 | F31: =F29*'Допущения'!$F$18 | G31: =G29*'Допущения'!$F$18 | H31: =H29*'Допущения'!$F$18 | I31: =I29*'Допущения'!$F$18 | J31: =J29*'Допущения'!$F$18 | K31: =K29*'Допущения'!$F$18 | ... AA31: =AA29*'Допущения'!$F$18 | AB31: =SUM(D31:AA31)
A32: C04 | B32: Smart Travel Wall (микро-магазин) | C32: TXNREV | D32: =D29*'Допущения'!$G$18 | E32: =E29*'Допущения'!$G$18 | F32: =F29*'Допущения'!$G$18 | G32: =G29*'Допущения'!$G$18 | H32: =H29*'Допущения'!$G$18 | I32: =I29*'Допущения'!$G$18 | J32: =J29*'Допущения'!$G$18 | K32: =K29*'Допущения'!$G$18 | ... AA32: =AA29*'Допущения'!$G$18 | AB32: =SUM(D32:AA32)
A33: C04 | B33: Smart Travel Wall (микро-магазин) | C33: COGS | D33: =D28*('Допущения'!$C$18+'Допущения'!$D$18) | E33: =E28*('Допущения'!$C$18+'Допущения'!$D$18) | F33: =F28*('Допущения'!$C$18+'Допущения'!$D$18) | G33: =G28*('Допущения'!$C$18+'Допущения'!$D$18) | H33: =H28*('Допущения'!$C$18+'Допущения'!$D$18) | I33: =I28*('Допущения'!$C$18+'Допущения'!$D$18) | J33: =J28*('Допущения'!$C$18+'Допущения'!$D$18) | K33: =K28*('Допущения'!$C$18+'Допущения'!$D$18) | ... AA33: =AA28*('Допущения'!$C$18+'Допущения'!$D$18) | AB33: =SUM(D33:AA33)
A34: C04 | B34: Smart Travel Wall (микро-магазин) | C34: VARC | D34: =D29*'Допущения'!$H$18 | E34: =E29*'Допущения'!$H$18 | F34: =F29*'Допущения'!$H$18 | G34: =G29*'Допущения'!$H$18 | H34: =H29*'Допущения'!$H$18 | I34: =I29*'Допущения'!$H$18 | J34: =J29*'Допущения'!$H$18 | K34: =K29*'Допущения'!$H$18 | ... AA34: =AA29*'Допущения'!$H$18 | AB34: =SUM(D34:AA34)
A35: C05 | B35: Rental-локеры | C35: NEWU | D35: =IF(D$3>='Допущения'!$K$19,D$4*'Допущения'!$J$19*'Допущения'!$I$19,0) | E35: =IF(E$3>='Допущения'!$K$19,E$4*'Допущения'!$J$19*'Допущения'!$I$19,0) | F35: =IF(F$3>='Допущения'!$K$19,F$4*'Допущения'!$J$19*'Допущения'!$I$19,0) | G35: =IF(G$3>='Допущения'!$K$19,G$4*'Допущения'!$J$19*'Допущения'!$I$19,0) | H35: =IF(H$3>='Допущения'!$K$19,H$4*'Допущения'!$J$19*'Допущения'!$I$19,0) | I35: =IF(I$3>='Допущения'!$K$19,I$4*'Допущения'!$J$19*'Допущения'!$I$19,0) | J35: =IF(J$3>='Допущения'!$K$19,J$4*'Допущения'!$J$19*'Допущения'!$I$19,0) | K35: =IF(K$3>='Допущения'!$K$19,K$4*'Допущения'!$J$19*'Допущения'!$I$19,0) | ... AA35: =IF(AA$3>='Допущения'!$K$19,AA$4*'Допущения'!$J$19*'Допущения'!$I$19,0) | AB35: =SUM(D35:AA35)
A36: C05 | B36: Rental-локеры | C36: ACTU | D36: =D35 | E36: =D36*(1-'Допущения'!$C$6)+E35 | F36: =E36*(1-'Допущения'!$C$6)+F35 | G36: =F36*(1-'Допущения'!$C$6)+G35 | H36: =G36*(1-'Допущения'!$C$6)+H35 | I36: =H36*(1-'Допущения'!$C$6)+I35 | J36: =I36*(1-'Допущения'!$C$6)+J35 | K36: =J36*(1-'Допущения'!$C$6)+K35 | L36: =K36*(1-'Допущения'!$C$6)+L35 | ... AA36: =Z36*(1-'Допущения'!$C$6)+AA35 | AB36: =SUM(D36:AA36)
A37: C05 | B37: Rental-локеры | C37: HWREV | D37: =D35*'Допущения'!$E$19 | E37: =E35*'Допущения'!$E$19 | F37: =F35*'Допущения'!$E$19 | G37: =G35*'Допущения'!$E$19 | H37: =H35*'Допущения'!$E$19 | I37: =I35*'Допущения'!$E$19 | J37: =J35*'Допущения'!$E$19 | K37: =K35*'Допущения'!$E$19 | ... AA37: =AA35*'Допущения'!$E$19 | AB37: =SUM(D37:AA37)
A38: C05 | B38: Rental-локеры | C38: RECREV | D38: =D36*'Допущения'!$F$19 | E38: =E36*'Допущения'!$F$19 | F38: =F36*'Допущения'!$F$19 | G38: =G36*'Допущения'!$F$19 | H38: =H36*'Допущения'!$F$19 | I38: =I36*'Допущения'!$F$19 | J38: =J36*'Допущения'!$F$19 | K38: =K36*'Допущения'!$F$19 | ... AA38: =AA36*'Допущения'!$F$19 | AB38: =SUM(D38:AA38)
A39: C05 | B39: Rental-локеры | C39: TXNREV | D39: =D36*'Допущения'!$G$19 | E39: =E36*'Допущения'!$G$19 | F39: =F36*'Допущения'!$G$19 | G39: =G36*'Допущения'!$G$19 | H39: =H36*'Допущения'!$G$19 | I39: =I36*'Допущения'!$G$19 | J39: =J36*'Допущения'!$G$19 | K39: =K36*'Допущения'!$G$19 | ... AA39: =AA36*'Допущения'!$G$19 | AB39: =SUM(D39:AA39)
A40: C05 | B40: Rental-локеры | C40: COGS | D40: =D35*('Допущения'!$C$19+'Допущения'!$D$19) | E40: =E35*('Допущения'!$C$19+'Допущения'!$D$19) | F40: =F35*('Допущения'!$C$19+'Допущения'!$D$19) | G40: =G35*('Допущения'!$C$19+'Допущения'!$D$19) | H40: =H35*('Допущения'!$C$19+'Допущения'!$D$19) | I40: =I35*('Допущения'!$C$19+'Допущения'!$D$19) | J40: =J35*('Допущения'!$C$19+'Допущения'!$D$19) | K40: =K35*('Допущения'!$C$19+'Допущения'!$D$19) | ... AA40: =AA35*('Допущения'!$C$19+'Допущения'!$D$19) | AB40: =SUM(D40:AA40)
A41: C05 | B41: Rental-локеры | C41: VARC | D41: =D36*'Допущения'!$H$19 | E41: =E36*'Допущения'!$H$19 | F41: =F36*'Допущения'!$H$19 | G41: =G36*'Допущения'!$H$19 | H41: =H36*'Допущения'!$H$19 | I41: =I36*'Допущения'!$H$19 | J41: =J36*'Допущения'!$H$19 | K41: =K36*'Допущения'!$H$19 | ... AA41: =AA36*'Допущения'!$H$19 | AB41: =SUM(D41:AA41)
A42: C06 | B42: Локеры для багажа | C42: NEWU | D42: =IF(D$3>='Допущения'!$K$20,D$4*'Допущения'!$J$20*'Допущения'!$I$20,0) | E42: =IF(E$3>='Допущения'!$K$20,E$4*'Допущения'!$J$20*'Допущения'!$I$20,0) | F42: =IF(F$3>='Допущения'!$K$20,F$4*'Допущения'!$J$20*'Допущения'!$I$20,0) | G42: =IF(G$3>='Допущения'!$K$20,G$4*'Допущения'!$J$20*'Допущения'!$I$20,0) | H42: =IF(H$3>='Допущения'!$K$20,H$4*'Допущения'!$J$20*'Допущения'!$I$20,0) | I42: =IF(I$3>='Допущения'!$K$20,I$4*'Допущения'!$J$20*'Допущения'!$I$20,0) | J42: =IF(J$3>='Допущения'!$K$20,J$4*'Допущения'!$J$20*'Допущения'!$I$20,0) | K42: =IF(K$3>='Допущения'!$K$20,K$4*'Допущения'!$J$20*'Допущения'!$I$20,0) | ... AA42: =IF(AA$3>='Допущения'!$K$20,AA$4*'Допущения'!$J$20*'Допущения'!$I$20,0) | AB42: =SUM(D42:AA42)
...

Sheet PnL
B1: Модель запуска в Лигурии: hardware + agent-сервисы для отелей (EUR, без НДС)
B3: Месяц | D3: 1 | E3: 2 | F3: 3 | G3: 4 | H3: 5 | I3: 6 | J3: 7 | K3: 8 | L3: 9 | M3: 10 | N3: 11 | O3: 12 | P3: 13 | Q3: 14 | R3: 15 | S3: 16 | T3: 17 | U3: 18 | V3: 19 | W3: 20 | X3: 21 | Y3: 22 | Z3: 23 | AA3: 24 | AB3: Год 1 | AC3: Год 2 | AD3: 24 мес.
B5: Выручка: hardware и setup | D5: =SUMIF('Модель'!$C$7:$C$111,"HWREV",'Модель'!D$7:D$111) | E5: =SUMIF('Модель'!$C$7:$C$111,"HWREV",'Модель'!E$7:E$111) | F5: =SUMIF('Модель'!$C$7:$C$111,"HWREV",'Модель'!F$7:F$111) | G5: =SUMIF('Модель'!$C$7:$C$111,"HWREV",'Модель'!G$7:G$111) | H5: =SUMIF('Модель'!$C$7:$C$111,"HWREV",'Модель'!H$7:H$111) | I5: =SUMIF('Модель'!$C$7:$C$111,"HWREV",'Модель'!I$7:I$111) | J5: =SUMIF('Модель'!$C$7:$C$111,"HWREV",'Модель'!J$7:J$111) | K5: =SUMIF('Модель'!$C$7:$C$111,"HWREV",'Модель'!K$7:K$111) | ... AA5: =SUMIF('Модель'!$C$7:$C$111,"HWREV",'Модель'!AA$7:AA$111) | AB5: =SUM(D5:O5) | AC5: =SUM(P5:AA5) | AD5: =SUM(D5:AA5)
B6: Выручка: recurring (SaaS/lease) | D6: =SUMIF('Модель'!$C$7:$C$111,"RECREV",'Модель'!D$7:D$111) | E6: =SUMIF('Модель'!$C$7:$C$111,"RECREV",'Модель'!E$7:E$111) | F6: =SUMIF('Модель'!$C$7:$C$111,"RECREV",'Модель'!F$7:F$111) | G6: =SUMIF('Модель'!$C$7:$C$111,"RECREV",'Модель'!G$7:G$111) | H6: =SUMIF('Модель'!$C$7:$C$111,"RECREV",'Модель'!H$7:H$111) | I6: =SUMIF('Модель'!$C$7:$C$111,"RECREV",'Модель'!I$7:I$111) | J6: =SUMIF('Модель'!$C$7:$C$111,"RECREV",'Модель'!J$7:J$111) | K6: =SUMIF('Модель'!$C$7:$C$111,"RECREV",'Модель'!K$7:K$111) | ... AA6: =SUMIF('Модель'!$C$7:$C$111,"RECREV",'Модель'!AA$7:AA$111) | AB6: =SUM(D6:O6) | AC6: =SUM(P6:AA6) | AD6: =SUM(D6:AA6)
B7: Маржа транзакций | D7: =SUMIF('Модель'!$C$7:$C$111,"TXNREV",'Модель'!D$7:D$111) | E7: =SUMIF('Модель'!$C$7:$C$111,"TXNREV",'Модель'!E$7:E$111) | F7: =SUMIF('Модель'!$C$7:$C$111,"TXNREV",'Модель'!F$7:F$111) | G7: =SUMIF('Модель'!$C$7:$C$111,"TXNREV",'Модель'!G$7:G$111) | H7: =SUMIF('Модель'!$C$7:$C$111,"TXNREV",'Модель'!H$7:H$111) | I7: =SUMIF('Модель'!$C$7:$C$111,"TXNREV",'Модель'!I$7:I$111) | J7: =SUMIF('Модель'!$C$7:$C$111,"TXNREV",'Модель'!J$7:J$111) | K7: =SUMIF('Модель'!$C$7:$C$111,"TXNREV",'Модель'!K$7:K$111) | ... AA7: =SUMIF('Модель'!$C$7:$C$111,"TXNREV",'Модель'!AA$7:AA$111) | AB7: =SUM(D7:O7) | AC7: =SUM(P7:AA7) | AD7: =SUM(D7:AA7)
B8: Выручка всего | D8: =SUM(D5:D7) | E8: =SUM(E5:E7) | F8: =SUM(F5:F7) | G8: =SUM(G5:G7) | H8: =SUM(H5:H7) | I8: =SUM(I5:I7) | J8: =SUM(J5:J7) | K8: =SUM(K5:K7) | ... AA8: =SUM(AA5:AA7) | AB8: =SUM(D8:O8) | AC8: =SUM(P8:AA8) | AD8: =SUM(D8:AA8)
B9: Landed HW + установка | D9: =SUMIF('Модель'!$C$7:$C$111,"COGS",'Модель'!D$7:D$111) | E9: =SUMIF('Модель'!$C$7:$C$111,"COGS",'Модель'!E$7:E$111) | F9: =SUMIF('Модель'!$C$7:$C$111,"COGS",'Модель'!F$7:F$111) | G9: =SUMIF('Модель'!$C$7:$C$111,"COGS",'Модель'!G$7:G$111) | H9: =SUMIF('Модель'!$C$7:$C$111,"COGS",'Модель'!H$7:H$111) | I9: =SUMIF('Модель'!$C$7:$C$111,"COGS",'Модель'!I$7:I$111) | J9: =SUMIF('Модель'!$C$7:$C$111,"COGS",'Модель'!J$7:J$111) | K9: =SUMIF('Модель'!$C$7:$C$111,"COGS",'Модель'!K$7:K$111) | ... AA9: =SUMIF('Модель'!$C$7:$C$111,"COGS",'Модель'!AA$7:AA$111) | AB9: =SUM(D9:O9) | AC9: =SUM(P9:AA9) | AD9: =SUM(D9:AA9)
B10: Переменные затраты | D10: =SUMIF('Модель'!$C$7:$C$111,"VARC",'Модель'!D$7:D$111) | E10: =SUMIF('Модель'!$C$7:$C$111,"VARC",'Модель'!E$7:E$111) | F10: =SUMIF('Модель'!$C$7:$C$111,"VARC",'Модель'!F$7:F$111) | G10: =SUMIF('Модель'!$C$7:$C$111,"VARC",'Модель'!G$7:G$111) | H10: =SUMIF('Модель'!$C$7:$C$111,"VARC",'Модель'!H$7:H$111) | I10: =SUMIF('Модель'!$C$7:$C$111,"VARC",'Модель'!I$7:I$111) | J10: =SUMIF('Модель'!$C$7:$C$111,"VARC",'Модель'!J$7:J$111) | K10: =SUMIF('Модель'!$C$7:$C$111,"VARC",'Модель'!K$7:K$111) | ... AA10: =SUMIF('Модель'!$C$7:$C$111,"VARC",'Модель'!AA$7:AA$111) | AB10: =SUM(D10:O10) | AC10: =SUM(P10:AA10) | AD10: =SUM(D10:AA10)
B11: Валовая прибыль | D11: =D8-D9-D10 | E11: =E8-E9-E10 | F11: =F8-F9-F10 | G11: =G8-G9-G10 | H11: =H8-H9-H10 | I11: =I8-I9-I10 | J11: =J8-J9-J10 | K11: =K8-K9-K10 | ... AA11: =AA8-AA9-AA10 | AB11: =SUM(D11:O11) | AC11: =SUM(P11:AA11) | AD11: =SUM(D11:AA11)
B12: Валовая маржа % | D12: =IF(D8=0,0,D11/D8) | E12: =IF(E8=0,0,E11/E8) | F12: =IF(F8=0,0,F11/F8) | G12: =IF(G8=0,0,G11/G8) | H12: =IF(H8=0,0,H11/H8) | I12: =IF(I8=0,0,I11/I8) | J12: =IF(J8=0,0,J11/J8) | K12: =IF(K8=0,0,K11/K8) | ... AD12: =IF(AD8=0,0,AD11/AD8)
B13: Постоянные opex | D13: =SUMPRODUCT(('Допущения'!$D$34:$D$42<=D$3)*'Допущения'!$C$34:$C$42) | E13: =SUMPRODUCT(('Допущения'!$D$34:$D$42<=E$3)*'Допущения'!$C$34:$C$42) | F13: =SUMPRODUCT(('Допущения'!$D$34:$D$42<=F$3)*'Допущения'!$C$34:$C$42) | G13: =SUMPRODUCT(('Допущения'!$D$34:$D$42<=G$3)*'Допущения'!$C$34:$C$42) | H13: =SUMPRODUCT(('Допущения'!$D$34:$D$42<=H$3)*'Допущения'!$C$34:$C$42) | I13: =SUMPRODUCT(('Допущения'!$D$34:$D$42<=I$3)*'Допущения'!$C$34:$C$42) | J13: =SUMPRODUCT(('Допущения'!$D$34:$D$42<=J$3)*'Допущения'!$C$34:$C$42) | K13: =SUMPRODUCT(('Допущения'!$D$34:$D$42<=K$3)*'Допущения'!$C$34:$C$42) | ... AA13: =SUMPRODUCT(('Допущения'!$D$34:$D$42<=AA$3)*'Допущения'!$C$34:$C$42) | AB13: =SUM(D13:O13) | AC13: =SUM(P13:AA13) | AD13: =SUM(D13:AA13)
B14: Разовые расходы запуска | D14: =IF(D$3=1,SUM('Допущения'!$C$46:$C$50),0) | E14: =IF(E$3=1,SUM('Допущения'!$C$46:$C$50),0) | F14: =IF(F$3=1,SUM('Допущения'!$C$46:$C$50),0) | G14: =IF(G$3=1,SUM('Допущения'!$C$46:$C$50),0) | H14: =IF(H$3=1,SUM('Допущения'!$C$46:$C$50),0) | I14: =IF(I$3=1,SUM('Допущения'!$C$46:$C$50),0) | J14: =IF(J$3=1,SUM('Допущения'!$C$46:$C$50),0) | K14: =IF(K$3=1,SUM('Допущения'!$C$46:$C$50),0) | ... AA14: =IF(AA$3=1,SUM('Допущения'!$C$46:$C$50),0) | AB14: =SUM(D14:O14) | AC14: =SUM(P14:AA14) | AD14: =SUM(D14:AA14)
B15: EBITDA | D15: =D11-D13-D14 | E15: =E11-E13-E14 | F15: =F11-F13-F14 | G15: =G11-G13-G14 | H15: =H11-H13-H14 | I15: =I11-I13-I14 | J15: =J11-J13-J14 | K15: =K11-K13-K14 | ... AA15: =AA11-AA13-AA14 | AB15: =SUM(D15:O15) | AC15: =SUM(P15:AA15) | AD15: =SUM(D15:AA15)
B16: Налог (упрощённо) | D16: =MAX(0,D15)*'Допущения'!$C$8 | E16: =MAX(0,E15)*'Допущения'!$C$8 | F16: =MAX(0,F15)*'Допущения'!$C$8 | G16: =MAX(0,G15)*'Допущения'!$C$8 | H16: =MAX(0,H15)*'Допущения'!$C$8 | I16: =MAX(0,I15)*'Допущения'!$C$8 | J16: =MAX(0,J15)*'Допущения'!$C$8 | K16: =MAX(0,K15)*'Допущения'!$C$8 | ... AA16: =MAX(0,AA15)*'Допущения'!$C$8 | AB16: =SUM(D16:O16) | AC16: =SUM(P16:AA16) | AD16: =SUM(D16:AA16)
B17: Чистый результат | D17: =D15-D16 | E17: =E15-E16 | F17: =F15-F16 | G17: =G15-G16 | H17: =H15-H16 | I17: =I15-I16 | J17: =J15-J16 | K17: =K15-K16 | ... AA17: =AA15-AA16 | AB17: =SUM(D17:O17) | AC17: =SUM(P17:AA17) | AD17: =SUM(D17:AA17)
B18: Накопленный результат | D18: =D17 | E18: =D18+E17 | F18: =E18+F17 | G18: =F18+G17 | H18: =G18+H17 | I18: =H18+I17 | J18: =I18+J17 | K18: =J18+K17 | L18: =K18+L17 | ... AA18: =Z18+AA17
B19: Вспом.: месяц, если EBITDA>0 | D19: =IF(D15>0,D$3,99) | E19: =IF(E15>0,E$3,99) | F19: =IF(F15>0,F$3,99) | G19: =IF(G15>0,G$3,99) | H19: =IF(H15>0,H$3,99) | I19: =IF(I15>0,I$3,99) | J19: =IF(J15>0,J$3,99) | K19: =IF(K15>0,K$3,99) | ... AA19: =IF(AA15>0,AA$3,99)

Sheet Cashflow
B1: Модель запуска в Лигурии: hardware + agent-сервисы для отелей (EUR, без НДС)
B3: Месяц | D3: 1 | E3: 2 | F3: 3 | G3: 4 | H3: 5 | I3: 6 | J3: 7 | K3: 8 | L3: 9 | M3: 10 | N3: 11 | O3: 12 | P3: 13 | Q3: 14 | R3: 15 | S3: 16 | T3: 17 | U3: 18 | V3: 19 | W3: 20 | X3: 21 | Y3: 22 | Z3: 23 | AA3: 24
B5: Поступления | D5: ='Допущения'!$C$9*'PnL'!D8 | E5: ='Допущения'!$C$9*'PnL'!E8+(1-'Допущения'!$C$9)*'PnL'!D8 | F5: ='Допущения'!$C$9*'PnL'!F8+(1-'Допущения'!$C$9)*'PnL'!E8 | G5: ='Допущения'!$C$9*'PnL'!G8+(1-'Допущения'!$C$9)*'PnL'!F8 | H5: ='Допущения'!$C$9*'PnL'!H8+(1-'Допущения'!$C$9)*'PnL'!G8 | I5: ='Допущения'!$C$9*'PnL'!I8+(1-'Допущения'!$C$9)*'PnL'!H8 | J5: ='Допущения'!$C$9*'PnL'!J8+(1-'Допущения'!$C$9)*'PnL'!I8 | K5: ='Допущения'!$C$9*'PnL'!K8+(1-'Допущения'!$C$9)*'PnL'!J8 | L5: ='Допущения'!$C$9*'PnL'!L8+(1-'Допущения'!$C$9)*'PnL'!K8 | ... AA5: ='Допущения'!$C$9*'PnL'!AA8+(1-'Допущения'!$C$9)*'PnL'!Z8
B6: Закупки hardware (оплата за 2 мес. вперёд) | D6: ='PnL'!D9+'PnL'!E9+'PnL'!F9 | E6: ='PnL'!G9 | F6: ='PnL'!H9 | G6: ='PnL'!I9 | H6: ='PnL'!J9 | I6: ='PnL'!K9 | J6: ='PnL'!L9 | K6: ='PnL'!M9 | L6: ='PnL'!N9 | ... Y6: ='PnL'!AA9 | Z6: 0 | AA6: 0
B7: Переменные затраты | D7: ='PnL'!D10 | E7: ='PnL'!E10 | F7: ='PnL'!F10 | G7: ='PnL'!G10 | H7: ='PnL'!H10 | I7: ='PnL'!I10 | J7: ='PnL'!J10 | K7: ='PnL'!K10 | ... AA7: ='PnL'!AA10
B8: Постоянные opex | D8: ='PnL'!D13 | E8: ='PnL'!E13 | F8: ='PnL'!F13 | G8: ='PnL'!G13 | H8: ='PnL'!H13 | I8: ='PnL'!I13 | J8: ='PnL'!J13 | K8: ='PnL'!K13 | ... AA8: ='PnL'!AA13
B9: Разовые расходы | D9: ='PnL'!D14 | E9: ='PnL'!E14 | F9: ='PnL'!F14 | G9: ='PnL'!G14 | H9: ='PnL'!H14 | I9: ='PnL'!I14 | J9: ='PnL'!J14 | K9: ='PnL'!K14 | ... AA9: ='PnL'!AA14
B10: Налоги | D10: ='PnL'!D16 | E10: ='PnL'!E16 | F10: ='PnL'!F16 | G10: ='PnL'!G16 | H10: ='PnL'!H16 | I10: ='PnL'!I16 | J10: ='PnL'!J16 | K10: ='PnL'!K16 | ... AA10: ='PnL'!AA16
B11: Чистый денежный поток | D11: =D5-D6-D7-D8-D9-D10 | E11: =E5-E6-E7-E8-E9-E10 | F11: =F5-F6-F7-F8-F9-F10 | G11: =G5-G6-G7-G8-G9-G10 | H11: =H5-H6-H7-H8-H9-H10 | I11: =I5-I6-I7-I8-I9-I10 | J11: =J5-J6-J7-J8-J9-J10 | K11: =K5-K6-K7-K8-K9-K10 | ... AA11: =AA5-AA6-AA7-AA8-AA9-AA10
B12: Остаток на начало | D12: ='Допущения'!$C$7 | E12: =D13 | F12: =E13 | G12: =F13 | H12: =G13 | I12: =H13 | J12: =I13 | K12: =J13 | L12: =K13 | ... AA12: =Z13
B13: Остаток на конец | D13: =D12+D11 | E13: =E12+E11 | F13: =F12+F11 | G13: =G12+G11 | H13: =H12+H11 | I13: =I12+I11 | J13: =J12+J11 | K13: =K12+K11 | ... AA13: =AA12+AA11
B14: Накопленный денежный поток | D14: =D11 | E14: =D14+E11 | F14: =E14+F11 | G14: =F14+G11 | H14: =G14+H11 | I14: =H14+I11 | J14: =I14+J11 | K14: =J14+K11 | L14: =K14+L11 | ... AA14: =Z14+AA11

Sheet Экон_категорий
B1: Модель запуска в Лигурии: hardware + agent-сервисы для отелей (EUR, без НДС)
B3: Категория | C3: Первоначальные затраты / ед. | D3: Разовая цена / ед. | E3: Маржа на разовой части / ед. | F3: Ежемесячный вклад / ед. | G3: Payback (мес.) | H3: Landed-затраты за 24 мес. (инвестиции) | I3: Выручка за 24 мес. | J3: Вклад за 24 мес. | K3: Вклад / инвестиции | L3: Активные ед., месяц 24 | M3: ID
B4: Hotel Agent OS (платформа агентов) | C4: ='Допущения'!C15+'Допущения'!D15 | D4: ='Допущения'!E15 | E4: =D4-C4 | F4: ='Допущения'!F15+'Допущения'!G15-'Допущения'!H15 | G4: =IF(F4<=0,"н/д",MAX(0,C4-D4)/F4) | H4: =SUMIFS('Модель'!$AB$7:$AB$111,'Модель'!$A$7:$A$111,$M4,'Модель'!$C$7:$C$111,"COGS") | I4: =SUMIFS('Модель'!$AB$7:$AB$111,'Модель'!$A$7:$A$111,$M4,'Модель'!$C$7:$C$111,"HWREV")+SUMIFS('Модель'!$AB$7:$AB$111,'Модель'!$A$7:$A$111,$M4,'Модель'!$C$7:$C$111,"RECREV")+SUMIFS('Модель'!$AB$7:$AB$111,'Модель'!$A$7:$A$111,$M4,'Модель'!$C$7:$C$111,"TXNREV") | J4: =I4-H4-SUMIFS('Модель'!$AB$7:$AB$111,'Модель'!$A$7:$A$111,$M4,'Модель'!$C$7:$C$111,"VARC") | K4: =IF(H4=0,"н/д",J4/H4) | L4: =SUMIFS('Модель'!$AA$7:$AA$111,'Модель'!$A$7:$A$111,$M4,'Модель'!$C$7:$C$111,"ACTU") | M4: C01
B5: GuestNode Lobby (ресепшен) | C5: ='Допущения'!C16+'Допущения'!D16 | D5: ='Допущения'!E16 | E5: =D5-C5 | F5: ='Допущения'!F16+'Допущения'!G16-'Допущения'!H16 | G5: =IF(F5<=0,"н/д",MAX(0,C5-D5)/F5) | H5: =SUMIFS('Модель'!$AB$7:$AB$111,'Модель'!$A$7:$A$111,$M5,'Модель'!$C$7:$C$111,"COGS") | I5: =SUMIFS('Модель'!$AB$7:$AB$111,'Модель'!$A$7:$A$111,$M5,'Модель'!$C$7:$C$111,"HWREV")+SUMIFS('Модель'!$AB$7:$AB$111,'Модель'!$A$7:$A$111,$M5,'Модель'!$C$7:$C$111,"RECREV")+SUMIFS('Модель'!$AB$7:$AB$111,'Модель'!$A$7:$A$111,$M5,'Модель'!$C$7:$C$111,"TXNREV") | J5: =I5-H5-SUMIFS('Модель'!$AB$7:$AB$111,'Модель'!$A$7:$A$111,$M5,'Модель'!$C$7:$C$111,"VARC") | K5: =IF(H5=0,"н/д",J5/H5) | L5: =SUMIFS('Модель'!$AA$7:$AA$111,'Модель'!$A$7:$A$111,$M5,'Модель'!$C$7:$C$111,"ACTU") | M5: C02
B6: GuestNode в номере | C6: ='Допущения'!C17+'Допущения'!D17 | D6: ='Допущения'!E17 | E6: =D6-C6 | F6: ='Допущения'!F17+'Допущения'!G17-'Допущения'!H17 | G6: =IF(F6<=0,"н/д",MAX(0,C6-D6)/F6) | H6: =SUMIFS('Модель'!$AB$7:$AB$111,'Модель'!$A$7:$A$111,$M6,'Модель'!$C$7:$C$111,"COGS") | I6: =SUMIFS('Модель'!$AB$7:$AB$111,'Модель'!$A$7:$A$111,$M6,'Модель'!$C$7:$C$111,"HWREV")+SUMIFS('Модель'!$AB$7:$AB$111,'Модель'!$A$7:$A$111,$M6,'Модель'!$C$7:$C$111,"RECREV")+SUMIFS('Модель'!$AB$7:$AB$111,'Модель'!$A$7:$A$111,$M6,'Модель'!$C$7:$C$111,"TXNREV") | J6: =I6-H6-SUMIFS('Модель'!$AB$7:$AB$111,'Модель'!$A$7:$A$111,$M6,'Модель'!$C$7:$C$111,"VARC") | K6: =IF(H6=0,"н/д",J6/H6) | L6: =SUMIFS('Модель'!$AA$7:$AA$111,'Модель'!$A$7:$A$111,$M6,'Модель'!$C$7:$C$111,"ACTU") | M6: C03
B7: Smart Travel Wall (микро-магазин) | C7: ='Допущения'!C18+'Допущения'!D18 | D7: ='Допущения'!E18 | E7: =D7-C7 | F7: ='Допущения'!F18+'Допущения'!G18-'Допущения'!H18 | G7: =IF(F7<=0,"н/д",MAX(0,C7-D7)/F7) | H7: =SUMIFS('Модель'!$AB$7:$AB$111,'Модель'!$A$7:$A$111,$M7,'Модель'!$C$7:$C$111,"COGS") | I7: =SUMIFS('Модель'!$AB$7:$AB$111,'Модель'!$A$7:$A$111,$M7,'Модель'!$C$7:$C$111,"HWREV")+SUMIFS('Модель'!$AB$7:$AB$111,'Модель'!$A$7:$A$111,$M7,'Модель'!$C$7:$C$111,"RECREV")+SUMIFS('Модель'!$AB$7:$AB$111,'Модель'!$A$7:$A$111,$M7,'Модель'!$C$7:$C$111,"TXNREV") | J7: =I7-H7-SUMIFS('Модель'!$AB$7:$AB$111,'Модель'!$A$7:$A$111,$M7,'Модель'!$C$7:$C$111,"VARC") | K7: =IF(H7=0,"н/д",J7/H7) | L7: =SUMIFS('Модель'!$AA$7:$AA$111,'Модель'!$A$7:$A$111,$M7,'Модель'!$C$7:$C$111,"ACTU") | M7: C04
B8: Rental-локеры | C8: ='Допущения'!C19+'Допущения'!D19 | D8: ='Допущения'!E19 | E8: =D8-C8 | F8: ='Допущения'!F19+'Допущения'!G19-'Допущения'!H19 | G8: =IF(F8<=0,"н/д",MAX(0,C8-D8)/F8) | H8: =SUMIFS('Модель'!$AB$7:$AB$111,'Модель'!$A$7:$A$111,$M8,'Модель'!$C$7:$C$111,"COGS") | I8: =SUMIFS('Модель'!$AB$7:$AB$111,'Модель'!$A$7:$A$111,$M8,'Модель'!$C$7:$C$111,"HWREV")+SUMIFS('Модель'!$AB$7:$AB$111,'Модель'!$A$7:$A$111,$M8,'Модель'!$C$7:$C$111,"RECREV")+SUMIFS('Модель'!$AB$7:$AB$111,'Модель'!$A$7:$A$111,$M8,'Модель'!$C$7:$C$111,"TXNREV") | J8: =I8-H8-SUMIFS('Модель'!$AB$7:$AB$111,'Модель'!$A$7:$A$111,$M8,'Модель'!$C$7:$C$111,"VARC") | K8: =IF(H8=0,"н/д",J8/H8) | L8: =SUMIFS('Модель'!$AA$7:$AA$111,'Модель'!$A$7:$A$111,$M8,'Модель'!$C$7:$C$111,"ACTU") | M8: C05
B9: Локеры для багажа | C9: ='Допущения'!C20+'Допущения'!D20 | D9: ='Допущения'!E20 | E9: =D9-C9 | F9: ='Допущения'!F20+'Допущения'!G20-'Допущения'!H20 | G9: =IF(F9<=0,"н/д",MAX(0,C9-D9)/F9) | H9: =SUMIFS('Модель'!$AB$7:$AB$111,'Модель'!$A$7:$A$111,$M9,'Модель'!$C$7:$C$111,"COGS") | I9: =SUMIFS('Модель'!$AB$7:$AB$111,'Модель'!$A$7:$A$111,$M9,'Модель'!$C$7:$C$111,"HWREV")+SUMIFS('Модель'!$AB$7:$AB$111,'Модель'!$A$7:$A$111,$M9,'Модель'!$C$7:$C$111,"RECREV")+SUMIFS('Модель'!$AB$7:$AB$111,'Модель'!$A$7:$A$111,$M9,'Модель'!$C$7:$C$111,"TXNREV") | J9: =I9-H9-SUMIFS('Модель'!$AB$7:$AB$111,'Модель'!$A$7:$A$111,$M9,'Модель'!$C$7:$C$111,"VARC") | K9: =IF(H9=0,"н/д",J9/H9) | L9: =SUMIFS('Модель'!$AA$7:$AA$111,'Модель'!$A$7:$A$111,$M9,'Модель'!$C$7:$C$111,"ACTU") | M9: C06
B10: Аренда power bank | C10: ='Допущения'!C21+'Допущения'!D21 | D10: ='Допущения'!E21 | E10: =D10-C10 | F10: ='Допущения'!F21+'Допущения'!G21-'Допущения'!H21 | G10: =IF(F10<=0,"н/д",MAX(0,C10-D10)/F10) | H10: =SUMIFS('Модель'!$AB$7:$AB$111,'Модель'!$A$7:$A$111,$M10,'Модель'!$C$7:$C$111,"COGS") | I10: =SUMIFS('Модель'!$AB$7:$AB$111,'Модель'!$A$7:$A$111,$M10,'Модель'!$C$7:$C$111,"HWREV")+SUMIFS('Модель'!$AB$7:$AB$111,'Модель'!$A$7:$A$111,$M10,'Модель'!$C$7:$C$111,"RECREV")+SUMIFS('Модель'!$AB$7:$AB$111,'Модель'!$A$7:$A$111,$M10,'Модель'!$C$7:$C$111,"TXNREV") | J10: =I10-H10-SUMIFS('Модель'!$AB$7:$AB$111,'Модель'!$A$7:$A$111,$M10,'Модель'!$C$7:$C$111,"VARC") | K10: =IF(H10=0,"н/д",J10/H10) | L10: =SUMIFS('Модель'!$AA$7:$AA$111,'Модель'!$A$7:$A$111,$M10,'Модель'!$C$7:$C$111,"ACTU") | M10: C07
B11: IoT-комплект энергосбережения (на номер) | C11: ='Допущения'!C22+'Допущения'!D22 | D11: ='Допущения'!E22 | E11: =D11-C11 | F11: ='Допущения'!F22+'Допущения'!G22-'Допущения'!H22 | G11: =IF(F11<=0,"н/д",MAX(0,C11-D11)/F11) | H11: =SUMIFS('Модель'!$AB$7:$AB$111,'Модель'!$A$7:$A$111,$M11,'Модель'!$C$7:$C$111,"COGS") | I11: =SUMIFS('Модель'!$AB$7:$AB$111,'Модель'!$A$7:$A$111,$M11,'Модель'!$C$7:$C$111,"HWREV")+SUMIFS('Модель'!$AB$7:$AB$111,'Модель'!$A$7:$A$111,$M11,'Модель'!$C$7:$C$111,"RECREV")+SUMIFS('Модель'!$AB$7:$AB$111,'Модель'!$A$7:$A$111,$M11,'Модель'!$C$7:$C$111,"TXNREV") | J11: =I11-H11-SUMIFS('Модель'!$AB$7:$AB$111,'Модель'!$A$7:$A$111,$M11,'Модель'!$C$7:$C$111,"VARC") | K11: =IF(H11=0,"н/д",J11/H11) | L11: =SUMIFS('Модель'!$AA$7:$AA$111,'Модель'!$A$7:$A$111,$M11,'Модель'!$C$7:$C$111,"ACTU") | M11: C08
B12: Smart access (на дверь) | C12: ='Допущения'!C23+'Допущения'!D23 | D12: ='Допущения'!E23 | E12: =D12-C12 | F12: ='Допущения'!F23+'Допущения'!G23-'Допущения'!H23 | G12: =IF(F12<=0,"н/д",MAX(0,C12-D12)/F12) | H12: =SUMIFS('Модель'!$AB$7:$AB$111,'Модель'!$A$7:$A$111,$M12,'Модель'!$C$7:$C$111,"COGS") | I12: =SUMIFS('Модель'!$AB$7:$AB$111,'Модель'!$A$7:$A$111,$M12,'Модель'!$C$7:$C$111,"HWREV")+SUMIFS('Модель'!$AB$7:$AB$111,'Модель'!$A$7:$A$111,$M12,'Модель'!$C$7:$C$111,"RECREV")+SUMIFS('Модель'!$AB$7:$AB$111,'Модель'!$A$7:$A$111,$M12,'Модель'!$C$7:$C$111,"TXNREV") | J12: =I12-H12-SUMIFS('Модель'!$AB$7:$AB$111,'Модель'!$A$7:$A$111,$M12,'Модель'!$C$7:$C$111,"VARC") | K12: =IF(H12=0,"н/д",J12/H12) | L12: =SUMIFS('Модель'!$AA$7:$AA$111,'Модель'!$A$7:$A$111,$M12,'Модель'!$C$7:$C$111,"ACTU") | M12: C09
B13: Датчики Healthy Room (на номер) | C13: ='Допущения'!C24+'Допущения'!D24 | D13: ='Допущения'!E24 | E13: =D13-C13 | F13: ='Допущения'!F24+'Допущения'!G24-'Допущения'!H24 | G13: =IF(F13<=0,"н/д",MAX(0,C13-D13)/F13) | H13: =SUMIFS('Модель'!$AB$7:$AB$111,'Модель'!$A$7:$A$111,$M13,'Модель'!$C$7:$C$111,"COGS") | I13: =SUMIFS('Модель'!$AB$7:$AB$111,'Модель'!$A$7:$A$111,$M13,'Модель'!$C$7:$C$111,"HWREV")+SUMIFS('Модель'!$AB$7:$AB$111,'Модель'!$A$7:$A$111,$M13,'Модель'!$C$7:$C$111,"RECREV")+SUMIFS('Модель'!$AB$7:$AB$111,'Модель'!$A$7:$A$111,$M13,'Модель'!$C$7:$C$111,"TXNREV") | J13: =I13-H13-SUMIFS('Модель'!$AB$7:$AB$111,'Модель'!$A$7:$A$111,$M13,'Модель'!$C$7:$C$111,"VARC") | K13: =IF(H13=0,"н/д",J13/H13) | L13: =SUMIFS('Модель'!$AA$7:$AA$111,'Модель'!$A$7:$A$111,$M13,'Модель'!$C$7:$C$111,"ACTU") | M13: C10
B14: Киоск check-in / ID | C14: ='Допущения'!C25+'Допущения'!D25 | D14: ='Допущения'!E25 | E14: =D14-C14 | F14: ='Допущения'!F25+'Допущения'!G25-'Допущения'!H25 | G14: =IF(F14<=0,"н/д",MAX(0,C14-D14)/F14) | H14: =SUMIFS('Модель'!$AB$7:$AB$111,'Модель'!$A$7:$A$111,$M14,'Модель'!$C$7:$C$111,"COGS") | I14: =SUMIFS('Модель'!$AB$7:$AB$111,'Модель'!$A$7:$A$111,$M14,'Модель'!$C$7:$C$111,"HWREV")+SUMIFS('Модель'!$AB$7:$AB$111,'Модель'!$A$7:$A$111,$M14,'Модель'!$C$7:$C$111,"RECREV")+SUMIFS('Модель'!$AB$7:$AB$111,'Модель'!$A$7:$A$111,$M14,'Модель'!$C$7:$C$111,"TXNREV") | J14: =I14-H14-SUMIFS('Модель'!$AB$7:$AB$111,'Модель'!$A$7:$A$111,$M14,'Модель'!$C$7:$C$111,"VARC") | K14: =IF(H14=0,"н/д",J14/H14) | L14: =SUMIFS('Модель'!$AA$7:$AA$111,'Модель'!$A$7:$A$111,$M14,'Модель'!$C$7:$C$111,"ACTU") | M14: C11
B15: Локальный marketplace | C15: ='Допущения'!C26+'Допущения'!D26 | D15: ='Допущения'!E26 | E15: =D15-C15 | F15: ='Допущения'!F26+'Допущения'!G26-'Допущения'!H26 | G15: =IF(F15<=0,"н/д",MAX(0,C15-D15)/F15) | H15: =SUMIFS('Модель'!$AB$7:$AB$111,'Модель'!$A$7:$A$111,$M15,'Модель'!$C$7:$C$111,"COGS") | I15: =SUMIFS('Модель'!$AB$7:$AB$111,'Модель'!$A$7:$A$111,$M15,'Модель'!$C$7:$C$111,"HWREV")+SUMIFS('Модель'!$AB$7:$AB$111,'Модель'!$A$7:$A$111,$M15,'Модель'!$C$7:$C$111,"RECREV")+SUMIFS('Модель'!$AB$7:$AB$111,'Модель'!$A$7:$A$111,$M15,'Модель'!$C$7:$C$111,"TXNREV") | J15: =I15-H15-SUMIFS('Модель'!$AB$7:$AB$111,'Модель'!$A$7:$A$111,$M15,'Модель'!$C$7:$C$111,"VARC") | K15: =IF(H15=0,"н/д",J15/H15) | L15: =SUMIFS('Модель'!$AA$7:$AA$111,'Модель'!$A$7:$A$111,$M15,'Модель'!$C$7:$C$111,"ACTU") | M15: C12
... B18: Регулируемый vending (только fee лицензированного партнёра) | C18: ='Допущения'!C29+'Допущения'!D29 | D18: ='Допущения'!E29 | E18: =D18-C18 | F18: ='Допущения'!F29+'Допущения'!G29-'Допущения'!H29 | G18: =IF(F18<=0,"н/д",MAX(0,C18-D18)/F18) | H18: =SUMIFS('Модель'!$AB$7:$AB$111,'Модель'!$A$7:$A$111,$M18,'Модель'!$C$7:$C$111,"COGS") | I18: =SUMIFS('Модель'!$AB$7:$AB$111,'Модель'!$A$7:$A$111,$M18,'Модель'!$C$7:$C$111,"HWREV")+SUMIFS('Модель'!$AB$7:$AB$111,'Модель'!$A$7:$A$111,$M18,'Модель'!$C$7:$C$111,"RECREV")+SUMIFS('Модель'!$AB$7:$AB$111,'Модель'!$A$7:$A$111,$M18,'Модель'!$C$7:$C$111,"TXNREV") | J18: =I18-H18-SUMIFS('Модель'!$AB$7:$AB$111,'Модель'!$A$7:$A$111,$M18,'Модель'!$C$7:$C$111,"VARC") | K18: =IF(H18=0,"н/д",J18/H18) | L18: =SUMIFS('Модель'!$AA$7:$AA$111,'Модель'!$A$7:$A$111,$M18,'Модель'!$C$7:$C$111,"ACTU") | M18: C15

Sheet Лицензии
A1: Категория | B1: Требование (ориентир.) | C1: Решение для go-to-market
A2: Agent-SaaS / данные гостей | B2: GDPR, DPA с отелями, прозрачность ИИ, меры безопасности | C2: Хостинг в ЕС, минимизация данных, audit-логи
A3: Идентификация гостей | B3: TULPS ст. 109 / Alloggiati Web, GDPR; без долгого хранения копий документов | C3: Проверка только при check-in; устройство в номере получает краткоживущий токен
A4: Радио-оборудование (Wi-Fi/BLE/Zigbee) | B4: CE, RED, EMC, LVD, RoHS, DoC и технический файл | C4: Ввозить только SKU с отчётами для конкретной модели
A5: White-label / private label | B5: Импортёр может принять на себя обязанности производителя | C5: Завершить аудит соответствия до ребрендинга
A6: Подключённые устройства (CRA) | B6: Cyber Resilience Act: отчётность с 11.09.2026, основные требования с 11.12.2027 | C6: SBOM, OTA-обновления, контакт по уязвимостям
A7: Платежи | B7: Договор с PSP/эквайером, сертифицированный терминал | C7: Использовать сертифицированный сторонний терминал
A8: Vending еды/напитков | B8: SCIA/SUAP, HACCP, маркировка (местные правила) | C8: Партнёрство с местным лицензированным оператором
A9: Vending алкоголя | B9: Возрастные ограничения и местные разрешения | C9: Только после юр. заключения
A10: Табак / электронные сигареты | B10: Режим ADM, авторизованные поставки, проверка возраста, ограничения рекламы и дистанционных продаж, акциз на жидкости | C10: Только партнёрство с лицензированным оператором; без прямых продаж
A11: Умные замки | B11: RED/EMC, совместимость с противопожарными дверями и аварийным выходом | C11: Сертифицированные замки, местный слесарь
A12: Роботы | B12: CE, безопасность машин/продукции, ответственность и оценка рисков | C12: Сначала пилот под наблюдением

Sheet Риски
A1: Риск | B1: Вероятность | C1: Влияние | D1: Mitigation
A2: Долгий цикл продаж | B2: Высокая | C2: Высокая | D2: Платные пилоты, сезонные дедлайны, партнёры PMS
A3: Низкое использование GuestNode | B3: Средняя | C3: Высокая | D3: Сначала lobby, QR-fallback, пороги использования
A4: Отказы оборудования | B4: Средняя | C4: Высокая | D4: Резерв 5–10%, сервис-партнёр в ЕС
A5: Слабая документация OEM | B5: Высокая | C5: Высокая | D5: Аудит соответствия до отгрузки
A6: Зависимость от китайского cloud | B6: Средняя | C6: Высокая | D6: Локальный API, cloud в ЕС, право экспорта данных
A7: Фрагментация интеграций PMS | B7: Высокая | C7: Высокая | D7: Начать с 2–3 PMS
A8: Высокая FDE-нагрузка | B8: Высокая | C8: Средняя | D8: Стандартные коннекторы и SOP
A9: Сезонность Лигурии | B9: Высокая | C9: Высокая | D9: Годовой SaaS, монтаж вне сезона
A10: Нехватка оборотного капитала | B10: Средняя | C10: Высокая | D10: Депозит отеля до заказа hardware
A11: Инцидент GDPR | B11: Низкая | C11: Очень высокая | D11: Минимизация, шифрование, DPA, логирование
A12: Санкции по табаку/vape | B12: Средняя | C12: Очень высокая | D12: Только модель с лицензированным оператором
A13: Экономика роботов не сходится для SMB | B13: Высокая | C13: Средняя | D13: Robot-agnostic ПО; без ранней закупки

Sheet Долговечность
A1: Тренд | B1: Горизонт (лет, оценка) | C1: Оценка долговечности | D1: Инвестиционный вывод
A2: Agentic operations | B2: 7-10 | C2: Очень высокий | D2: Основная software-платформа
A3: Слой идентификации/контекста | B3: 7-10 | C3: Очень высокий | D3: Ключевой архитектурный актив
A4: Многоязычный сервис гостей | B4: 7-10 | C4: Очень высокий (сам по себе не moat) | D4: Базовая функция
A5: Energy IoT | B5: 8-12 | C5: Очень высокий | D5: Самый долговечный hardware-кейс
A6: Smart access | B6: 8-12 | C6: Очень высокий | D6: Зрелая инфраструктура
A7: PMS-нейтральная оркестрация | B7: 5-10 | C7: Высокий | D7: Снижает зависимость от одного PMS
A8: Smart vending / micro-market | B8: 5-8 | C8: Высокий | D8: Стабильный слой физической торговли
A9: Rental-локеры | B9: 5-8 | C9: Высокий | D9: Подходит отелям с малым штатом
A10: Киоски check-in | B10: 4-7 | C10: Средне-высокий | D10: Часть функций уйдёт на телефон
A11: Голосовые ассистенты в номере | B11: 3-6 | C11: Средний | D11: Нужны приватность и доказанное использование
A12: QR-консьерж | B12: 2-4 | C12: Средний | D12: Быстро коммодитизируется
... A15: Vape-vending | B15: 2-5 | C15: Низко-средний | D15: Регуляторный риск выше стратегической ценности

Sheet Примечания
A1: Примечания и ограничения
A2: Финансовые входные данные — плановые допущения (синие ячейки), а не котировки. Landed-стоимость, цены, attach rate и постоянные расходы нужно заменить реальными данными поставщиков/отелей.
A3: Суммы в EUR без НДС; НДС по срокам, перенос убытков, амортизация и стоимость финансирования не моделируются. Landed-стоимость hardware списывается при установке (консервативно).
A4: Рыночные факты из чата (объёмы Лигурии, заявления вендоров, даты регуляции) получены на прежних шагах исследования и в этой сборке не перепроверялись. Перед внешней передачей сверить с первоисточниками (ISTAT/Regione Liguria, ADM, EUR-Lex, Polizia di Stato).
A5: Лист лицензий — ориентировочный чек-лист, не юридическая консультация; подтвердить у итальянского юриста.
A6: Горизонты долговечности трендов — экспертная оценка, не прогноз из источника данных.
A7: Регулируемый vending по умолчанию 0% attach (только модель fee лицензированного партнёра).
