Workbook

Sheet Summary
A1: LIGURIA HOSPITALITY AGENT+HARDWARE - INVESTMENT SUMMARY / SINTESI / ИНВЕСТИЦИОННОЕ РЕЗЮМЕ
A3: English | B3: Italiano | C3: Русский | D3: Value
A4: Scenario selected (1 Lean, 2 Base, 3 Regional) | B4: Scenario scelto (1 Lean, 2 Base, 3 Regionale) | C4: Выбранный сценарий (1 Lean, 2 Base, 3 Regional) | D4: =Assumptions!B8
A5: Clients at month 12 | B5: Clienti al mese 12 | C5: Клиентов на 12-й месяц | D5: =Assumptions!B9
A6: Clients at month 24 | B6: Clienti al mese 24 | C6: Клиентов на 24-й месяц | D6: =Assumptions!B10
A7: Revenue Y1 (EUR) | B7: Ricavi anno 1 | C7: Выручка, год 1 | D7: =PnL_Annual!B14
A8: Revenue Y2 (EUR) | B8: Ricavi anno 2 | C8: Выручка, год 2 | D8: =PnL_Annual!C14
A9: EBITDA Y1 (EUR) | B9: EBITDA anno 1 | C9: EBITDA, год 1 | D9: =PnL_Annual!B17
A10: EBITDA Y2 (EUR) | B10: EBITDA anno 2 | C10: EBITDA, год 2 | D10: =PnL_Annual!C17
A11: Pre-launch investment (EUR) | B11: Investimento pre-lancio | C11: Предстартовые инвестиции | D11: =Assumptions!B28
A12: Peak funding need (EUR) = -min cumulative cash | B12: Fabbisogno finanziario massimo | C12: Пиковая потребность в финансировании = -min накопл. cash | D12: =-MIN(Model_24M!C83:AA83)
A13: Cumulative cash at month 24 (EUR) | B13: Cassa cumulata mese 24 | C13: Накопленный cash на 24-й месяц | D13: =Model_24M!AA83
A14: First month with EBITDA > 0 (999 = none in 24m) | B14: Primo mese con EBITDA > 0 (999 = nessuno) | C14: Первый месяц с EBITDA > 0 (999 = нет за 24 мес.) | D14: =MIN(Model_24M!C84:AA84)
A16: NOTE: all figures are scenario outputs of ILLUSTRATIVE assumptions (blue cells in Assumptions), not forecasts from sourced data. Replace with supplier quotes and pilot results.
A17: NOTA: cifre = output di ipotesi ILLUSTRATIVE, non previsioni basate su dati verificati. Sostituire con preventivi fornitori e risultati pilota.
A18: ПРИМЕЧАНИЕ: цифры - результат расчёта по ИЛЛЮСТРАТИВНЫМ допущениям, а не прогноз по проверенным данным. Заменить на коммерческие предложения поставщиков и итоги пилота.

Sheet Liguria_TAM
A1: Metric / Metrica / Показатель | B1: Value
A2: Hotels in Liguria (2025, earlier research - verify with ISTAT/Regione) | B2: 1178
A3: B&B / holiday accommodation businesses (earlier research - verify) | B3: 1559
A4: AAUT tourist apartments (earlier research - verify) | B4: 39099
A5: Arrivals, official accommodation 2025 (earlier research - verify) | B5: 5310000
A6: Nights, official accommodation 2025 (earlier research - verify) | B6: 15960000
A8: Addressable hotels+B&B (excl. AAUT) | B8: =B2+B3
A9: Penetration at M24 (clients / addressable) | B9: =Assumptions!B10/B8
A10: Penetration at M24, only hotels | B10: =Assumptions!B10/B2

Sheet Assumptions
A1: ASSUMPTIONS / IPOTESI / ДОПУЩЕНИЯ (EUR, ex VAT) - blue = editable input; ILLUSTRATIVE placeholders, replace with supplier quotes & pilot data
A3: Scenario / Scenario / Сценарий | B3: Clients M12 | C3: Clients M24 | D3: Opex multiplier
A4: 1 Lean | B4: 15 | C4: 35 | D4: 0.7
A5: 2 Base Liguria | B5: 30 | C5: 80 | D5: 1
A6: 3 Regional Scale | B6: 60 | C6: 160 | D6: 1.8
A8: Selected scenario (1/2/3) / Scenario scelto / Выбранный сценарий | B8: 2
A9: Clients at M12 | B9: =INDEX(B4:B6,B8)
A10: Clients at M24 | B10: =INDEX(C4:C6,B8)
A11: Opex multiplier | B11: =INDEX(D4:D6,B8)
A12: Simplified tax rate on positive EBITDA (IRES 24% + IRAP 3.9%; no loss carry-forward, no D&A) | B12: 0.279
A14: Fixed opex EUR/month (x multiplier) / Costi fissi / Постоянные расходы | B14: EUR/month
A15: Team (founder draw, part-time dev, installer) / Team / Команда | B15: 9500
A16: Marketing & trade shows / Marketing / Маркетинг | B16: 1500
A17: Cloud, LLM base, tools / Cloud e strumenti / Облако и инструменты | B17: 600
A18: Legal, compliance, accounting / Legale e contabilita / Юристы и бухгалтерия | B18: 500
A19: Insurance, travel, other / Assicurazioni, viaggi / Страховка, поездки, прочее | B19: 900
A20: Total fixed opex / Totale / Итого | B20: =SUM(B15:B19)
A22: Pre-launch investment EUR (month 0) / Investimento pre-lancio / Предстартовые инвестиции | B22: EUR
A23: CE/RED/EMC technical file & lab checks / Fascicolo tecnico CE/RED / Тех. досье и лаборатория CE/RED | B23: 12000
A24: Demo kits & samples / Kit demo e campioni / Демо-комплекты и образцы | B24: 8000
A25: Legal: GDPR/DPIA, contracts, licences / Legale / Юристы: GDPR, договоры, лицензии | B25: 6000
A26: Brand, website, demo environment / Brand e sito / Бренд, сайт, демо | B26: 4000
A27: Contingency % / Imprevisti / Резерв | B27: 0.1
A28: Total pre-launch / Totale / Итого | B28: =SUM(B23:B26)*(1+B27)
A31: Key | B31: Category EN | C31: Categoria IT | D31: Категория RU | E31: Adoption (% of clients) | F31: Units per adopting client | G31: Hardware price EUR/unit | H31: Landed cost EUR/unit | I31: Monthly fee EUR/unit | J31: Monthly direct cost EUR/unit | K31: Setup/install revenue EUR/unit | L31: Setup/install cost EUR/unit | M31: Start month
A32: OS | B32: Hotel Agent OS (SaaS) | C32: Hotel Agent OS (SaaS) | D32: Hotel Agent OS (SaaS) | E32: 1 | F32: 1 | G32: 0 | H32: 0 | I32: 350 | J32: 90 | K32: 1500 | L32: 600 | M32: 1
A33: LOB | B33: Lobby GuestNode | C33: GuestNode Lobby | D33: GuestNode в лобби | E33: 0.6 | F33: 1 | G33: 650 | H33: 320 | I33: 60 | J33: 15 | K33: 150 | L33: 80 | M33: 1
A34: ROOM | B34: In-room GuestNode | C34: GuestNode in camera | D34: GuestNode в номере | E34: 0.15 | F34: 10 | G34: 140 | H34: 75 | I34: 6 | J34: 1.5 | K34: 0 | L34: 0 | M34: 4
A35: WALL | B35: Smart Travel Wall (vending+commerce) | C35: Smart Travel Wall (vending+commercio) | D35: Smart Travel Wall (vending+commerce) | E35: 0.3 | F35: 1 | G35: 3200 | H35: 1900 | I35: 180 | J35: 40 | K35: 200 | L35: 120 | M35: 3
A36: LOCK | B36: Rental & luggage lockers | C36: Locker noleggio e bagagli | D36: Локеры: аренда и багаж | E36: 0.25 | F36: 1 | G36: 2800 | H36: 1700 | I36: 150 | J36: 25 | K36: 200 | L36: 120 | M36: 3
A37: IOT | B37: IoT Energy Kit (per room) | C37: Kit energia IoT (per camera) | D37: IoT Energy Kit (на номер) | E37: 0.3 | F37: 20 | G37: 190 | H37: 105 | I37: 4 | J37: 1 | K37: 20 | L37: 12 | M37: 3
A38: ACC | B38: Smart Access (per door) | C38: Smart Access (per porta) | D38: Smart Access (на дверь) | E38: 0.15 | F38: 15 | G38: 160 | H38: 90 | I38: 3 | J38: 0.8 | K38: 15 | L38: 10 | M38: 6
A39: KIO | B39: Check-in / ID kiosk | C39: Kiosk check-in / ID | D39: Киоск check-in / ID | E39: 0.1 | F39: 1 | G39: 3800 | H39: 2300 | I39: 120 | J39: 30 | K39: 300 | L39: 150 | M39: 6
A40: ROB | B40: Delivery/cleaning robot | C40: Robot consegna/pulizia | D40: Робот доставки/уборки | E40: 0.03 | F40: 1 | G40: 9000 | H40: 6500 | I40: 400 | J40: 150 | K40: 500 | L40: 300 | M40: 13
A41: VAPE | B41: Regulated vending (vape/nicotine) - EXCLUDED | C41: Vending regolamentato - ESCLUSO | D41: Регулируемый vending - ИСКЛЮЧЕН | E41: 0 | F41: 1 | G41: 0 | H41: 0 | I41: 0 | J41: 0 | K41: 0 | L41: 0 | M41: 99

Sheet Model_24M
A1: Monthly P&L and cash flow / P&L e cash flow mensili / Помесячные P&L и cash flow (EUR)
A3: Month / Mese / Месяц | C3: 0 | D3: 1 | E3: 2 | F3: 3 | G3: 4 | H3: 5 | I3: 6 | J3: 7 | K3: 8 | L3: 9 | M3: 10 | N3: 11 | O3: 12 | P3: 13 | Q3: 14 | R3: 15 | S3: 16 | T3: 17 | U3: 18 | V3: 19 | W3: 20 | X3: 21 | Y3: 22 | Z3: 23 | AA3: 24
A4: Clients cumulative / Clienti / Клиенты (накоп.) | C4: 0 | D4: =IF(D$3<=12,Assumptions!$B$9*D$3/12,Assumptions!$B$9+(Assumptions!$B$10-Assumptions!$B$9)*(D$3-12)/12) | E4: =IF(E$3<=12,Assumptions!$B$9*E$3/12,Assumptions!$B$9+(Assumptions!$B$10-Assumptions!$B$9)*(E$3-12)/12) | F4: =IF(F$3<=12,Assumptions!$B$9*F$3/12,Assumptions!$B$9+(Assumptions!$B$10-Assumptions!$B$9)*(F$3-12)/12) | G4: =IF(G$3<=12,Assumptions!$B$9*G$3/12,Assumptions!$B$9+(Assumptions!$B$10-Assumptions!$B$9)*(G$3-12)/12) | H4: =IF(H$3<=12,Assumptions!$B$9*H$3/12,Assumptions!$B$9+(Assumptions!$B$10-Assumptions!$B$9)*(H$3-12)/12) | I4: =IF(I$3<=12,Assumptions!$B$9*I$3/12,Assumptions!$B$9+(Assumptions!$B$10-Assumptions!$B$9)*(I$3-12)/12) | J4: =IF(J$3<=12,Assumptions!$B$9*J$3/12,Assumptions!$B$9+(Assumptions!$B$10-Assumptions!$B$9)*(J$3-12)/12) | K4: =IF(K$3<=12,Assumptions!$B$9*K$3/12,Assumptions!$B$9+(Assumptions!$B$10-Assumptions!$B$9)*(K$3-12)/12) | ... AA4: =IF(AA$3<=12,Assumptions!$B$9*AA$3/12,Assumptions!$B$9+(Assumptions!$B$10-Assumptions!$B$9)*(AA$3-12)/12)
A5: New clients / Nuovi / Новые клиенты | D5: =D4-C4 | E5: =E4-D4 | F5: =F4-E4 | G5: =G4-F4 | H5: =H4-G4 | I5: =I4-H4 | J5: =J4-I4 | K5: =K4-J4 | ... AA5: =AA4-Z4
A8: =Assumptions!B32&" / "&Assumptions!C32&" / "&Assumptions!D32
A9: Units installed (cum.) | C9: 0 | D9: =IF(D$3>=Assumptions!$M$32,D$4*Assumptions!$E$32*Assumptions!$F$32,0) | E9: =IF(E$3>=Assumptions!$M$32,E$4*Assumptions!$E$32*Assumptions!$F$32,0) | F9: =IF(F$3>=Assumptions!$M$32,F$4*Assumptions!$E$32*Assumptions!$F$32,0) | G9: =IF(G$3>=Assumptions!$M$32,G$4*Assumptions!$E$32*Assumptions!$F$32,0) | H9: =IF(H$3>=Assumptions!$M$32,H$4*Assumptions!$E$32*Assumptions!$F$32,0) | I9: =IF(I$3>=Assumptions!$M$32,I$4*Assumptions!$E$32*Assumptions!$F$32,0) | J9: =IF(J$3>=Assumptions!$M$32,J$4*Assumptions!$E$32*Assumptions!$F$32,0) | K9: =IF(K$3>=Assumptions!$M$32,K$4*Assumptions!$E$32*Assumptions!$F$32,0) | ... AA9: =IF(AA$3>=Assumptions!$M$32,AA$4*Assumptions!$E$32*Assumptions!$F$32,0)
A10: New units | C10: 0 | D10: =D9-C9 | E10: =E9-D9 | F10: =F9-E9 | G10: =G9-F9 | H10: =H9-G9 | I10: =I9-H9 | J10: =J9-I9 | K10: =K9-J9 | ... AA10: =AA9-Z9
A11: Revenue | C11: 0 | D11: =D10*(Assumptions!$G$32+Assumptions!$K$32)+D9*Assumptions!$I$32 | E11: =E10*(Assumptions!$G$32+Assumptions!$K$32)+E9*Assumptions!$I$32 | F11: =F10*(Assumptions!$G$32+Assumptions!$K$32)+F9*Assumptions!$I$32 | G11: =G10*(Assumptions!$G$32+Assumptions!$K$32)+G9*Assumptions!$I$32 | H11: =H10*(Assumptions!$G$32+Assumptions!$K$32)+H9*Assumptions!$I$32 | I11: =I10*(Assumptions!$G$32+Assumptions!$K$32)+I9*Assumptions!$I$32 | J11: =J10*(Assumptions!$G$32+Assumptions!$K$32)+J9*Assumptions!$I$32 | K11: =K10*(Assumptions!$G$32+Assumptions!$K$32)+K9*Assumptions!$I$32 | ... AA11: =AA10*(Assumptions!$G$32+Assumptions!$K$32)+AA9*Assumptions!$I$32
A12: Direct cost | C12: 0 | D12: =D10*(Assumptions!$H$32+Assumptions!$L$32)+D9*Assumptions!$J$32 | E12: =E10*(Assumptions!$H$32+Assumptions!$L$32)+E9*Assumptions!$J$32 | F12: =F10*(Assumptions!$H$32+Assumptions!$L$32)+F9*Assumptions!$J$32 | G12: =G10*(Assumptions!$H$32+Assumptions!$L$32)+G9*Assumptions!$J$32 | H12: =H10*(Assumptions!$H$32+Assumptions!$L$32)+H9*Assumptions!$J$32 | I12: =I10*(Assumptions!$H$32+Assumptions!$L$32)+I9*Assumptions!$J$32 | J12: =J10*(Assumptions!$H$32+Assumptions!$L$32)+J9*Assumptions!$J$32 | K12: =K10*(Assumptions!$H$32+Assumptions!$L$32)+K9*Assumptions!$J$32 | ... AA12: =AA10*(Assumptions!$H$32+Assumptions!$L$32)+AA9*Assumptions!$J$32
A14: =Assumptions!B33&" / "&Assumptions!C33&" / "&Assumptions!D33
A15: Units installed (cum.) | C15: 0 | D15: =IF(D$3>=Assumptions!$M$33,D$4*Assumptions!$E$33*Assumptions!$F$33,0) | E15: =IF(E$3>=Assumptions!$M$33,E$4*Assumptions!$E$33*Assumptions!$F$33,0) | F15: =IF(F$3>=Assumptions!$M$33,F$4*Assumptions!$E$33*Assumptions!$F$33,0) | G15: =IF(G$3>=Assumptions!$M$33,G$4*Assumptions!$E$33*Assumptions!$F$33,0) | H15: =IF(H$3>=Assumptions!$M$33,H$4*Assumptions!$E$33*Assumptions!$F$33,0) | I15: =IF(I$3>=Assumptions!$M$33,I$4*Assumptions!$E$33*Assumptions!$F$33,0) | J15: =IF(J$3>=Assumptions!$M$33,J$4*Assumptions!$E$33*Assumptions!$F$33,0) | K15: =IF(K$3>=Assumptions!$M$33,K$4*Assumptions!$E$33*Assumptions!$F$33,0) | ... AA15: =IF(AA$3>=Assumptions!$M$33,AA$4*Assumptions!$E$33*Assumptions!$F$33,0)
A16: New units | C16: 0 | D16: =D15-C15 | E16: =E15-D15 | F16: =F15-E15 | G16: =G15-F15 | H16: =H15-G15 | I16: =I15-H15 | J16: =J15-I15 | K16: =K15-J15 | ... AA16: =AA15-Z15
A17: Revenue | C17: 0 | D17: =D16*(Assumptions!$G$33+Assumptions!$K$33)+D15*Assumptions!$I$33 | E17: =E16*(Assumptions!$G$33+Assumptions!$K$33)+E15*Assumptions!$I$33 | F17: =F16*(Assumptions!$G$33+Assumptions!$K$33)+F15*Assumptions!$I$33 | G17: =G16*(Assumptions!$G$33+Assumptions!$K$33)+G15*Assumptions!$I$33 | H17: =H16*(Assumptions!$G$33+Assumptions!$K$33)+H15*Assumptions!$I$33 | I17: =I16*(Assumptions!$G$33+Assumptions!$K$33)+I15*Assumptions!$I$33 | J17: =J16*(Assumptions!$G$33+Assumptions!$K$33)+J15*Assumptions!$I$33 | K17: =K16*(Assumptions!$G$33+Assumptions!$K$33)+K15*Assumptions!$I$33 | ... AA17: =AA16*(Assumptions!$G$33+Assumptions!$K$33)+AA15*Assumptions!$I$33
A18: Direct cost | C18: 0 | D18: =D16*(Assumptions!$H$33+Assumptions!$L$33)+D15*Assumptions!$J$33 | E18: =E16*(Assumptions!$H$33+Assumptions!$L$33)+E15*Assumptions!$J$33 | F18: =F16*(Assumptions!$H$33+Assumptions!$L$33)+F15*Assumptions!$J$33 | G18: =G16*(Assumptions!$H$33+Assumptions!$L$33)+G15*Assumptions!$J$33 | H18: =H16*(Assumptions!$H$33+Assumptions!$L$33)+H15*Assumptions!$J$33 | I18: =I16*(Assumptions!$H$33+Assumptions!$L$33)+I15*Assumptions!$J$33 | J18: =J16*(Assumptions!$H$33+Assumptions!$L$33)+J15*Assumptions!$J$33 | K18: =K16*(Assumptions!$H$33+Assumptions!$L$33)+K15*Assumptions!$J$33 | ... AA18: =AA16*(Assumptions!$H$33+Assumptions!$L$33)+AA15*Assumptions!$J$33
A20: =Assumptions!B34&" / "&Assumptions!C34&" / "&Assumptions!D34
A21: Units installed (cum.) | C21: 0 | D21: =IF(D$3>=Assumptions!$M$34,D$4*Assumptions!$E$34*Assumptions!$F$34,0) | E21: =IF(E$3>=Assumptions!$M$34,E$4*Assumptions!$E$34*Assumptions!$F$34,0) | F21: =IF(F$3>=Assumptions!$M$34,F$4*Assumptions!$E$34*Assumptions!$F$34,0) | G21: =IF(G$3>=Assumptions!$M$34,G$4*Assumptions!$E$34*Assumptions!$F$34,0) | H21: =IF(H$3>=Assumptions!$M$34,H$4*Assumptions!$E$34*Assumptions!$F$34,0) | I21: =IF(I$3>=Assumptions!$M$34,I$4*Assumptions!$E$34*Assumptions!$F$34,0) | J21: =IF(J$3>=Assumptions!$M$34,J$4*Assumptions!$E$34*Assumptions!$F$34,0) | K21: =IF(K$3>=Assumptions!$M$34,K$4*Assumptions!$E$34*Assumptions!$F$34,0) | ... AA21: =IF(AA$3>=Assumptions!$M$34,AA$4*Assumptions!$E$34*Assumptions!$F$34,0)
A22: New units | C22: 0 | D22: =D21-C21 | E22: =E21-D21 | F22: =F21-E21 | G22: =G21-F21 | H22: =H21-G21 | I22: =I21-H21 | J22: =J21-I21 | K22: =K21-J21 | ... AA22: =AA21-Z21
A23: Revenue | C23: 0 | D23: =D22*(Assumptions!$G$34+Assumptions!$K$34)+D21*Assumptions!$I$34 | E23: =E22*(Assumptions!$G$34+Assumptions!$K$34)+E21*Assumptions!$I$34 | F23: =F22*(Assumptions!$G$34+Assumptions!$K$34)+F21*Assumptions!$I$34 | G23: =G22*(Assumptions!$G$34+Assumptions!$K$34)+G21*Assumptions!$I$34 | H23: =H22*(Assumptions!$G$34+Assumptions!$K$34)+H21*Assumptions!$I$34 | I23: =I22*(Assumptions!$G$34+Assumptions!$K$34)+I21*Assumptions!$I$34 | J23: =J22*(Assumptions!$G$34+Assumptions!$K$34)+J21*Assumptions!$I$34 | K23: =K22*(Assumptions!$G$34+Assumptions!$K$34)+K21*Assumptions!$I$34 | ... AA23: =AA22*(Assumptions!$G$34+Assumptions!$K$34)+AA21*Assumptions!$I$34
A24: Direct cost | C24: 0 | D24: =D22*(Assumptions!$H$34+Assumptions!$L$34)+D21*Assumptions!$J$34 | E24: =E22*(Assumptions!$H$34+Assumptions!$L$34)+E21*Assumptions!$J$34 | F24: =F22*(Assumptions!$H$34+Assumptions!$L$34)+F21*Assumptions!$J$34 | G24: =G22*(Assumptions!$H$34+Assumptions!$L$34)+G21*Assumptions!$J$34 | H24: =H22*(Assumptions!$H$34+Assumptions!$L$34)+H21*Assumptions!$J$34 | I24: =I22*(Assumptions!$H$34+Assumptions!$L$34)+I21*Assumptions!$J$34 | J24: =J22*(Assumptions!$H$34+Assumptions!$L$34)+J21*Assumptions!$J$34 | K24: =K22*(Assumptions!$H$34+Assumptions!$L$34)+K21*Assumptions!$J$34 | ... AA24: =AA22*(Assumptions!$H$34+Assumptions!$L$34)+AA21*Assumptions!$J$34
A26: =Assumptions!B35&" / "&Assumptions!C35&" / "&Assumptions!D35
A27: Units installed (cum.) | C27: 0 | D27: =IF(D$3>=Assumptions!$M$35,D$4*Assumptions!$E$35*Assumptions!$F$35,0) | E27: =IF(E$3>=Assumptions!$M$35,E$4*Assumptions!$E$35*Assumptions!$F$35,0) | F27: =IF(F$3>=Assumptions!$M$35,F$4*Assumptions!$E$35*Assumptions!$F$35,0) | G27: =IF(G$3>=Assumptions!$M$35,G$4*Assumptions!$E$35*Assumptions!$F$35,0) | H27: =IF(H$3>=Assumptions!$M$35,H$4*Assumptions!$E$35*Assumptions!$F$35,0) | I27: =IF(I$3>=Assumptions!$M$35,I$4*Assumptions!$E$35*Assumptions!$F$35,0) | J27: =IF(J$3>=Assumptions!$M$35,J$4*Assumptions!$E$35*Assumptions!$F$35,0) | K27: =IF(K$3>=Assumptions!$M$35,K$4*Assumptions!$E$35*Assumptions!$F$35,0) | ... AA27: =IF(AA$3>=Assumptions!$M$35,AA$4*Assumptions!$E$35*Assumptions!$F$35,0)
A28: New units | C28: 0 | D28: =D27-C27 | E28: =E27-D27 | F28: =F27-E27 | G28: =G27-F27 | H28: =H27-G27 | I28: =I27-H27 | J28: =J27-I27 | K28: =K27-J27 | ... AA28: =AA27-Z27
A29: Revenue | C29: 0 | D29: =D28*(Assumptions!$G$35+Assumptions!$K$35)+D27*Assumptions!$I$35 | E29: =E28*(Assumptions!$G$35+Assumptions!$K$35)+E27*Assumptions!$I$35 | F29: =F28*(Assumptions!$G$35+Assumptions!$K$35)+F27*Assumptions!$I$35 | G29: =G28*(Assumptions!$G$35+Assumptions!$K$35)+G27*Assumptions!$I$35 | H29: =H28*(Assumptions!$G$35+Assumptions!$K$35)+H27*Assumptions!$I$35 | I29: =I28*(Assumptions!$G$35+Assumptions!$K$35)+I27*Assumptions!$I$35 | J29: =J28*(Assumptions!$G$35+Assumptions!$K$35)+J27*Assumptions!$I$35 | K29: =K28*(Assumptions!$G$35+Assumptions!$K$35)+K27*Assumptions!$I$35 | ... AA29: =AA28*(Assumptions!$G$35+Assumptions!$K$35)+AA27*Assumptions!$I$35
A30: Direct cost | C30: 0 | D30: =D28*(Assumptions!$H$35+Assumptions!$L$35)+D27*Assumptions!$J$35 | E30: =E28*(Assumptions!$H$35+Assumptions!$L$35)+E27*Assumptions!$J$35 | F30: =F28*(Assumptions!$H$35+Assumptions!$L$35)+F27*Assumptions!$J$35 | G30: =G28*(Assumptions!$H$35+Assumptions!$L$35)+G27*Assumptions!$J$35 | H30: =H28*(Assumptions!$H$35+Assumptions!$L$35)+H27*Assumptions!$J$35 | I30: =I28*(Assumptions!$H$35+Assumptions!$L$35)+I27*Assumptions!$J$35 | J30: =J28*(Assumptions!$H$35+Assumptions!$L$35)+J27*Assumptions!$J$35 | K30: =K28*(Assumptions!$H$35+Assumptions!$L$35)+K27*Assumptions!$J$35 | ... AA30: =AA28*(Assumptions!$H$35+Assumptions!$L$35)+AA27*Assumptions!$J$35
A32: =Assumptions!B36&" / "&Assumptions!C36&" / "&Assumptions!D36
A33: Units installed (cum.) | C33: 0 | D33: =IF(D$3>=Assumptions!$M$36,D$4*Assumptions!$E$36*Assumptions!$F$36,0) | E33: =IF(E$3>=Assumptions!$M$36,E$4*Assumptions!$E$36*Assumptions!$F$36,0) | F33: =IF(F$3>=Assumptions!$M$36,F$4*Assumptions!$E$36*Assumptions!$F$36,0) | G33: =IF(G$3>=Assumptions!$M$36,G$4*Assumptions!$E$36*Assumptions!$F$36,0) | H33: =IF(H$3>=Assumptions!$M$36,H$4*Assumptions!$E$36*Assumptions!$F$36,0) | I33: =IF(I$3>=Assumptions!$M$36,I$4*Assumptions!$E$36*Assumptions!$F$36,0) | J33: =IF(J$3>=Assumptions!$M$36,J$4*Assumptions!$E$36*Assumptions!$F$36,0) | K33: =IF(K$3>=Assumptions!$M$36,K$4*Assumptions!$E$36*Assumptions!$F$36,0) | ... AA33: =IF(AA$3>=Assumptions!$M$36,AA$4*Assumptions!$E$36*Assumptions!$F$36,0)
A34: New units | C34: 0 | D34: =D33-C33 | E34: =E33-D33 | F34: =F33-E33 | G34: =G33-F33 | H34: =H33-G33 | I34: =I33-H33 | J34: =J33-I33 | K34: =K33-J33 | ... AA34: =AA33-Z33
A35: Revenue | C35: 0 | D35: =D34*(Assumptions!$G$36+Assumptions!$K$36)+D33*Assumptions!$I$36 | E35: =E34*(Assumptions!$G$36+Assumptions!$K$36)+E33*Assumptions!$I$36 | F35: =F34*(Assumptions!$G$36+Assumptions!$K$36)+F33*Assumptions!$I$36 | G35: =G34*(Assumptions!$G$36+Assumptions!$K$36)+G33*Assumptions!$I$36 | H35: =H34*(Assumptions!$G$36+Assumptions!$K$36)+H33*Assumptions!$I$36 | I35: =I34*(Assumptions!$G$36+Assumptions!$K$36)+I33*Assumptions!$I$36 | J35: =J34*(Assumptions!$G$36+Assumptions!$K$36)+J33*Assumptions!$I$36 | K35: =K34*(Assumptions!$G$36+Assumptions!$K$36)+K33*Assumptions!$I$36 | ... AA35: =AA34*(Assumptions!$G$36+Assumptions!$K$36)+AA33*Assumptions!$I$36
A36: Direct cost | C36: 0 | D36: =D34*(Assumptions!$H$36+Assumptions!$L$36)+D33*Assumptions!$J$36 | E36: =E34*(Assumptions!$H$36+Assumptions!$L$36)+E33*Assumptions!$J$36 | F36: =F34*(Assumptions!$H$36+Assumptions!$L$36)+F33*Assumptions!$J$36 | G36: =G34*(Assumptions!$H$36+Assumptions!$L$36)+G33*Assumptions!$J$36 | H36: =H34*(Assumptions!$H$36+Assumptions!$L$36)+H33*Assumptions!$J$36 | I36: =I34*(Assumptions!$H$36+Assumptions!$L$36)+I33*Assumptions!$J$36 | J36: =J34*(Assumptions!$H$36+Assumptions!$L$36)+J33*Assumptions!$J$36 | K36: =K34*(Assumptions!$H$36+Assumptions!$L$36)+K33*Assumptions!$J$36 | ... AA36: =AA34*(Assumptions!$H$36+Assumptions!$L$36)+AA33*Assumptions!$J$36
A38: =Assumptions!B37&" / "&Assumptions!C37&" / "&Assumptions!D37
A39: Units installed (cum.) | C39: 0 | D39: =IF(D$3>=Assumptions!$M$37,D$4*Assumptions!$E$37*Assumptions!$F$37,0) | E39: =IF(E$3>=Assumptions!$M$37,E$4*Assumptions!$E$37*Assumptions!$F$37,0) | F39: =IF(F$3>=Assumptions!$M$37,F$4*Assumptions!$E$37*Assumptions!$F$37,0) | G39: =IF(G$3>=Assumptions!$M$37,G$4*Assumptions!$E$37*Assumptions!$F$37,0) | H39: =IF(H$3>=Assumptions!$M$37,H$4*Assumptions!$E$37*Assumptions!$F$37,0) | I39: =IF(I$3>=Assumptions!$M$37,I$4*Assumptions!$E$37*Assumptions!$F$37,0) | J39: =IF(J$3>=Assumptions!$M$37,J$4*Assumptions!$E$37*Assumptions!$F$37,0) | K39: =IF(K$3>=Assumptions!$M$37,K$4*Assumptions!$E$37*Assumptions!$F$37,0) | ... AA39: =IF(AA$3>=Assumptions!$M$37,AA$4*Assumptions!$E$37*Assumptions!$F$37,0)
A40: New units | C40: 0 | D40: =D39-C39 | E40: =E39-D39 | F40: =F39-E39 | G40: =G39-F39 | H40: =H39-G39 | I40: =I39-H39 | J40: =J39-I39 | K40: =K39-J39 | ... AA40: =AA39-Z39
A41: Revenue | C41: 0 | D41: =D40*(Assumptions!$G$37+Assumptions!$K$37)+D39*Assumptions!$I$37 | E41: =E40*(Assumptions!$G$37+Assumptions!$K$37)+E39*Assumptions!$I$37 | F41: =F40*(Assumptions!$G$37+Assumptions!$K$37)+F39*Assumptions!$I$37 | G41: =G40*(Assumptions!$G$37+Assumptions!$K$37)+G39*Assumptions!$I$37 | H41: =H40*(Assumptions!$G$37+Assumptions!$K$37)+H39*Assumptions!$I$37 | I41: =I40*(Assumptions!$G$37+Assumptions!$K$37)+I39*Assumptions!$I$37 | J41: =J40*(Assumptions!$G$37+Assumptions!$K$37)+J39*Assumptions!$I$37 | K41: =K40*(Assumptions!$G$37+Assumptions!$K$37)+K39*Assumptions!$I$37 | ... AA41: =AA40*(Assumptions!$G$37+Assumptions!$K$37)+AA39*Assumptions!$I$37
A42: Direct cost | C42: 0 | D42: =D40*(Assumptions!$H$37+Assumptions!$L$37)+D39*Assumptions!$J$37 | E42: =E40*(Assumptions!$H$37+Assumptions!$L$37)+E39*Assumptions!$J$37 | F42: =F40*(Assumptions!$H$37+Assumptions!$L$37)+F39*Assumptions!$J$37 | G42: =G40*(Assumptions!$H$37+Assumptions!$L$37)+G39*Assumptions!$J$37 | H42: =H40*(Assumptions!$H$37+Assumptions!$L$37)+H39*Assumptions!$J$37 | I42: =I40*(Assumptions!$H$37+Assumptions!$L$37)+I39*Assumptions!$J$37 | J42: =J40*(Assumptions!$H$37+Assumptions!$L$37)+J39*Assumptions!$J$37 | K42: =K40*(Assumptions!$H$37+Assumptions!$L$37)+K39*Assumptions!$J$37 | ... AA42: =AA40*(Assumptions!$H$37+Assumptions!$L$37)+AA39*Assumptions!$J$37
A44: =Assumptions!B38&" / "&Assumptions!C38&" / "&Assumptions!D38
A45: Units installed (cum.) | C45: 0 | D45: =IF(D$3>=Assumptions!$M$38,D$4*Assumptions!$E$38*Assumptions!$F$38,0) | E45: =IF(E$3>=Assumptions!$M$38,E$4*Assumptions!$E$38*Assumptions!$F$38,0) | F45: =IF(F$3>=Assumptions!$M$38,F$4*Assumptions!$E$38*Assumptions!$F$38,0) | G45: =IF(G$3>=Assumptions!$M$38,G$4*Assumptions!$E$38*Assumptions!$F$38,0) | H45: =IF(H$3>=Assumptions!$M$38,H$4*Assumptions!$E$38*Assumptions!$F$38,0) | I45: =IF(I$3>=Assumptions!$M$38,I$4*Assumptions!$E$38*Assumptions!$F$38,0) | J45: =IF(J$3>=Assumptions!$M$38,J$4*Assumptions!$E$38*Assumptions!$F$38,0) | K45: =IF(K$3>=Assumptions!$M$38,K$4*Assumptions!$E$38*Assumptions!$F$38,0) | ... AA45: =IF(AA$3>=Assumptions!$M$38,AA$4*Assumptions!$E$38*Assumptions!$F$38,0)
A46: New units | C46: 0 | D46: =D45-C45 | E46: =E45-D45 | F46: =F45-E45 | G46: =G45-F45 | H46: =H45-G45 | I46: =I45-H45 | J46: =J45-I45 | K46: =K45-J45 | ... AA46: =AA45-Z45
A47: Revenue | C47: 0 | D47: =D46*(Assumptions!$G$38+Assumptions!$K$38)+D45*Assumptions!$I$38 | E47: =E46*(Assumptions!$G$38+Assumptions!$K$38)+E45*Assumptions!$I$38 | F47: =F46*(Assumptions!$G$38+Assumptions!$K$38)+F45*Assumptions!$I$38 | G47: =G46*(Assumptions!$G$38+Assumptions!$K$38)+G45*Assumptions!$I$38 | H47: =H46*(Assumptions!$G$38+Assumptions!$K$38)+H45*Assumptions!$I$38 | I47: =I46*(Assumptions!$G$38+Assumptions!$K$38)+I45*Assumptions!$I$38 | J47: =J46*(Assumptions!$G$38+Assumptions!$K$38)+J45*Assumptions!$I$38 | K47: =K46*(Assumptions!$G$38+Assumptions!$K$38)+K45*Assumptions!$I$38 | ... AA47: =AA46*(Assumptions!$G$38+Assumptions!$K$38)+AA45*Assumptions!$I$38
A48: Direct cost | C48: 0 | D48: =D46*(Assumptions!$H$38+Assumptions!$L$38)+D45*Assumptions!$J$38 | E48: =E46*(Assumptions!$H$38+Assumptions!$L$38)+E45*Assumptions!$J$38 | F48: =F46*(Assumptions!$H$38+Assumptions!$L$38)+F45*Assumptions!$J$38 | G48: =G46*(Assumptions!$H$38+Assumptions!$L$38)+G45*Assumptions!$J$38 | H48: =H46*(Assumptions!$H$38+Assumptions!$L$38)+H45*Assumptions!$J$38 | I48: =I46*(Assumptions!$H$38+Assumptions!$L$38)+I45*Assumptions!$J$38 | J48: =J46*(Assumptions!$H$38+Assumptions!$L$38)+J45*Assumptions!$J$38 | K48: =K46*(Assumptions!$H$38+Assumptions!$L$38)+K45*Assumptions!$J$38 | ... AA48: =AA46*(Assumptions!$H$38+Assumptions!$L$38)+AA45*Assumptions!$J$38
A50: =Assumptions!B39&" / "&Assumptions!C39&" / "&Assumptions!D39
...

Sheet PnL_Annual
A1: Annual P&L by category / P&L annuale per categoria / Годовой P&L по категориям (EUR)
A3: Category | B3: Rev Y1 | C3: Rev Y2 | D3: Direct cost Y1 | E3: Direct cost Y2 | F3: GP Y1 | G3: GP Y2 | H3: GM% Y2
A4: =Assumptions!B32&" / "&Assumptions!C32&" / "&Assumptions!D32 | B4: =SUM(Model_24M!D11:O11) | C4: =SUM(Model_24M!P11:AA11) | D4: =SUM(Model_24M!D12:O12) | E4: =SUM(Model_24M!P12:AA12) | F4: =B4-D4 | G4: =C4-E4 | H4: =IF(C4=0,0,G4/C4)
A5: =Assumptions!B33&" / "&Assumptions!C33&" / "&Assumptions!D33 | B5: =SUM(Model_24M!D17:O17) | C5: =SUM(Model_24M!P17:AA17) | D5: =SUM(Model_24M!D18:O18) | E5: =SUM(Model_24M!P18:AA18) | F5: =B5-D5 | G5: =C5-E5 | H5: =IF(C5=0,0,G5/C5)
A6: =Assumptions!B34&" / "&Assumptions!C34&" / "&Assumptions!D34 | B6: =SUM(Model_24M!D23:O23) | C6: =SUM(Model_24M!P23:AA23) | D6: =SUM(Model_24M!D24:O24) | E6: =SUM(Model_24M!P24:AA24) | F6: =B6-D6 | G6: =C6-E6 | H6: =IF(C6=0,0,G6/C6)
A7: =Assumptions!B35&" / "&Assumptions!C35&" / "&Assumptions!D35 | B7: =SUM(Model_24M!D29:O29) | C7: =SUM(Model_24M!P29:AA29) | D7: =SUM(Model_24M!D30:O30) | E7: =SUM(Model_24M!P30:AA30) | F7: =B7-D7 | G7: =C7-E7 | H7: =IF(C7=0,0,G7/C7)
A8: =Assumptions!B36&" / "&Assumptions!C36&" / "&Assumptions!D36 | B8: =SUM(Model_24M!D35:O35) | C8: =SUM(Model_24M!P35:AA35) | D8: =SUM(Model_24M!D36:O36) | E8: =SUM(Model_24M!P36:AA36) | F8: =B8-D8 | G8: =C8-E8 | H8: =IF(C8=0,0,G8/C8)
A9: =Assumptions!B37&" / "&Assumptions!C37&" / "&Assumptions!D37 | B9: =SUM(Model_24M!D41:O41) | C9: =SUM(Model_24M!P41:AA41) | D9: =SUM(Model_24M!D42:O42) | E9: =SUM(Model_24M!P42:AA42) | F9: =B9-D9 | G9: =C9-E9 | H9: =IF(C9=0,0,G9/C9)
A10: =Assumptions!B38&" / "&Assumptions!C38&" / "&Assumptions!D38 | B10: =SUM(Model_24M!D47:O47) | C10: =SUM(Model_24M!P47:AA47) | D10: =SUM(Model_24M!D48:O48) | E10: =SUM(Model_24M!P48:AA48) | F10: =B10-D10 | G10: =C10-E10 | H10: =IF(C10=0,0,G10/C10)
A11: =Assumptions!B39&" / "&Assumptions!C39&" / "&Assumptions!D39 | B11: =SUM(Model_24M!D53:O53) | C11: =SUM(Model_24M!P53:AA53) | D11: =SUM(Model_24M!D54:O54) | E11: =SUM(Model_24M!P54:AA54) | F11: =B11-D11 | G11: =C11-E11 | H11: =IF(C11=0,0,G11/C11)
A12: =Assumptions!B40&" / "&Assumptions!C40&" / "&Assumptions!D40 | B12: =SUM(Model_24M!D59:O59) | C12: =SUM(Model_24M!P59:AA59) | D12: =SUM(Model_24M!D60:O60) | E12: =SUM(Model_24M!P60:AA60) | F12: =B12-D12 | G12: =C12-E12 | H12: =IF(C12=0,0,G12/C12)
A13: =Assumptions!B41&" / "&Assumptions!C41&" / "&Assumptions!D41 | B13: =SUM(Model_24M!D65:O65) | C13: =SUM(Model_24M!P65:AA65) | D13: =SUM(Model_24M!D66:O66) | E13: =SUM(Model_24M!P66:AA66) | F13: =B13-D13 | G13: =C13-E13 | H13: =IF(C13=0,0,G13/C13)
A14: TOTAL / TOTALE / ИТОГО | B14: =SUM(B4:B13) | C14: =SUM(C4:C13) | D14: =SUM(D4:D13) | E14: =SUM(E4:E13) | F14: =SUM(F4:F13) | G14: =SUM(G4:G13) | H14: =IF(C14=0,0,G14/C14)
A15: Pre-launch investment (month 0) | B15: =Assumptions!B28
A16: Fixed opex | B16: =SUM(Model_24M!D73:O73) | C16: =SUM(Model_24M!P73:AA73)
A17: EBITDA | B17: =SUM(Model_24M!D74:O74) | C17: =SUM(Model_24M!P74:AA74)
A18: Tax | B18: =SUM(Model_24M!D75:O75) | C18: =SUM(Model_24M!P75:AA75)
A19: Net income | B19: =SUM(Model_24M!D76:O76) | C19: =SUM(Model_24M!P76:AA76)

Sheet Trend_Longevity
A1: Trend EN | B1: Tendenza IT | C1: Тренд RU | D1: Horizon | E1: Assessment (analyst judgement) / Valutazione / Оценка (экспертное суждение)
A2: Agentic hotel operations | B2: Operazioni alberghiere agentiche | C2: Agentic-операции отеля | D2: 7-10 y | E2: Very high / Molto alto / Очень высокий
A3: Identity/context layer (guest-room-reservation) | B3: Livello identita/contesto (ospite-camera-prenotazione) | C3: Слой идентификации/контекста (гость-номер-бронь) | D3: 7-10 y | E3: Very high / Molto alto / Очень высокий
A4: Energy IoT (occupancy-based HVAC) | B4: IoT energia (HVAC basato su presenza) | C4: Energy IoT (климат по occupancy) | D4: 8-12 y | E4: Very high / Molto alto / Очень высокий
A5: Smart access / digital keys | B5: Smart access / chiavi digitali | C5: Smart access / цифровые ключи | D5: 8-12 y | E5: Very high / Molto alto / Очень высокий
A6: Multilingual guest service | B6: Servizio multilingue | C6: Мультиязычный сервис | D6: 7-10 y | E6: Very high, weak moat / Molto alto, moat debole / Очень высокий, слабый moat
A7: Smart vending / micro-market / lockers | B7: Smart vending / micro-market / locker | C7: Smart vending / micro-market / локеры | D7: 5-8 y | E7: High / Alto / Высокий
A8: Check-in kiosks | B8: Kiosk di check-in | C8: Киоски check-in | D8: 4-7 y | E8: Medium-high / Medio-alto / Средне-высокий
A9: In-room voice/screen assistant | B9: Assistente vocale/schermo in camera | C9: Голосовой/экранный ассистент в номере | D9: 3-6 y | E9: Medium / Medio / Средний
A10: QR/phone concierge | B10: Concierge QR/telefono | C10: QR/телефонный консьерж | D10: 2-4 y | E10: Medium, commoditising / Medio, commoditizzazione / Средний, коммодитизация
A11: Delivery/cleaning robots | B11: Robot consegna/pulizia | C11: Роботы доставки/уборки | D11: 5-8 y | E11: Medium, size-dependent / Medio, dipende dalla dimensione / Средний, зависит от размера отеля
A12: Humanoid greeters | B12: Umanoidi di accoglienza | C12: Гуманоидные greeters | D12: 1-3 y | E12: Low / Basso / Низкий
A13: Vape/nicotine vending | B13: Vending vape/nicotina | C13: Vending вейпов/никотина | D13: 2-5 y | E13: Low-medium; regulatory risk / Basso-medio; rischio normativo / Низко-средний; регуляторный риск

Sheet Licences
A1: Category EN | B1: Categoria IT | C1: Категория RU | D1: Requirement EN (verify with counsel) | E1: Requisito IT (verificare con legale) | F1: Требование RU (проверить с юристом)
A2: Agentic SaaS / guest data | B2: SaaS agentico / dati ospiti | C2: Agentic SaaS / данные гостей | D2: GDPR, DPA with hotels, DPIA, audit logs, EU hosting | E2: GDPR, DPA con hotel, DPIA, log di audit, hosting UE | F2: GDPR, DPA с отелями, DPIA, audit-логи, хостинг в ЕС
A3: Guest registration / identity | B3: Registrazione ospiti / identita | C3: Регистрация гостей / идентификация | D3: Alloggiati Web (TULPS art.109), ISTAT; do not store ID copies longer than needed; keep ID out of room devices | E3: Alloggiati Web (TULPS art.109), ISTAT; non conservare copie documenti oltre il necessario; niente documenti sui dispositivi in camera | F3: Alloggiati Web (TULPS ст.109), ISTAT; не хранить копии документов дольше необходимого; документы не держать на устройствах в номере
A4: Radio hardware import (Wi-Fi/BLE/Zigbee) | B4: Import hardware radio | C4: Импорт радио-оборудования | D4: CE, RED, EMC/LVD, RoHS, EU DoC, technical file; importer duties | E4: CE, RED, EMC/LVD, RoHS, DoC UE, fascicolo tecnico; obblighi dell'importatore | F4: CE, RED, EMC/LVD, RoHS, EU DoC, технич. досье; обязанности импортёра
A5: White-label / own brand | B5: White-label / marchio proprio | C5: White-label / свой бренд | D5: Own brand can shift manufacturer obligations to you | E5: Il marchio proprio puo trasferire obblighi del fabbricante | F5: Свой бренд может перенести на вас обязанности производителя
A6: Connected products cyber | B6: Cybersicurezza prodotti connessi | C6: Кибербезопасность подключённых устройств | D6: EU Cyber Resilience Act (reporting from Sep 2026, main duties Dec 2027): SBOM, updates, vulnerability contact | E6: Cyber Resilience Act UE (segnalazioni da set 2026, obblighi principali dic 2027): SBOM, aggiornamenti, contatto vulnerabilita | F6: EU Cyber Resilience Act (отчётность с сентября 2026, основные требования с декабря 2027): SBOM, обновления, контакт по уязвимостям
A7: Payments (vending/lockers) | B7: Pagamenti (vending/locker) | C7: Платежи (vending/локеры) | D7: Use certified PSP/terminal (e.g., Nexi/Adyen/Stripe); avoid handling card data | E7: Usare PSP/terminale certificato; non gestire dati carta | F7: Сертифицированный PSP/терминал; не обрабатывать данные карт
A8: Food/drink vending | B8: Vending alimentare | C8: Vending еды/напитков | D8: SCIA/SUAP, HACCP, labelling - ideally via local licensed operator | E8: SCIA/SUAP, HACCP, etichettatura - meglio tramite operatore locale | F8: SCIA/SUAP, HACCP, маркировка - лучше через местного лицензированного оператора
A9: Smart locks | B9: Serrature smart | C9: Умные замки | D9: RED/EMC, fire/emergency egress compatibility, qualified locksmith | E9: RED/EMC, compatibilita antincendio/emergenza, fabbro qualificato | F9: RED/EMC, совместимость с пожарной эвакуацией, квалифицированный слесарь
A10: Robots | B10: Robot | C10: Роботы | D10: CE/machinery safety, risk assessment, liability insurance, supervised deployment | E10: CE/sicurezza macchine, valutazione rischi, assicurazione RC, impiego supervisionato | F10: CE/безопасность машин, оценка рисков, страхование ответственности, работа под присмотром
A11: Tobacco / vape vending | B11: Vending tabacchi / vape | C11: Vending табака / вейпов | D11: ADM authorisation, age verification, excise, advertising ban: only via licensed operator after legal opinion | E11: Autorizzazione ADM, verifica eta, accise, divieto pubblicita: solo tramite operatore autorizzato dopo parere legale | F11: Разрешение ADM, проверка возраста, акциз, запрет рекламы: только через лицензированного оператора после юридического заключения

Sheet Risks
A1: Risk EN | B1: Rischio IT | C1: Риск RU | D1: Likelihood | E1: Mitigation EN | F1: Mitigazione IT | G1: Митигация RU
A2: Long hotel sales cycle | B2: Ciclo di vendita lungo | C2: Долгий цикл продаж | D2: High | E2: Paid pilots, PMS partners, off-season installs | F2: Pilot a pagamento, partner PMS, installazioni fuori stagione | G2: Платные пилоты, партнёры PMS, установка вне сезона
A3: Low guest usage of GuestNode | B3: Scarso uso di GuestNode | C3: Низкое использование GuestNode | D3: Medium | E3: Lobby-first, QR fallback, usage gates before room rollout | F3: Prima lobby, QR di riserva, soglie di utilizzo | G3: Сначала лобби, QR-запасной канал, пороги использования
A4: Hardware failures / weak OEM docs | B4: Guasti hardware / documentazione OEM debole | C4: Поломки / слабая документация OEM | D4: High | E4: Pre-shipment audit, 5-10% spare pool, EU repair partner | F4: Audit pre-spedizione, scorta 5-10%, partner riparazioni UE | G4: Аудит перед отгрузкой, запас 5-10%, сервис-партнёр в ЕС
A5: Chinese cloud lock-in | B5: Dipendenza dal cloud cinese | C5: Зависимость от китайского облака | D5: Medium | E5: Local API, own EU cloud, data export rights | F5: API locale, cloud UE proprio, diritti di export dati | G5: Локальный API, собственное облако в ЕС, права экспорта данных
A6: PMS integration fragmentation | B6: Frammentazione integrazioni PMS | C6: Фрагментация интеграций PMS | D6: High | E6: Start with 2-3 PMS (e.g., Slope, WuBook, Octorate - verify APIs) | F6: Partire con 2-3 PMS (verificare API) | G6: Начать с 2-3 PMS (проверить API)
A7: Seasonality of Liguria | B7: Stagionalita Liguria | C7: Сезонность Лигурии | D7: High | E7: Annual SaaS contracts, schedule installs Nov-Mar | F7: Contratti annuali, installazioni nov-mar | G7: Годовые контракты, установка ноя-мар
A8: Working-capital squeeze | B8: Tensione di capitale circolante | C8: Нехватка оборотного капитала | D8: Medium | E8: Hotel deposit before ordering, 30-50% supplier deposit limits | F8: Acconto hotel prima dell'ordine | G8: Депозит отеля до заказа оборудования
A9: GDPR incident | B9: Incidente GDPR | C9: Инцидент GDPR | D9: Low-medium / very high impact | E9: Data minimisation, encryption, DPAs, logging | F9: Minimizzazione dati, cifratura, DPA, log | G9: Минимизация данных, шифрование, DPA, логирование
A10: Tobacco/vape enforcement | B10: Sanzioni tabacchi/vape | C10: Санкции по табаку/вейпам | D10: Medium / very high impact | E10: Excluded from base case; licensed-operator model only | F10: Escluso dal caso base; solo operatore autorizzato | G10: Исключено из базового сценария; только через лицензированного оператора
A11: Robot economics fail for SMB | B11: Economia robot non sostenibile per PMI | C11: Экономика роботов не сходится для SMB | D11: High | E11: Robot-agnostic software first; pilot only at 80+ rooms | F11: Software agnostico prima; pilota solo da 80+ camere | G11: Сначала robot-agnostic софт; пилот только от 80+ номеров
